Workbook

Sheet Intructivo
B2: Matriz Mapa de Riesgos
B4: Teniendo en cuenta que con la expedición del Decreto 1499 de 2017 “Por medio del cual se modifica el Decreto 1083 de 2015, Decreto Único Reglamentario del Sector Función Pública, en lo relacionado con el Sistema de Gestión establecido en el artículo 133 de la Ley 1753 de 2015”, se crea un solo Sistema de Gestión y se alinea con el Sistema de Control Interno, hoy todas las entidades públicas requieren actualizar y/o implementar el Modelo Integrado de Planeación y Gestión MIPG, modelo que incorpora el Modelo Estándar de Control Interno MECI a través de la 7a dimensión del mismo. En este marco general, el proceso de administración del riesgo es un esfuerzo conjunto entre la Alta Dirección y los servidores en todos sus niveles, ejercicio que inicia con la formulación de la política de Administración del Riesgo, la cual incluye los niveles de responsabilidad frente al seguimiento y evaluación, aspectos que deberán definirse acorde con el Esquema de Líneas de Defensa vinculado a la Dimensión 7. Teniendo en cuenta lo anterior y dada la necesidad de las entidades frente a la estructuración de los mapas de riesgos, como herramienta fundamental frente a la gestión del riesgo, el presente formato desarrolla un esquema completo acorde con los contenidos metodológicos de la Guía para la Administración del Riesgo y el diseño de controles V5. El formato cuenta con celdas parametrizadas y permite contar con los respectivos mapas de calor para riesgo inherente y riesgo residual.
B6: Orientaciones Generales
B7: Antes de iniciar con el diligenciamiento de la información en la matriz, se requiere haber avanzado en el análisis del proceso, su objetivo, alcance, actividades clave, considere los lineamientos establecidos en el Paso 2: identificación del riesgo, donde se explica ampliamente las bases para adelanter este análisis. Así mismo, considere en el Paso 3: valoración del riesgo los lineamientos para definir el No. de veces que se hace la actividad con la cual se relaciona el riesgo y su impacto en términos económicos o reputacionales. En este mismo paso se analizan los controles que deben responder a los atributos de eficiencia e informativos. NOTA: Si lo considera pertinente, es posible agregar hojas de trabajo adicionales al presente formato que permitan incluir la traza de estos análisis.
B9: El archivo contiene las siguientes hojas: - Hoja 1 Instructivo - Hoja 2 Mapa Final: Encontrará la totalidad de la estructura para la identificación y valoración de los riesgos por proceso, programa o proyecto, acorde con el nivel de desagregación que la entidad considere necesaria.
C12: Columna | E12: Descripción - Lineamientos para el diligenciamiento
C13: Proceso | E13: Diligencie el nombre del proceso al cual se le identificarán y valorarán los riesgos.
C14: Objetivo | E14: Diligencie el objetivo del proceso.
C15: Alcance | E15: Diligencie el alcance del proceso.
C16: Referencia | E16: Permite definir unl consecutivo de riesgos. Una entidad puede ir en el riesgo 150, pero tener 70 riesgos, lo que permite llevar una traza de los riesgos. Esta información la debe administrar la oficina asesora de planeación o gerencia de riesgos. Cuando un el riesgo salga del mapa no existirá otro riesgo con el mismo número.
C17: Impacto | E17: Analice las consecuencias que puede ocasionar a la organización la materialización del riesgo, redacte de la forma más concreta posible.
C18: Causa Inmediata | E18: Circunstancias bajo las cuales se presenta el riesgo, es la situación más evidente frente al riesgo, redacte de la forma más concreta posible.
C19: Causa Raíz | E19: Causa principal o básica, corresponde a las razones por la cuales se puede presentar el riesgo, redacte de la forma más concreta posible.
C20: Descripción del Riesgo | E20: Consolida o resume los análisis sobre impacto + causa inmediata + causa raíz, permitiendo contar con una redacción clara y concreta del riesgo indentificado. Tenga en cuenta la estructura de alto nivel establecida en al guía, inicia con POSIBILIDAD DE + Impacto para la entidad (Qué) + Causa Inmediata (Cómo) + Causa Raíz (Por qué)
C21: Clasificación del Riesgo | E21: Utilice la lista de despligue que se encuentra parametrizada, le aparecerán las opciones: i)Daños Activos Fisicos, ii)Ejecucion y Administracion de procesos, iii)Fallas Tecnologicas, iv)Fraude Externo, v)Fraude Interno, vi)Relaciones Laborales, vii)Usuarios, productos y practicas organizacionales.
C22: Frecuencia con la cual se lleva a cabo la actividad | E22: Defina el # de veces que se ejecuta la actividad durante el año, (Recuerde la probabilidad e ocurrencia del riesgo se defien como el No. de veces que se pasa por el punto de riesgo en el periodo de 1 año). La matriz automáticamente hará el cálculo para el nivel de probabilidad inherente (Columnas H-I)
C23: Criterios de Impacto | E23: Utilice la lista de despligue que se encuentra parametrizada, le aparecerán las opciones de la tabla de Impacto en la Hoja 6 del presente documento. La matriz automáticamente hará el cálculo para el nivel de impacto inherente (Columnas L-M)
... C37: Estado | E37: Utilice la lista de despligue que se encuentra parametrizada, le aparecerán las opciones: i)Finalizado, ii)En curso, la selección en este caso dependerá de las acciones del plan que se hayan establecido en cada caso.
B40: - Hoja 3 Matriz de Calor Inherente: En esta hoja, en la medida en que ese diligencia el Mapa Final, se verán reflejados los riesgos en su zona correspondiente. Esta hoja no se diligencia se genera de manera automática.
B41: - Hoja 4 Matriz de Calor Residual: En esta hoja, en la medida en que ese diligencia el Mapa Final, se verán reflejados los riesgos en su zona correspondiente. Esta hoja no se diligencia se genera de manera automática.
B42: - Hoja 5 Tabla de probabilidad: Tabla referente para todos los cálculos (no se diligencia)
B43: - Hoja 6 Tabla de Impacto: Tabla referente para todos los cálculos (no se diligencia)
B44: - Hoja 7 Tabla de Valoración de Controles: Tabla referente para todos los cálculos (no se diligencia)

Sheet Mapa final
D1: SISTEMA DE GESTIÓN DE CALIDAD
D3: GESTIÓN DE CALIDAD
D4: MAPA DE RIESGOS
D5: VERSIÓN: 05 | G5: FECHA: 07-05-2025 | J5: Página 1 de 1
A7: Proceso: | C7: Gestion de Evaluación Independiente
A8: Objetivo: | C8: Mejorar y proteger el valor de la organización a través de la ejecución del programa de auditorías, de manera independiente y objetiva en el marco del sistema de control interno con el fin de ofrecer una seguridad razonable respecto al logro de los objetivos institucionales
A9: Alcance: | C9: Inicia desde la definición de la estrategia y métodos para evaluar la gestión institucional con enfoque preventivo hasta la revisión de la estrategia y metodología para la evaluación de la gestión institucional
A10: Identificación del riesgo | H10: Análisis del riesgo inherente | O10: Evaluación del riesgo - Valoración de los controles | X10: Evaluación del riesgo - Nivel del riesgo residual | AE10: Plan de Acción | AH10: I SEGUIMIENTO 2025 Corte: 30 de abril 2025 | AK10: III SEGUIMIENTO 2025 Corte: 31 de agosto 2025 | AN10: III SEGUIMIENTO 2025 Corte: 31 diciembre 2025
A11: Referencia | B11: Impacto | C11: Causa Inmediata | D11: Causa Raíz | E11: Descripción del Riesgo | F11: Clasificación del Riesgo | G11: Frecuencia con la cual se realiza la actividad | H11: Probabilidad Inherente | I11: % | J11: Criterios de impacto | K11: Observación de criterio | L11: Impacto Inherente | M11: % | N11: Zona de Riesgo Inherente | O11: No. Control | P11: Descripción del Control | Q11: Afectación | R11: Atributos | X11: Probabilidad Residual | Y11: Probabilidad Residual Final | Z11: % | AA11: Impacto Residual Final | AB11: % | AC11: Zona de Riesgo Final | AD11: Tratamiento | AE11: Plan de Acción | AF11: Responsable | AG11: Fecha Implementación | AH11: Fecha Seguimiento | AI11: Seguimiento | AJ11: Estado del Plan de Acción | AK11: Fecha Seguimiento | AL11: Seguimiento | AM11: Estado del Plan de Acción | AN11: Fecha Seguimiento | AO11: Seguimiento | AP11: Estado del Plan de Acción
R12: Tipo | S12: Implementación | T12: Calificación | U12: Documentación | V12: Frecuencia | W12: Evidencia
A13: 1 | B13: Reputacional | C13: Falta de mejora de los procesos de la Corporacion y perdida de credibilidad por parte de la ciudadania | D13: Incumplimiento de Plan Anual de Auditoria aprobado por el comité Insttitucional de Coordinación de Control Interno, por aspectos internos y externos. | E13: Posibilidad de afectación reputaciones por la falta de mejora de los procesos de la Corporacion y perdida de credibilidad por parte de la ciudadania por incumplimiento del Plan Anual de Auditoria aprobado por el comité Insttitucional de Coordinación de Control Interno | F13: Ejecucion y Administracion de procesos | G13: 27 | H13: =IF(G13<=0,"",IF(G13<=2,"Muy Baja",IF(G13<=24,"Baja",IF(G13<=500,"Media",IF(G13<=5000,"Alta","Muy Alta"))))) -> Media | I13: =IF(H13="","",IF(H13="Muy Baja",0.2,IF(H13="Baja",0.4,IF(H13="Media",0.6,IF(H13="Alta",0.8,IF(H13="Muy Alta",1,)))))) -> 0.6 | J13: El riesgo afecta la imagen de la entidad internamente, de conocimiento general, nivel interno, de junta dircetiva y accionistas y/o de provedores | K13: =IF(NOT(ISERROR(MATCH(J13,#REF!,0))),#REF!&"Por favor no seleccionar los criterios de impacto(Afectación Económica o presupuestal y Pérdida Reputacional)",J13) -> El riesgo afecta la imagen de la entidad internamente, de conocimiento general, nivel interno, de junta dircetiva y accionistas y/o de provedores | L13: Bajo | N13: Bajo | O13: 1 | P13: El Jefe de la Oficina de Control Interno realiza seguimiento trimestral al cumplimiento del Plan Anual de Auditorias, en caso de no cumplimiento se lleva reporte o informes al Comité Institucional de Coordinación de Control Interno, para que se tomen las acciones correspondientes | Q13: =IF(OR(R13="Preventivo",R13="Detectivo"),"Probabilidad",IF(R13="Correctivo","Impacto","")) -> Probabilidad | R13: Preventivo | S13: Manual | T13: =IF(AND(R13="Preventivo",S13="Automático"),"50%",IF(AND(R13="Preventivo",S13="Manual"),"40%",IF(AND(R13="Detectivo",S13="Automático"),"40%",IF(AND(R13="Detectivo",S13="Manual"),"30%",IF(AND(R13="Correctivo",S13="Automático"),"35%",IF(AND(R13="Correctivo",S13="Manual"),"25%","")))))) -> 40% | U13: Documentado | V13: Aleatoria | W13: Con Registro | X13: =IFERROR(IF(Q13="Probabilidad",(I13-(+I13*T13)),IF(Q13="Impacto",I13,"")),"") -> 0.36 | Y13: =IFERROR(IF(X13="","",IF(X13<=0.2,"Muy Baja",IF(X13<=0.4,"Baja",IF(X13<=0.6,"Media",IF(X13<=0.8,"Alta","Muy Alta"))))),"") -> Baja | Z13: =+X13 -> 0.36 | AA13: =IFERROR(IF(AB13="","",IF(AB13<=0.2,"Leve",IF(AB13<=0.4,"Menor",IF(AB13<=0.6,"Moderado",IF(AB13<=0.8,"Mayor","Catastrófico"))))),"") -> Leve | AB13: =IFERROR(IF(Q13="Impacto",(M13-(+M13*T13)),IF(Q13="Probabilidad",M13,"")),"") -> 0 | AC13: =IFERROR(IF(OR(AND(Y13="Muy Baja",AA13="Leve"),AND(Y13="Muy Baja",AA13="Menor"),AND(Y13="Baja",AA13="Leve")),"Bajo",IF(OR(AND(Y13="Muy baja",AA13="Moderado"),AND(Y13="Baja",AA13="Menor"),AND(Y13="Baja",AA13="Moderado"),AND(Y13="Media",AA13="Leve"),AND(Y13="Media",AA13="Menor"),AND(Y13="Media",AA13="Moderado"),AND(Y13="Alta",AA13="Leve"),AND(Y13="Alta",AA13="Menor")),"Moderado",IF(OR(AND(Y13="Muy Baja",AA13="Mayor"),AND(Y13="Baja",AA13="Mayor"),AND(Y13="Media",AA13="Mayor"),AND(Y13="Alta",AA13="Moderado"),AND(Y13="Alta",AA13="Mayor"),AND(Y13="Muy Alta",AA13="Leve"),AND(Y13="Muy Alta",AA13="Menor"),AND(Y13="Muy Alta",AA13="Moderado"),AND(Y13="Muy Alta",AA13="Mayor")),"Alto",IF(OR(AND(Y13="Muy Baja",AA13="Catastrófico"),AND(Y13="Baja",AA13="Catastrófico"),AND(Y13="Media",AA13="Catastrófico"),AND(Y13="Alta",AA13="Catastrófico"),AND(Y13="Muy Alta",AA13="Catastrófico")),"Extremo","")))),"") -> Bajo | AD13: Reducir (mitigar) | AE13: Realizar seguimiento cuatrimestral al cumplimiento de los términos establecidos para la auditoria interna elaborados y aprobados en el cronograma anual, por parte del Comité Institucional de Coordinación de Control Interno de la presente vigencia. | AF13: Control Interno | AG13: CUATRIMESTRAL
K14: =IF(NOT(ISERROR(MATCH(J14,_xlfn.ANCHORARRAY(E19),0))),I21&"Por favor no seleccionar los criterios de impacto",J14) -> 0 | O14: 2 | P14: El jefe de la Oficina de Control Interno, realiza seguimiento cuatrimestral a la presentación de los informes a los auditados, establecidos en la carta plan de auditoría interna, con el fin de asegurar su cumplimiento en las fechas establecidas. | Q14: =IF(OR(R14="Preventivo",R14="Detectivo"),"Probabilidad",IF(R14="Correctivo","Impacto","")) -> Probabilidad | R14: Preventivo | S14: Manual | T14: =IF(AND(R14="Preventivo",S14="Automático"),"50%",IF(AND(R14="Preventivo",S14="Manual"),"40%",IF(AND(R14="Detectivo",S14="Automático"),"40%",IF(AND(R14="Detectivo",S14="Manual"),"30%",IF(AND(R14="Correctivo",S14="Automático"),"35%",IF(AND(R14="Correctivo",S14="Manual"),"25%","")))))) -> 40% | U14: Sin Documentar | V14: Continua | W14: Sin Registro | X14: =IFERROR(IF(AND(Q13="Probabilidad",Q14="Probabilidad"),(Z13-(+Z13*T14)),IF(Q14="Probabilidad",(I13-(+I13*T14)),IF(Q14="Impacto",Z13,""))),"") -> 0.216 | Z14: =+X14 -> 0.216 | AB14: =IFERROR(IF(AND(Q13="Impacto",Q14="Impacto"),(AB7-(+AB7*T14)),IF(Q14="Impacto",(#REF!-(+#REF!*T14)),IF(Q14="Probabilidad",AB7,""))),"") -> 0 | AD14: Reducir (mitigar) | AE14: Realizar seguimiento a la presentación de los informes a los auditados, en carpeta física verificando la radicación y las fechas acordadas con los auditados. | AF14: Control Interno | AG14: CUATRIMESTRAL
K15: =IF(NOT(ISERROR(MATCH(J15,_xlfn.ANCHORARRAY(E20),0))),I22&"Por favor no seleccionar los criterios de impacto",J15) -> 0 | O15: 3 | P15: El jefe de Control interno lleva propuesta al comité de Control Interno sobre el ajuste del Plan de Auditorias, la situacion que se presento y explicar el porque se debera modificar el plan de Auditorias para que de esta forma se apruebe el nuevo plan . | Q15: =IF(OR(R15="Preventivo",R15="Detectivo"),"Probabilidad",IF(R15="Correctivo","Impacto","")) -> Probabilidad | R15: Preventivo | S15: Manual | T15: =IF(AND(R15="Preventivo",S15="Automático"),"50%",IF(AND(R15="Preventivo",S15="Manual"),"40%",IF(AND(R15="Detectivo",S15="Automático"),"40%",IF(AND(R15="Detectivo",S15="Manual"),"30%",IF(AND(R15="Correctivo",S15="Automático"),"35%",IF(AND(R15="Correctivo",S15="Manual"),"25%","")))))) -> 40% | U15: Sin Documentar | V15: Continua | W15: Sin Registro | X15: =IFERROR(IF(AND(Q14="Probabilidad",Q15="Probabilidad"),(Z14-(+Z14*T15)),IF(Q15="Probabilidad",(I14-(+I14*T15)),IF(Q15="Impacto",Z14,""))),"") -> 0.1296 | Z15: =+X15 -> 0.1296 | AB15: =IFERROR(IF(AND(Q14="Impacto",Q15="Impacto"),(AB8-(+AB8*T15)),IF(Q15="Impacto",(#REF!-(+#REF!*T15)),IF(Q15="Probabilidad",AB8,""))),"") -> 0 | AD15: Reducir (mitigar) | AE15: Rendir informe al Comité Institucional de Coordinación de Control sobre los cambios en el cronograma anual de auditorías internas, con su respectiva sustentación de cambio y nueva propuesta. | AF15: Control Interno | AG15: CUATRIMESTRAL
K16: =IF(NOT(ISERROR(MATCH(J16,_xlfn.ANCHORARRAY(E21),0))),I23&"Por favor no seleccionar los criterios de impacto",J16) -> 0 | X16: =IFERROR(IF(AND(Q15="Probabilidad",Q16="Probabilidad"),(Z15-(+Z15*T16)),IF(AND(Q15="Impacto",Q16="Probabilidad"),(Z14-(+Z14*T16)),IF(Q16="Impacto",Z15,""))),"")
K17: =IF(NOT(ISERROR(MATCH(J17,_xlfn.ANCHORARRAY(E22),0))),I24&"Por favor no seleccionar los criterios de impacto",J17) -> 0 | X17: =IFERROR(IF(AND(Q16="Probabilidad",Q17="Probabilidad"),(Z16-(+Z16*T17)),IF(AND(Q16="Impacto",Q17="Probabilidad"),(Z15-(+Z15*T17)),IF(Q17="Impacto",Z16,""))),"")
K18: =IF(NOT(ISERROR(MATCH(J18,_xlfn.ANCHORARRAY(E23),0))),I25&"Por favor no seleccionar los criterios de impacto",J18) -> 0 | X18: =IFERROR(IF(AND(Q17="Probabilidad",Q18="Probabilidad"),(Z17-(+Z17*T18)),IF(AND(Q17="Impacto",Q18="Probabilidad"),(Z16-(+Z16*T18)),IF(Q18="Impacto",Z17,""))),"")
B19: *Nota: La columna referencia se sugiere para mantener el consecutivo de riesgos, así el riesgo salga del mapa no existirá otro riesgo con el mismo número. Una entidad puede ir en el riesgo 150 pero tener 70 riesgos, lo que permite llevar una traza de los riesgos. Esta información la debe administrar la Oficina Asesora de Planeación o Gerencia de Riesgos.
B21: Fuente: Adaptado de Curso Riesgo Operativo Universidad del Rosario por Dirección de Gestión y Desempeño Institucional de Función Pública, 2020.

Sheet EJEMPLOS
A1: RECURSOS FISICOS Y TECNOLOGICOS
A3: 1 | B3: Económico | C3: multa y sanción del ente regulador | D3: manejo de inventarios de la entidad fuera de los lineamientos procedimientales y normativos | E3: Posibilidad de afectación económica por multa y sanción del ente regulador debido al manejo de iventarios de la entidad fuera de los lineamientos procedimientales y normativos | F3: Ejecucion y Administracion de procesos | G3: 12 | H3: Baja | I3: 0.4 | J3: Entre 10 y 50 SMLMV | K3: Entre 10 y 50 SMLMV | L3: Menor | M3: 0.4 | N3: Moderado | O3: 1 | P3: El tecnico, profesional , contratista efectua mensualmente la actualizacion de la carpeta compartida de los movimientos de ingresos, traslados y egresos de almacen dejando como evidencia los soportes respectivos.
K4: 0 | O4: 2 | P4: El profesional universitario efectua seguimiento mensual de verificacion y/o convalidacion de los movimientos de almacen por cada rubro contable con el detallado de inventario de bienes y el profesional especializado reviza y convalida la informacion dejando como evidencia los movimientos de inventarios.
K5: 0 | O5: 3
K6: 0 | O6: 4
K7: 0 | O7: 5
K8: 0 | O8: 6
A9: 2 | B9: Reputacional | C9: investigaciones de entes reguladores, quejas o requerimientos de servidores y usuarios | D9: realización de mantenimientos preventivos y correctivos en la infraestructura fuera de los tiempos y requerimientos normativos y procedimentales | E9: Posibilidad de afectación reputacional por investigaciones de entes reguladores, quejas o requerimientos de servidores y usuarios debido a la realización de mantenimientos preventivos y correctivos en la infraestructura fuera de los tiempos y requerimientos normativos y procedimentales | F9: Ejecucion y Administracion de procesos | G9: 19 | H9: Baja | I9: 0.4 | J9: El riesgo afecta la imagen de la entidad con algunos usuarios de relevancia frente al logro de los objetivos | K9: El riesgo afecta la imagen de la entidad con algunos usuarios de relevancia frente al logro de los objetivos | L9: Moderado | M9: 0.6 | N9: Moderado | O9: 1 | P9: El profesional del proceso identifica las necesidades y verfica semestralmente el cumplimiento del cronograma definido a través de la matriz de necesidades de infraestructura, dejando como evidencia el seguimiento semestral
K10: 0 | O10: 2 | P10: El Subdirector Administrativo deberá realizar un contrato de prestación de servicios de mantenimiento preventivo y correctivo con empresas que cuenten con capacidad técnica y experiencia suficiente en este tipo de actividades, dejando establecidos los requisitos en los pliegos de condiciones de los procesos de selección
K11: 0 | O11: 3 | P11: El Subdirector Administrativo debe contratar una firma interventora experta que realice el seguimiento técnico, jurídico, ambiental y financiero a las actividades a realizar por el contratista de mantenimiento locativo, quien presenta mensualmente como registro los informes de ejecución y gestión
K12: 0 | O12: 4
K13: 0 | O13: 5
K14: 0 | O14: 6
A15: 4 | B15: Reputacional | C15: perdida de imagen de usuarios internos, externos y directivos de la SDM | D15: prestación de los servicios generales y administrativos fuera de las necesidades requeridas. | E15: Posibilidad de afectación reputacional por perdida de imagen de usuarios internos, externos y directivos de la SDM, por la prestación de los servicios generales y administrativos fuera de las necesidades requeridas. | F15: Ejecucion y Administracion de procesos | G15: 9 | H15: Baja | I15: 0.4 | J15: El riesgo afecta la imagen de la entidad con algunos usuarios de relevancia frente al logro de los objetivos | K15: El riesgo afecta la imagen de la entidad con algunos usuarios de relevancia frente al logro de los objetivos | L15: Moderado | M15: 0.6 | N15: Moderado | O15: 1 | P15: El profesional del area hará seguimiento anual al tablero de control con semaforos de alertas que permira identificar las fechas de los vencimientos de los contratos y el flujo de proceso de los docuemntos en caso de adiciones, prorrogas y suscripcion de nuevos contratos, como evidencias se aportara el seguimiento del tablero de control.
K16: 0 | O16: 2
K17: 0 | O17: 3
K18: 0 | O18: 4
K19: 0 | O19: 5
K20: 0 | O20: 6
A23: GESTIÓN DOCUMENTAL
B26: Reputacional | C26: sanciones de la contraloria, archivo departanmentaly quejas de ususarios internos y externos | D26: ejecución del sistema de gestión documental fuera de los requerimiento normativos y procedimientales | E26: posibilidad de afectación reputacional por sanciones del archivo departamental y quejas de ususarios internos y externos debido a la ejecución del sistema de gestión documental fuera de los requerimiento normativos y procedimientales | F26: Ejecucion y Administracion de procesos | G26: 12 | H26: Baja | I26: 0.4 | J26: El riesgo afecta la imagen de de la entidad con efecto publicitario sostenido a nivel de sector administrativo, nivel departamental o municipal | K26: El riesgo afecta la imagen de de la entidad con efecto publicitario sostenido a nivel de sector administrativo, nivel departamental o municipal | L26: Mayor | M26: 0.8 | N26: Alto | O26: 1 | P26: El profesional debe asegurar la actualización y/o creación mensual de los instrumentos archivísticos de la Entidad dejando como evidencia cronograma e instrumentos actualizados
K27: 0 | O27: 2 | P27: El profesional del área deberá presentar los avances de la gestión documental en dos sesiones de Comité Interno de Archivo en el año, dejando como evidencia acta del comité
K28: 0 | O28: 3 | P28: El profesional del proceso verifica trimestralmente el cumplimiento de las transferencias documentales y las actividades contenidas en el PINAR dejando como evidencia las actas de transferencias primarias- suscritas.
K29: 0 | O29: 4 | P29: El supervisor del contrato hace segimiento mensual de los documentos del proceso, las sanciones y/o consecuencias del incumplimiento de alguna o algunas de las obligaciones contractuales asumidas por el contratista del contrato de almacenamiento y custodia, así como del arrendamiento de la bodega dejando como evidencia actas de seguimiento al contrato y compromisos allí pactados.
K30: 0 | O30: 5 | P30: El Subdirector administrativio hará seguimiento mensual al plan de contingencia para garantizar la continuidad del Sistema de Información Orfeo en caso de indisponibilidad
K31: 0 | O31: 6
A34: CONTROL INTERNO
A36: 1 | B36: Reputacional | C36: sanciones administrativas por entes gubernamentales | D36: presentación de informes de Ley,como producto de seguimientos fuera la normatividad vigente. | E36: Posibilidad de afectación reputacional por sanciones administrativas por entes gubernamentales debido a la presentación de informes de Ley,como producto de seguimientos fuera la normatividad vigente. | F36: Ejecucion y Administracion de procesos | G36: 39 | H36: Media | I36: 0.6 | J36: El riesgo afecta la imagen de la entidad con algunos usuarios de relevancia frente al logro de los objetivos | K36: El riesgo afecta la imagen de la entidad con algunos usuarios de relevancia frente al logro de los objetivos | L36: Moderado | M36: 0.6 | N36: Moderado | O36: 1 | P36: Los profesionales de control interno realizan mensualmente reuniones de seguimiento y autoevaluación del PAAI, a través de la verificación de la ejecución de actividades del mes en curso y las actividades programadas para el mes siguiente, teniendo como resultado el registro de actas de seguimiento.
K37: 0 | O37: 2 | P37: Jefe de la Oficina de Control Interno presenta en el CICI las fechas establecidas para la presentación de los informes de ley , con el fin de tomar acciones necesarias para cumplir con los lineamientos normativos.
K38: 0 | O38: 3
K39: 0 | O39: 4
K40: 0 | O40: 5
K41: 0 | O41: 6
A45: GESTIÓN FINANCIERA
A47: Referencia | B47: Impacto | C47: Causa Inmediata | D47: Causa Raíz | E47: Descripción del Riesgo | F47: Clasificación del Riesgo | G47: Frecuencia con la cual se realiza la actividad | H47: Probabilidad Inherente | I47: % | J47: Criterios de impacto | K47: Observación de criterio | L47: Impacto Inherente | M47: % | N47: Zona de Riesgo Inherente | O47: No. Control | P47: Descripción del Control
A49: 1 | B49: Reputacional | C49: requerimientos de los usuarios e incumplimiento del procedimiento en terminos procedimentales | D49: Realización del proceso de devolucion o Compensación de Pagos en Exceso y Pagos de lo no Debido por Conceptos no Tributarios y de lo no debido por inconsistencias y desactualizacion del sistema SICON fuera de los terminos procedimentales. | E49: Posibilidad de afectación reputacional por requerimientos de los usuarios e investigaciones administrativas,legales por entes de control por la realizacion del proceso de devoluciones fuera de los terminos procedimentales. | F49: Ejecucion y Administracion de procesos | G49: 670 | H49: Alta | I49: 0.8 | J49: El riesgo afecta la imagen de la entidad con algunos usuarios de relevancia frente al logro de los objetivos | K49: El riesgo afecta la imagen de la entidad con algunos usuarios de relevancia frente al logro de los objetivos | L49: Moderado | M49: 0.6 | N49: Alto | O49: 1 | P49: EL profesional Especializado del proceso verifica permanentemente que las devoluciones cargadas en la carpeta compartida STORAGE_ADMIN cumplan con los requisitos establecidos en el procedimiento dejando como registro la verificacion mediante-orden de devolucion
K50: 0 | O50: 2 | P50: El profesional especializado del proceso y el técnico verifican permanente que las devoluciones registradas en los sistema SICON y BOGDATA cumplan con los requisitos establecidos en el procedimiento dejando registrada la verificación en los aplicativos.
K51: 0 | O51: 3
K52: 0 | O52: 4
K53: 0 | O53: 5
...

Sheet Matriz Calor Inherente
B2: Matriz de Calor Inherente | J2: Impacto
B6: Probabilidad | E6: Muy Alta 100% | J6: =IF(AND('Mapa final'!$H$13="Muy Alta",'Mapa final'!$L$13="Leve"),CONCATENATE("R",'Mapa final'!$A$13),"") | L6: =IF(AND('Mapa final'!#REF!="Muy Alta",'Mapa final'!#REF!="Leve"),CONCATENATE("R",'Mapa final'!#REF!),"") -> #REF! | N6: =IF(AND('Mapa final'!#REF!="Muy Alta",'Mapa final'!#REF!="Leve"),CONCATENATE("R",'Mapa final'!#REF!),"") -> #REF! | P6: =IF(AND('Mapa final'!$H$13="Muy Alta",'Mapa final'!$L$13="Menor"),CONCATENATE("R",'Mapa final'!$A$13),"") | R6: =IF(AND('Mapa final'!#REF!="Muy Alta",'Mapa final'!#REF!="Menor"),CONCATENATE("R",'Mapa final'!#REF!),"") -> #REF! | T6: =IF(AND('Mapa final'!#REF!="Muy Alta",'Mapa final'!#REF!="Menor"),CONCATENATE("R",'Mapa final'!#REF!),"") -> #REF! | V6: =IF(AND('Mapa final'!$H$13="Muy Alta",'Mapa final'!$L$13="Moderado"),CONCATENATE("R",'Mapa final'!$A$13),"") | X6: =IF(AND('Mapa final'!#REF!="Muy Alta",'Mapa final'!#REF!="Moderado"),CONCATENATE("R",'Mapa final'!#REF!),"") -> #REF! | Z6: =IF(AND('Mapa final'!#REF!="Muy Alta",'Mapa final'!#REF!="Moderado"),CONCATENATE("R",'Mapa final'!#REF!),"") -> #REF! | AB6: =IF(AND('Mapa final'!$H$13="Muy Alta",'Mapa final'!$L$13="Mayor"),CONCATENATE("R",'Mapa final'!$A$13),"") | AD6: =IF(AND('Mapa final'!#REF!="Muy Alta",'Mapa final'!#REF!="Mayor"),CONCATENATE("R",'Mapa final'!#REF!),"") -> #REF! | AF6: =IF(AND('Mapa final'!#REF!="Muy Alta",'Mapa final'!#REF!="Mayor"),CONCATENATE("R",'Mapa final'!#REF!),"") -> #REF! | AH6: =IF(AND('Mapa final'!$H$13="Muy Alta",'Mapa final'!$L$13="Catastrófico"),CONCATENATE("R",'Mapa final'!$A$13),"") | AJ6: =IF(AND('Mapa final'!#REF!="Muy Alta",'Mapa final'!#REF!="Catastrófico"),CONCATENATE("R",'Mapa final'!#REF!),"") -> #REF! | AL6: =IF(AND('Mapa final'!#REF!="Muy Alta",'Mapa final'!#REF!="Catastrófico"),CONCATENATE("R",'Mapa final'!#REF!),"") -> #REF! | AO6: Extremo
J8: =IF(AND('Mapa final'!#REF!="Muy Alta",'Mapa final'!#REF!="Leve"),CONCATENATE("R",'Mapa final'!#REF!),"") -> #REF! | L8: =IF(AND('Mapa final'!#REF!="Muy Alta",'Mapa final'!#REF!="Leve"),CONCATENATE("R",'Mapa final'!#REF!),"") -> #REF! | N8: =IF(AND('Mapa final'!#REF!="Muy Alta",'Mapa final'!#REF!="Leve"),CONCATENATE("R",'Mapa final'!#REF!),"") -> #REF! | P8: =IF(AND('Mapa final'!#REF!="Muy Alta",'Mapa final'!#REF!="Menor"),CONCATENATE("R",'Mapa final'!#REF!),"") -> #REF! | R8: =IF(AND('Mapa final'!#REF!="Muy Alta",'Mapa final'!#REF!="Menor"),CONCATENATE("R",'Mapa final'!#REF!),"") -> #REF! | T8: =IF(AND('Mapa final'!#REF!="Muy Alta",'Mapa final'!#REF!="Menor"),CONCATENATE("R",'Mapa final'!#REF!),"") -> #REF! | V8: =IF(AND('Mapa final'!#REF!="Muy Alta",'Mapa final'!#REF!="Moderado"),CONCATENATE("R",'Mapa final'!#REF!),"") -> #REF! | X8: =IF(AND('Mapa final'!#REF!="Muy Alta",'Mapa final'!#REF!="Moderado"),CONCATENATE("R",'Mapa final'!#REF!),"") -> #REF! | Z8: =IF(AND('Mapa final'!#REF!="Muy Alta",'Mapa final'!#REF!="Moderado"),CONCATENATE("R",'Mapa final'!#REF!),"") -> #REF! | AB8: =IF(AND('Mapa final'!#REF!="Muy Alta",'Mapa final'!#REF!="Mayor"),CONCATENATE("R",'Mapa final'!#REF!),"") -> #REF! | AD8: =IF(AND('Mapa final'!#REF!="Muy Alta",'Mapa final'!#REF!="Mayor"),CONCATENATE("R",'Mapa final'!#REF!),"") -> #REF! | AF8: =IF(AND('Mapa final'!#REF!="Muy Alta",'Mapa final'!#REF!="Mayor"),CONCATENATE("R",'Mapa final'!#REF!),"") -> #REF! | AH8: =IF(AND('Mapa final'!#REF!="Muy Alta",'Mapa final'!#REF!="Catastrófico"),CONCATENATE("R",'Mapa final'!#REF!),"") -> #REF! | AJ8: =IF(AND('Mapa final'!#REF!="Muy Alta",'Mapa final'!#REF!="Catastrófico"),CONCATENATE("R",'Mapa final'!#REF!),"") -> #REF! | AL8: =IF(AND('Mapa final'!#REF!="Muy Alta",'Mapa final'!#REF!="Catastrófico"),CONCATENATE("R",'Mapa final'!#REF!),"") -> #REF!
J10: =IF(AND('Mapa final'!#REF!="Muy Alta",'Mapa final'!#REF!="Leve"),CONCATENATE("R",'Mapa final'!#REF!),"") -> #REF! | L10: =IF(AND('Mapa final'!#REF!="Muy Alta",'Mapa final'!#REF!="Leve"),CONCATENATE("R",'Mapa final'!#REF!),"") -> #REF! | N10: =IF(AND('Mapa final'!#REF!="Muy Alta",'Mapa final'!#REF!="Leve"),CONCATENATE("R",'Mapa final'!#REF!),"") -> #REF! | P10: =IF(AND('Mapa final'!#REF!="Muy Alta",'Mapa final'!#REF!="Menor"),CONCATENATE("R",'Mapa final'!#REF!),"") -> #REF! | R10: =IF(AND('Mapa final'!#REF!="Muy Alta",'Mapa final'!#REF!="Menor"),CONCATENATE("R",'Mapa final'!#REF!),"") -> #REF! | T10: =IF(AND('Mapa final'!#REF!="Muy Alta",'Mapa final'!#REF!="Menor"),CONCATENATE("R",'Mapa final'!#REF!),"") -> #REF! | V10: =IF(AND('Mapa final'!#REF!="Muy Alta",'Mapa final'!#REF!="Moderado"),CONCATENATE("R",'Mapa final'!#REF!),"") -> #REF! | X10: =IF(AND('Mapa final'!#REF!="Muy Alta",'Mapa final'!#REF!="Moderado"),CONCATENATE("R",'Mapa final'!#REF!),"") -> #REF! | Z10: =IF(AND('Mapa final'!#REF!="Muy Alta",'Mapa final'!#REF!="Moderado"),CONCATENATE("R",'Mapa final'!#REF!),"") -> #REF! | AB10: =IF(AND('Mapa final'!#REF!="Muy Alta",'Mapa final'!#REF!="Mayor"),CONCATENATE("R",'Mapa final'!#REF!),"") -> #REF! | AD10: =IF(AND('Mapa final'!#REF!="Muy Alta",'Mapa final'!#REF!="Mayor"),CONCATENATE("R",'Mapa final'!#REF!),"") -> #REF! | AF10: =IF(AND('Mapa final'!#REF!="Muy Alta",'Mapa final'!#REF!="Mayor"),CONCATENATE("R",'Mapa final'!#REF!),"") -> #REF! | AH10: =IF(AND('Mapa final'!#REF!="Muy Alta",'Mapa final'!#REF!="Catastrófico"),CONCATENATE("R",'Mapa final'!#REF!),"") -> #REF! | AJ10: =IF(AND('Mapa final'!#REF!="Muy Alta",'Mapa final'!#REF!="Catastrófico"),CONCATENATE("R",'Mapa final'!#REF!),"") -> #REF! | AL10: =IF(AND('Mapa final'!#REF!="Muy Alta",'Mapa final'!#REF!="Catastrófico"),CONCATENATE("R",'Mapa final'!#REF!),"") -> #REF!
J12: =IF(AND('Mapa final'!#REF!="Muy Alta",'Mapa final'!#REF!="Leve"),CONCATENATE("R",'Mapa final'!#REF!),"") -> #REF! | L12: =IF(AND('Mapa final'!$H$19="Muy Alta",'Mapa final'!$L$19="Leve"),CONCATENATE("R",'Mapa final'!$A$19),"") | N12: =IF(AND('Mapa final'!$H$25="Muy Alta",'Mapa final'!$L$25="Leve"),CONCATENATE("R",'Mapa final'!$A$25),"") | P12: =IF(AND('Mapa final'!#REF!="Muy Alta",'Mapa final'!#REF!="Menor"),CONCATENATE("R",'Mapa final'!#REF!),"") -> #REF! | R12: =IF(AND('Mapa final'!$H$19="Muy Alta",'Mapa final'!$L$19="Menor"),CONCATENATE("R",'Mapa final'!$A$19),"") | T12: =IF(AND('Mapa final'!$H$25="Muy Alta",'Mapa final'!$L$25="Menor"),CONCATENATE("R",'Mapa final'!$A$25),"") | V12: =IF(AND('Mapa final'!#REF!="Muy Alta",'Mapa final'!#REF!="Moderado"),CONCATENATE("R",'Mapa final'!#REF!),"") -> #REF! | X12: =IF(AND('Mapa final'!$H$19="Muy Alta",'Mapa final'!$L$19="Moderado"),CONCATENATE("R",'Mapa final'!$A$19),"") | Z12: =IF(AND('Mapa final'!$H$25="Muy Alta",'Mapa final'!$L$25="Moderado"),CONCATENATE("R",'Mapa final'!$A$25),"") | AB12: =IF(AND('Mapa final'!#REF!="Muy Alta",'Mapa final'!#REF!="Mayor"),CONCATENATE("R",'Mapa final'!#REF!),"") -> #REF! | AD12: =IF(AND('Mapa final'!$H$19="Muy Alta",'Mapa final'!$L$19="Mayor"),CONCATENATE("R",'Mapa final'!$A$19),"") | AF12: =IF(AND('Mapa final'!$H$25="Muy Alta",'Mapa final'!$L$25="Mayor"),CONCATENATE("R",'Mapa final'!$A$25),"") | AH12: =IF(AND('Mapa final'!#REF!="Muy Alta",'Mapa final'!#REF!="Catastrófico"),CONCATENATE("R",'Mapa final'!#REF!),"") -> #REF! | AJ12: =IF(AND('Mapa final'!$H$19="Muy Alta",'Mapa final'!$L$19="Catastrófico"),CONCATENATE("R",'Mapa final'!$A$19),"") | AL12: =IF(AND('Mapa final'!$H$25="Muy Alta",'Mapa final'!$L$25="Catastrófico"),CONCATENATE("R",'Mapa final'!$A$25),"")
E14: Alta 80% | J14: =IF(AND('Mapa final'!$H$13="Alta",'Mapa final'!$L$13="Leve"),CONCATENATE("R",'Mapa final'!$A$13),"") | L14: =IF(AND('Mapa final'!#REF!="Alta",'Mapa final'!#REF!="Leve"),CONCATENATE("R",'Mapa final'!#REF!),"") -> #REF! | N14: =IF(AND('Mapa final'!#REF!="Alta",'Mapa final'!#REF!="Leve"),CONCATENATE("R",'Mapa final'!#REF!),"") -> #REF! | P14: =IF(AND('Mapa final'!$H$13="Alta",'Mapa final'!$L$13="Menor"),CONCATENATE("R",'Mapa final'!$A$13),"") | R14: =IF(AND('Mapa final'!#REF!="Alta",'Mapa final'!#REF!="Menor"),CONCATENATE("R",'Mapa final'!#REF!),"") -> #REF! | T14: =IF(AND('Mapa final'!#REF!="Alta",'Mapa final'!#REF!="Menor"),CONCATENATE("R",'Mapa final'!#REF!),"") -> #REF! | V14: =IF(AND('Mapa final'!$H$13="Alta",'Mapa final'!$L$13="Moderado"),CONCATENATE("R",'Mapa final'!$A$13),"") | X14: =IF(AND('Mapa final'!#REF!="Alta",'Mapa final'!#REF!="Moderado"),CONCATENATE("R",'Mapa final'!#REF!),"") -> #REF! | Z14: =IF(AND('Mapa final'!#REF!="Alta",'Mapa final'!#REF!="Moderado"),CONCATENATE("R",'Mapa final'!#REF!),"") -> #REF! | AB14: =IF(AND('Mapa final'!$H$13="Alta",'Mapa final'!$L$13="Mayor"),CONCATENATE("R",'Mapa final'!$A$13),"") | AD14: =IF(AND('Mapa final'!#REF!="Alta",'Mapa final'!#REF!="Mayor"),CONCATENATE("R",'Mapa final'!#REF!),"") -> #REF! | AF14: =IF(AND('Mapa final'!#REF!="Alta",'Mapa final'!#REF!="Mayor"),CONCATENATE("R",'Mapa final'!#REF!),"") -> #REF! | AH14: =IF(AND('Mapa final'!$H$13="Alta",'Mapa final'!$L$13="Catastrófico"),CONCATENATE("R",'Mapa final'!$A$13),"") | AJ14: =IF(AND('Mapa final'!#REF!="Alta",'Mapa final'!#REF!="Catastrófico"),CONCATENATE("R",'Mapa final'!#REF!),"") -> #REF! | AL14: =IF(AND('Mapa final'!#REF!="Alta",'Mapa final'!#REF!="Catastrófico"),CONCATENATE("R",'Mapa final'!#REF!),"") -> #REF! | AO14: Alto
J16: =IF(AND('Mapa final'!#REF!="Alta",'Mapa final'!#REF!="Leve"),CONCATENATE("R",'Mapa final'!#REF!),"") -> #REF! | L16: =IF(AND('Mapa final'!#REF!="Alta",'Mapa final'!#REF!="Leve"),CONCATENATE("R",'Mapa final'!#REF!),"") -> #REF! | N16: =IF(AND('Mapa final'!#REF!="Alta",'Mapa final'!#REF!="Leve"),CONCATENATE("R",'Mapa final'!#REF!),"") -> #REF! | P16: =IF(AND('Mapa final'!#REF!="Alta",'Mapa final'!#REF!="Menor"),CONCATENATE("R",'Mapa final'!#REF!),"") -> #REF! | R16: =IF(AND('Mapa final'!#REF!="Alta",'Mapa final'!#REF!="Menor"),CONCATENATE("R",'Mapa final'!#REF!),"") -> #REF! | T16: =IF(AND('Mapa final'!#REF!="Alta",'Mapa final'!#REF!="Menor"),CONCATENATE("R",'Mapa final'!#REF!),"") -> #REF! | V16: =IF(AND('Mapa final'!#REF!="Alta",'Mapa final'!#REF!="Moderado"),CONCATENATE("R",'Mapa final'!#REF!),"") -> #REF! | X16: =IF(AND('Mapa final'!#REF!="Alta",'Mapa final'!#REF!="Moderado"),CONCATENATE("R",'Mapa final'!#REF!),"") -> #REF! | Z16: =IF(AND('Mapa final'!#REF!="Alta",'Mapa final'!#REF!="Moderado"),CONCATENATE("R",'Mapa final'!#REF!),"") -> #REF! | AB16: =IF(AND('Mapa final'!#REF!="Alta",'Mapa final'!#REF!="Mayor"),CONCATENATE("R",'Mapa final'!#REF!),"") -> #REF! | AD16: =IF(AND('Mapa final'!#REF!="Alta",'Mapa final'!#REF!="Mayor"),CONCATENATE("R",'Mapa final'!#REF!),"") -> #REF! | AF16: =IF(AND('Mapa final'!#REF!="Alta",'Mapa final'!#REF!="Mayor"),CONCATENATE("R",'Mapa final'!#REF!),"") -> #REF! | AH16: =IF(AND('Mapa final'!#REF!="Alta",'Mapa final'!#REF!="Catastrófico"),CONCATENATE("R",'Mapa final'!#REF!),"") -> #REF! | AJ16: =IF(AND('Mapa final'!#REF!="Alta",'Mapa final'!#REF!="Catastrófico"),CONCATENATE("R",'Mapa final'!#REF!),"") -> #REF! | AL16: =IF(AND('Mapa final'!#REF!="Alta",'Mapa final'!#REF!="Catastrófico"),CONCATENATE("R",'Mapa final'!#REF!),"") -> #REF!
J18: =IF(AND('Mapa final'!#REF!="Alta",'Mapa final'!#REF!="Leve"),CONCATENATE("R",'Mapa final'!#REF!),"") -> #REF! | L18: =IF(AND('Mapa final'!#REF!="Alta",'Mapa final'!#REF!="Leve"),CONCATENATE("R",'Mapa final'!#REF!),"") -> #REF! | N18: =IF(AND('Mapa final'!#REF!="Alta",'Mapa final'!#REF!="Leve"),CONCATENATE("R",'Mapa final'!#REF!),"") -> #REF! | P18: =IF(AND('Mapa final'!#REF!="Alta",'Mapa final'!#REF!="Menor"),CONCATENATE("R",'Mapa final'!#REF!),"") -> #REF! | R18: =IF(AND('Mapa final'!#REF!="Alta",'Mapa final'!#REF!="Menor"),CONCATENATE("R",'Mapa final'!#REF!),"") -> #REF! | T18: =IF(AND('Mapa final'!#REF!="Alta",'Mapa final'!#REF!="Menor"),CONCATENATE("R",'Mapa final'!#REF!),"") -> #REF! | V18: =IF(AND('Mapa final'!#REF!="Alta",'Mapa final'!#REF!="Moderado"),CONCATENATE("R",'Mapa final'!#REF!),"") -> #REF! | X18: =IF(AND('Mapa final'!#REF!="Alta",'Mapa final'!#REF!="Moderado"),CONCATENATE("R",'Mapa final'!#REF!),"") -> #REF! | Z18: =IF(AND('Mapa final'!#REF!="Alta",'Mapa final'!#REF!="Moderado"),CONCATENATE("R",'Mapa final'!#REF!),"") -> #REF! | AB18: =IF(AND('Mapa final'!#REF!="Alta",'Mapa final'!#REF!="Mayor"),CONCATENATE("R",'Mapa final'!#REF!),"") -> #REF! | AD18: =IF(AND('Mapa final'!#REF!="Alta",'Mapa final'!#REF!="Mayor"),CONCATENATE("R",'Mapa final'!#REF!),"") -> #REF! | AF18: =IF(AND('Mapa final'!#REF!="Alta",'Mapa final'!#REF!="Mayor"),CONCATENATE("R",'Mapa final'!#REF!),"") -> #REF! | AH18: =IF(AND('Mapa final'!#REF!="Alta",'Mapa final'!#REF!="Catastrófico"),CONCATENATE("R",'Mapa final'!#REF!),"") -> #REF! | AJ18: =IF(AND('Mapa final'!#REF!="Alta",'Mapa final'!#REF!="Catastrófico"),CONCATENATE("R",'Mapa final'!#REF!),"") -> #REF! | AL18: =IF(AND('Mapa final'!#REF!="Alta",'Mapa final'!#REF!="Catastrófico"),CONCATENATE("R",'Mapa final'!#REF!),"") -> #REF!
J20: =IF(AND('Mapa final'!#REF!="Alta",'Mapa final'!#REF!="Leve"),CONCATENATE("R",'Mapa final'!#REF!),"") -> #REF! | L20: =IF(AND('Mapa final'!$H$19="Alta",'Mapa final'!$L$19="Leve"),CONCATENATE("R",'Mapa final'!$A$19),"") | N20: =IF(AND('Mapa final'!$H$25="Alta",'Mapa final'!$L$25="Leve"),CONCATENATE("R",'Mapa final'!$A$25),"") | P20: =IF(AND('Mapa final'!#REF!="Alta",'Mapa final'!#REF!="Menor"),CONCATENATE("R",'Mapa final'!#REF!),"") -> #REF! | R20: =IF(AND('Mapa final'!$H$19="Alta",'Mapa final'!$L$19="Menor"),CONCATENATE("R",'Mapa final'!$A$19),"") | T20: =IF(AND('Mapa final'!$H$25="Alta",'Mapa final'!$L$25="Menor"),CONCATENATE("R",'Mapa final'!$A$25),"") | V20: =IF(AND('Mapa final'!#REF!="Alta",'Mapa final'!#REF!="Moderado"),CONCATENATE("R",'Mapa final'!#REF!),"") -> #REF! | X20: =IF(AND('Mapa final'!$H$19="Alta",'Mapa final'!$L$19="Moderado"),CONCATENATE("R",'Mapa final'!$A$19),"") | Z20: =IF(AND('Mapa final'!$H$25="Alta",'Mapa final'!$L$25="Moderado"),CONCATENATE("R",'Mapa final'!$A$25),"") | AB20: =IF(AND('Mapa final'!#REF!="Alta",'Mapa final'!#REF!="Mayor"),CONCATENATE("R",'Mapa final'!#REF!),"") -> #REF! | AD20: =IF(AND('Mapa final'!$H$19="Alta",'Mapa final'!$L$19="Mayor"),CONCATENATE("R",'Mapa final'!$A$19),"") | AF20: =IF(AND('Mapa final'!$H$25="Alta",'Mapa final'!$L$25="Mayor"),CONCATENATE("R",'Mapa final'!$A$25),"") | AH20: =IF(AND('Mapa final'!#REF!="Alta",'Mapa final'!#REF!="Catastrófico"),CONCATENATE("R",'Mapa final'!#REF!),"") -> #REF! | AJ20: =IF(AND('Mapa final'!$H$19="Alta",'Mapa final'!$L$19="Catastrófico"),CONCATENATE("R",'Mapa final'!$A$19),"") | AL20: =IF(AND('Mapa final'!$H$25="Alta",'Mapa final'!$L$25="Catastrófico"),CONCATENATE("R",'Mapa final'!$A$25),"")
E22: Media 60% | J22: =IF(AND('Mapa final'!$H$13="Media",'Mapa final'!$L$13="Leve"),CONCATENATE("R",'Mapa final'!$A$13),"") | L22: =IF(AND('Mapa final'!#REF!="Media",'Mapa final'!#REF!="Leve"),CONCATENATE("R",'Mapa final'!#REF!),"") -> #REF! | N22: =IF(AND('Mapa final'!#REF!="Media",'Mapa final'!#REF!="Leve"),CONCATENATE("R",'Mapa final'!#REF!),"") -> #REF! | P22: =IF(AND('Mapa final'!$H$13="Media",'Mapa final'!$L$13="Menor"),CONCATENATE("R",'Mapa final'!$A$13),"") | R22: =IF(AND('Mapa final'!#REF!="Media",'Mapa final'!#REF!="Menor"),CONCATENATE("R",'Mapa final'!#REF!),"") -> #REF! | T22: =IF(AND('Mapa final'!#REF!="Media",'Mapa final'!#REF!="Menor"),CONCATENATE("R",'Mapa final'!#REF!),"") -> #REF! | V22: =IF(AND('Mapa final'!$H$13="Media",'Mapa final'!$L$13="Moderado"),CONCATENATE("R",'Mapa final'!$A$13),"") | X22: =IF(AND('Mapa final'!#REF!="Media",'Mapa final'!#REF!="Moderado"),CONCATENATE("R",'Mapa final'!#REF!),"") -> #REF! | Z22: =IF(AND('Mapa final'!#REF!="Media",'Mapa final'!#REF!="Moderado"),CONCATENATE("R",'Mapa final'!#REF!),"") -> #REF! | AB22: =IF(AND('Mapa final'!$H$13="Media",'Mapa final'!$L$13="Mayor"),CONCATENATE("R",'Mapa final'!$A$13),"") | AD22: =IF(AND('Mapa final'!#REF!="Media",'Mapa final'!#REF!="Mayor"),CONCATENATE("R",'Mapa final'!#REF!),"") -> #REF! | AF22: =IF(AND('Mapa final'!#REF!="Media",'Mapa final'!#REF!="Mayor"),CONCATENATE("R",'Mapa final'!#REF!),"") -> #REF! | AH22: =IF(AND('Mapa final'!$H$13="Media",'Mapa final'!$L$13="Catastrófico"),CONCATENATE("R",'Mapa final'!$A$13),"") | AJ22: =IF(AND('Mapa final'!#REF!="Media",'Mapa final'!#REF!="Catastrófico"),CONCATENATE("R",'Mapa final'!#REF!),"") -> #REF! | AL22: =IF(AND('Mapa final'!#REF!="Media",'Mapa final'!#REF!="Catastrófico"),CONCATENATE("R",'Mapa final'!#REF!),"") -> #REF! | AO22: Moderado
J24: =IF(AND('Mapa final'!#REF!="Media",'Mapa final'!#REF!="Leve"),CONCATENATE("R",'Mapa final'!#REF!),"") -> #REF! | L24: =IF(AND('Mapa final'!#REF!="Media",'Mapa final'!#REF!="Leve"),CONCATENATE("R",'Mapa final'!#REF!),"") -> #REF! | N24: =IF(AND('Mapa final'!#REF!="Media",'Mapa final'!#REF!="Leve"),CONCATENATE("R",'Mapa final'!#REF!),"") -> #REF! | P24: =IF(AND('Mapa final'!#REF!="Media",'Mapa final'!#REF!="Menor"),CONCATENATE("R",'Mapa final'!#REF!),"") -> #REF! | R24: =IF(AND('Mapa final'!#REF!="Media",'Mapa final'!#REF!="Menor"),CONCATENATE("R",'Mapa final'!#REF!),"") -> #REF! | T24: =IF(AND('Mapa final'!#REF!="Media",'Mapa final'!#REF!="Menor"),CONCATENATE("R",'Mapa final'!#REF!),"") -> #REF! | V24: =IF(AND('Mapa final'!#REF!="Media",'Mapa final'!#REF!="Moderado"),CONCATENATE("R",'Mapa final'!#REF!),"") -> #REF! | X24: =IF(AND('Mapa final'!#REF!="Media",'Mapa final'!#REF!="Moderado"),CONCATENATE("R",'Mapa final'!#REF!),"") -> #REF! | Z24: =IF(AND('Mapa final'!#REF!="Media",'Mapa final'!#REF!="Moderado"),CONCATENATE("R",'Mapa final'!#REF!),"") -> #REF! | AB24: =IF(AND('Mapa final'!#REF!="Media",'Mapa final'!#REF!="Mayor"),CONCATENATE("R",'Mapa final'!#REF!),"") -> #REF! | AD24: =IF(AND('Mapa final'!#REF!="Media",'Mapa final'!#REF!="Mayor"),CONCATENATE("R",'Mapa final'!#REF!),"") -> #REF! | AF24: =IF(AND('Mapa final'!#REF!="Media",'Mapa final'!#REF!="Mayor"),CONCATENATE("R",'Mapa final'!#REF!),"") -> #REF! | AH24: =IF(AND('Mapa final'!#REF!="Media",'Mapa final'!#REF!="Catastrófico"),CONCATENATE("R",'Mapa final'!#REF!),"") -> #REF! | AJ24: =IF(AND('Mapa final'!#REF!="Media",'Mapa final'!#REF!="Catastrófico"),CONCATENATE("R",'Mapa final'!#REF!),"") -> #REF! | AL24: =IF(AND('Mapa final'!#REF!="Media",'Mapa final'!#REF!="Catastrófico"),CONCATENATE("R",'Mapa final'!#REF!),"") -> #REF!
J26: =IF(AND('Mapa final'!#REF!="Media",'Mapa final'!#REF!="Leve"),CONCATENATE("R",'Mapa final'!#REF!),"") -> #REF! | L26: =IF(AND('Mapa final'!#REF!="Media",'Mapa final'!#REF!="Leve"),CONCATENATE("R",'Mapa final'!#REF!),"") -> #REF! | N26: =IF(AND('Mapa final'!#REF!="Media",'Mapa final'!#REF!="Leve"),CONCATENATE("R",'Mapa final'!#REF!),"") -> #REF! | P26: =IF(AND('Mapa final'!#REF!="Media",'Mapa final'!#REF!="Menor"),CONCATENATE("R",'Mapa final'!#REF!),"") -> #REF! | R26: =IF(AND('Mapa final'!#REF!="Media",'Mapa final'!#REF!="Menor"),CONCATENATE("R",'Mapa final'!#REF!),"") -> #REF! | T26: =IF(AND('Mapa final'!#REF!="Media",'Mapa final'!#REF!="Menor"),CONCATENATE("R",'Mapa final'!#REF!),"") -> #REF! | V26: =IF(AND('Mapa final'!#REF!="Media",'Mapa final'!#REF!="Moderado"),CONCATENATE("R",'Mapa final'!#REF!),"") -> #REF! | X26: =IF(AND('Mapa final'!#REF!="Media",'Mapa final'!#REF!="Moderado"),CONCATENATE("R",'Mapa final'!#REF!),"") -> #REF! | Z26: =IF(AND('Mapa final'!#REF!="Media",'Mapa final'!#REF!="Moderado"),CONCATENATE("R",'Mapa final'!#REF!),"") -> #REF! | AB26: =IF(AND('Mapa final'!#REF!="Media",'Mapa final'!#REF!="Mayor"),CONCATENATE("R",'Mapa final'!#REF!),"") -> #REF! | AD26: =IF(AND('Mapa final'!#REF!="Media",'Mapa final'!#REF!="Mayor"),CONCATENATE("R",'Mapa final'!#REF!),"") -> #REF! | AF26: =IF(AND('Mapa final'!#REF!="Media",'Mapa final'!#REF!="Mayor"),CONCATENATE("R",'Mapa final'!#REF!),"") -> #REF! | AH26: =IF(AND('Mapa final'!#REF!="Media",'Mapa final'!#REF!="Catastrófico"),CONCATENATE("R",'Mapa final'!#REF!),"") -> #REF! | AJ26: =IF(AND('Mapa final'!#REF!="Media",'Mapa final'!#REF!="Catastrófico"),CONCATENATE("R",'Mapa final'!#REF!),"") -> #REF! | AL26: =IF(AND('Mapa final'!#REF!="Media",'Mapa final'!#REF!="Catastrófico"),CONCATENATE("R",'Mapa final'!#REF!),"") -> #REF!
J28: =IF(AND('Mapa final'!#REF!="Media",'Mapa final'!#REF!="Leve"),CONCATENATE("R",'Mapa final'!#REF!),"") -> #REF! | L28: =IF(AND('Mapa final'!$H$19="Media",'Mapa final'!$L$19="Leve"),CONCATENATE("R",'Mapa final'!$A$19),"") | N28: =IF(AND('Mapa final'!$H$25="Media",'Mapa final'!$L$25="Leve"),CONCATENATE("R",'Mapa final'!$A$25),"") | P28: =IF(AND('Mapa final'!#REF!="Media",'Mapa final'!#REF!="Menor"),CONCATENATE("R",'Mapa final'!#REF!),"") -> #REF! | R28: =IF(AND('Mapa final'!$H$19="Media",'Mapa final'!$L$19="Menor"),CONCATENATE("R",'Mapa final'!$A$19),"") | T28: =IF(AND('Mapa final'!$H$25="Media",'Mapa final'!$L$25="Menor"),CONCATENATE("R",'Mapa final'!$A$25),"") | V28: =IF(AND('Mapa final'!#REF!="Media",'Mapa final'!#REF!="Moderado"),CONCATENATE("R",'Mapa final'!#REF!),"") -> #REF! | X28: =IF(AND('Mapa final'!$H$19="Media",'Mapa final'!$L$19="Moderado"),CONCATENATE("R",'Mapa final'!$A$19),"") | Z28: =IF(AND('Mapa final'!$H$25="Media",'Mapa final'!$L$25="Moderado"),CONCATENATE("R",'Mapa final'!$A$25),"") | AB28: =IF(AND('Mapa final'!#REF!="Media",'Mapa final'!#REF!="Mayor"),CONCATENATE("R",'Mapa final'!#REF!),"") -> #REF! | AD28: =IF(AND('Mapa final'!$H$19="Media",'Mapa final'!$L$19="Mayor"),CONCATENATE("R",'Mapa final'!$A$19),"") | AF28: =IF(AND('Mapa final'!$H$25="Media",'Mapa final'!$L$25="Mayor"),CONCATENATE("R",'Mapa final'!$A$25),"") | AH28: =IF(AND('Mapa final'!#REF!="Media",'Mapa final'!#REF!="Catastrófico"),CONCATENATE("R",'Mapa final'!#REF!),"") -> #REF! | AJ28: =IF(AND('Mapa final'!$H$19="Media",'Mapa final'!$L$19="Catastrófico"),CONCATENATE("R",'Mapa final'!$A$19),"") | AL28: =IF(AND('Mapa final'!$H$25="Media",'Mapa final'!$L$25="Catastrófico"),CONCATENATE("R",'Mapa final'!$A$25),"")
E30: Baja 40% | J30: =IF(AND('Mapa final'!$H$13="Baja",'Mapa final'!$L$13="Leve"),CONCATENATE("R",'Mapa final'!$A$13),"") | L30: =IF(AND('Mapa final'!#REF!="Baja",'Mapa final'!#REF!="Leve"),CONCATENATE("R",'Mapa final'!#REF!),"") -> #REF! | N30: =IF(AND('Mapa final'!#REF!="Baja",'Mapa final'!#REF!="Leve"),CONCATENATE("R",'Mapa final'!#REF!),"") -> #REF! | P30: =IF(AND('Mapa final'!$H$13="Baja",'Mapa final'!$L$13="Menor"),CONCATENATE("R",'Mapa final'!$A$13),"") | R30: =IF(AND('Mapa final'!#REF!="Baja",'Mapa final'!#REF!="Menor"),CONCATENATE("R",'Mapa final'!#REF!),"") -> #REF! | T30: =IF(AND('Mapa final'!#REF!="Baja",'Mapa final'!#REF!="Menor"),CONCATENATE("R",'Mapa final'!#REF!),"") -> #REF! | V30: =IF(AND('Mapa final'!$H$13="Baja",'Mapa final'!$L$13="Moderado"),CONCATENATE("R",'Mapa final'!$A$13),"") | X30: =IF(AND('Mapa final'!#REF!="Baja",'Mapa final'!#REF!="Moderado"),CONCATENATE("R",'Mapa final'!#REF!),"") -> #REF! | Z30: =IF(AND('Mapa final'!#REF!="Baja",'Mapa final'!#REF!="Moderado"),CONCATENATE("R",'Mapa final'!#REF!),"") -> #REF! | AB30: =IF(AND('Mapa final'!$H$13="Baja",'Mapa final'!$L$13="Mayor"),CONCATENATE("R",'Mapa final'!$A$13),"") | AD30: =IF(AND('Mapa final'!#REF!="Baja",'Mapa final'!#REF!="Mayor"),CONCATENATE("R",'Mapa final'!#REF!),"") -> #REF! | AF30: =IF(AND('Mapa final'!#REF!="Baja",'Mapa final'!#REF!="Mayor"),CONCATENATE("R",'Mapa final'!#REF!),"") -> #REF! | AH30: =IF(AND('Mapa final'!$H$13="Baja",'Mapa final'!$L$13="Catastrófico"),CONCATENATE("R",'Mapa final'!$A$13),"") | AJ30: =IF(AND('Mapa final'!#REF!="Baja",'Mapa final'!#REF!="Catastrófico"),CONCATENATE("R",'Mapa final'!#REF!),"") -> #REF! | AL30: =IF(AND('Mapa final'!#REF!="Baja",'Mapa final'!#REF!="Catastrófico"),CONCATENATE("R",'Mapa final'!#REF!),"") -> #REF! | AO30: Bajo
J32: =IF(AND('Mapa final'!#REF!="Baja",'Mapa final'!#REF!="Leve"),CONCATENATE("R",'Mapa final'!#REF!),"") -> #REF! | L32: =IF(AND('Mapa final'!#REF!="Baja",'Mapa final'!#REF!="Leve"),CONCATENATE("R",'Mapa final'!#REF!),"") -> #REF! | N32: =IF(AND('Mapa final'!#REF!="Baja",'Mapa final'!#REF!="Leve"),CONCATENATE("R",'Mapa final'!#REF!),"") -> #REF! | P32: =IF(AND('Mapa final'!#REF!="Baja",'Mapa final'!#REF!="Menor"),CONCATENATE("R",'Mapa final'!#REF!),"") -> #REF! | R32: =IF(AND('Mapa final'!#REF!="Baja",'Mapa final'!#REF!="Menor"),CONCATENATE("R",'Mapa final'!#REF!),"") -> #REF! | T32: =IF(AND('Mapa final'!#REF!="Baja",'Mapa final'!#REF!="Menor"),CONCATENATE("R",'Mapa final'!#REF!),"") -> #REF! | V32: =IF(AND('Mapa final'!#REF!="Baja",'Mapa final'!#REF!="Moderado"),CONCATENATE("R",'Mapa final'!#REF!),"") -> #REF! | X32: =IF(AND('Mapa final'!#REF!="Baja",'Mapa final'!#REF!="Moderado"),CONCATENATE("R",'Mapa final'!#REF!),"") -> #REF! | Z32: =IF(AND('Mapa final'!#REF!="Baja",'Mapa final'!#REF!="Moderado"),CONCATENATE("R",'Mapa final'!#REF!),"") -> #REF! | AB32: =IF(AND('Mapa final'!#REF!="Baja",'Mapa final'!#REF!="Mayor"),CONCATENATE("R",'Mapa final'!#REF!),"") -> #REF! | AD32: =IF(AND('Mapa final'!#REF!="Baja",'Mapa final'!#REF!="Mayor"),CONCATENATE("R",'Mapa final'!#REF!),"") -> #REF! | AF32: =IF(AND('Mapa final'!#REF!="Baja",'Mapa final'!#REF!="Mayor"),CONCATENATE("R",'Mapa final'!#REF!),"") -> #REF! | AH32: =IF(AND('Mapa final'!#REF!="Baja",'Mapa final'!#REF!="Catastrófico"),CONCATENATE("R",'Mapa final'!#REF!),"") -> #REF! | AJ32: =IF(AND('Mapa final'!#REF!="Baja",'Mapa final'!#REF!="Catastrófico"),CONCATENATE("R",'Mapa final'!#REF!),"") -> #REF! | AL32: =IF(AND('Mapa final'!#REF!="Baja",'Mapa final'!#REF!="Catastrófico"),CONCATENATE("R",'Mapa final'!#REF!),"") -> #REF!
J34: =IF(AND('Mapa final'!#REF!="Baja",'Mapa final'!#REF!="Leve"),CONCATENATE("R",'Mapa final'!#REF!),"") -> #REF! | L34: =IF(AND('Mapa final'!#REF!="Baja",'Mapa final'!#REF!="Leve"),CONCATENATE("R",'Mapa final'!#REF!),"") -> #REF! | N34: =IF(AND('Mapa final'!#REF!="Baja",'Mapa final'!#REF!="Leve"),CONCATENATE("R",'Mapa final'!#REF!),"") -> #REF! | P34: =IF(AND('Mapa final'!#REF!="Baja",'Mapa final'!#REF!="Menor"),CONCATENATE("R",'Mapa final'!#REF!),"") -> #REF! | R34: =IF(AND('Mapa final'!#REF!="Baja",'Mapa final'!#REF!="Menor"),CONCATENATE("R",'Mapa final'!#REF!),"") -> #REF! | T34: =IF(AND('Mapa final'!#REF!="Baja",'Mapa final'!#REF!="Menor"),CONCATENATE("R",'Mapa final'!#REF!),"") -> #REF! | V34: =IF(AND('Mapa final'!#REF!="Baja",'Mapa final'!#REF!="Moderado"),CONCATENATE("R",'Mapa final'!#REF!),"") -> #REF! | X34: =IF(AND('Mapa final'!#REF!="Baja",'Mapa final'!#REF!="Moderado"),CONCATENATE("R",'Mapa final'!#REF!),"") -> #REF! | Z34: =IF(AND('Mapa final'!#REF!="Baja",'Mapa final'!#REF!="Moderado"),CONCATENATE("R",'Mapa final'!#REF!),"") -> #REF! | AB34: =IF(AND('Mapa final'!#REF!="Baja",'Mapa final'!#REF!="Mayor"),CONCATENATE("R",'Mapa final'!#REF!),"") -> #REF! | AD34: =IF(AND('Mapa final'!#REF!="Baja",'Mapa final'!#REF!="Mayor"),CONCATENATE("R",'Mapa final'!#REF!),"") -> #REF! | AF34: =IF(AND('Mapa final'!#REF!="Baja",'Mapa final'!#REF!="Mayor"),CONCATENATE("R",'Mapa final'!#REF!),"") -> #REF! | AH34: =IF(AND('Mapa final'!#REF!="Baja",'Mapa final'!#REF!="Catastrófico"),CONCATENATE("R",'Mapa final'!#REF!),"") -> #REF! | AJ34: =IF(AND('Mapa final'!#REF!="Baja",'Mapa final'!#REF!="Catastrófico"),CONCATENATE("R",'Mapa final'!#REF!),"") -> #REF! | AL34: =IF(AND('Mapa final'!#REF!="Baja",'Mapa final'!#REF!="Catastrófico"),CONCATENATE("R",'Mapa final'!#REF!),"") -> #REF!
J36: =IF(AND('Mapa final'!#REF!="Baja",'Mapa final'!#REF!="Leve"),CONCATENATE("R",'Mapa final'!#REF!),"") -> #REF! | L36: =IF(AND('Mapa final'!$H$19="Baja",'Mapa final'!$L$19="Leve"),CONCATENATE("R",'Mapa final'!$A$19),"") | N36: =IF(AND('Mapa final'!$H$25="Baja",'Mapa final'!$L$25="Leve"),CONCATENATE("R",'Mapa final'!$A$25),"") | P36: =IF(AND('Mapa final'!#REF!="Baja",'Mapa final'!#REF!="Menor"),CONCATENATE("R",'Mapa final'!#REF!),"") -> #REF! | R36: =IF(AND('Mapa final'!$H$19="Baja",'Mapa final'!$L$19="Menor"),CONCATENATE("R",'Mapa final'!$A$19),"") | T36: =IF(AND('Mapa final'!$H$25="Baja",'Mapa final'!$L$25="Menor"),CONCATENATE("R",'Mapa final'!$A$25),"") | V36: =IF(AND('Mapa final'!#REF!="Baja",'Mapa final'!#REF!="Moderado"),CONCATENATE("R",'Mapa final'!#REF!),"") -> #REF! | X36: =IF(AND('Mapa final'!$H$19="Baja",'Mapa final'!$L$19="Moderado"),CONCATENATE("R",'Mapa final'!$A$19),"") | Z36: =IF(AND('Mapa final'!$H$25="Baja",'Mapa final'!$L$25="Moderado"),CONCATENATE("R",'Mapa final'!$A$25),"") | AB36: =IF(AND('Mapa final'!#REF!="Baja",'Mapa final'!#REF!="Mayor"),CONCATENATE("R",'Mapa final'!#REF!),"") -> #REF! | AD36: =IF(AND('Mapa final'!$H$19="Baja",'Mapa final'!$L$19="Mayor"),CONCATENATE("R",'Mapa final'!$A$19),"") | AF36: =IF(AND('Mapa final'!$H$25="Baja",'Mapa final'!$L$25="Mayor"),CONCATENATE("R",'Mapa final'!$A$25),"") | AH36: =IF(AND('Mapa final'!#REF!="Baja",'Mapa final'!#REF!="Catastrófico"),CONCATENATE("R",'Mapa final'!#REF!),"") -> #REF! | AJ36: =IF(AND('Mapa final'!$H$19="Baja",'Mapa final'!$L$19="Catastrófico"),CONCATENATE("R",'Mapa final'!$A$19),"") | AL36: =IF(AND('Mapa final'!$H$25="Baja",'Mapa final'!$L$25="Catastrófico"),CONCATENATE("R",'Mapa final'!$A$25),"")
E38: Muy Baja 20% | J38: =IF(AND('Mapa final'!$H$13="Muy Baja",'Mapa final'!$L$13="Leve"),CONCATENATE("R",'Mapa final'!$A$13),"") | L38: =IF(AND('Mapa final'!#REF!="Muy Baja",'Mapa final'!#REF!="Leve"),CONCATENATE("R",'Mapa final'!#REF!),"") -> #REF! | N38: =IF(AND('Mapa final'!#REF!="Muy Baja",'Mapa final'!#REF!="Leve"),CONCATENATE("R",'Mapa final'!#REF!),"") -> #REF! | P38: =IF(AND('Mapa final'!$H$13="Muy Baja",'Mapa final'!$L$13="Menor"),CONCATENATE("R",'Mapa final'!$A$13),"") | R38: =IF(AND('Mapa final'!#REF!="Muy Baja",'Mapa final'!#REF!="Menor"),CONCATENATE("R",'Mapa final'!#REF!),"") -> #REF! | T38: =IF(AND('Mapa final'!#REF!="Muy Baja",'Mapa final'!#REF!="Menor"),CONCATENATE("R",'Mapa final'!#REF!),"") -> #REF! | V38: =IF(AND('Mapa final'!$H$13="Muy Baja",'Mapa final'!$L$13="Moderado"),CONCATENATE("R",'Mapa final'!$A$13),"") | X38: =IF(AND('Mapa final'!#REF!="Muy Baja",'Mapa final'!#REF!="Moderado"),CONCATENATE("R",'Mapa final'!#REF!),"") -> #REF! | Z38: =IF(AND('Mapa final'!#REF!="Muy Baja",'Mapa final'!#REF!="Moderado"),CONCATENATE("R",'Mapa final'!#REF!),"") -> #REF! | AB38: =IF(AND('Mapa final'!$H$13="Muy Baja",'Mapa final'!$L$13="Mayor"),CONCATENATE("R",'Mapa final'!$A$13),"") | AD38: =IF(AND('Mapa final'!#REF!="Muy Baja",'Mapa final'!#REF!="Mayor"),CONCATENATE("R",'Mapa final'!#REF!),"") -> #REF! | AF38: =IF(AND('Mapa final'!#REF!="Muy Baja",'Mapa final'!#REF!="Mayor"),CONCATENATE("R",'Mapa final'!#REF!),"") -> #REF! | AH38: =IF(AND('Mapa final'!$H$13="Muy Baja",'Mapa final'!$L$13="Catastrófico"),CONCATENATE("R",'Mapa final'!$A$13),"") | AJ38: =IF(AND('Mapa final'!#REF!="Muy Baja",'Mapa final'!#REF!="Catastrófico"),CONCATENATE("R",'Mapa final'!#REF!),"") -> #REF! | AL38: =IF(AND('Mapa final'!#REF!="Muy Baja",'Mapa final'!#REF!="Catastrófico"),CONCATENATE("R",'Mapa final'!#REF!),"") -> #REF!
J40: =IF(AND('Mapa final'!#REF!="Muy Baja",'Mapa final'!#REF!="Leve"),CONCATENATE("R",'Mapa final'!#REF!),"") -> #REF! | L40: =IF(AND('Mapa final'!#REF!="Muy Baja",'Mapa final'!#REF!="Leve"),CONCATENATE("R",'Mapa final'!#REF!),"") -> #REF! | N40: =IF(AND('Mapa final'!#REF!="Muy Baja",'Mapa final'!#REF!="Leve"),CONCATENATE("R",'Mapa final'!#REF!),"") -> #REF! | P40: =IF(AND('Mapa final'!#REF!="Muy Baja",'Mapa final'!#REF!="Menor"),CONCATENATE("R",'Mapa final'!#REF!),"") -> #REF! | R40: =IF(AND('Mapa final'!#REF!="Muy Baja",'Mapa final'!#REF!="Menor"),CONCATENATE("R",'Mapa final'!#REF!),"") -> #REF! | T40: =IF(AND('Mapa final'!#REF!="Muy Baja",'Mapa final'!#REF!="Menor"),CONCATENATE("R",'Mapa final'!#REF!),"") -> #REF! | V40: =IF(AND('Mapa final'!#REF!="Muy Baja",'Mapa final'!#REF!="Moderado"),CONCATENATE("R",'Mapa final'!#REF!),"") -> #REF! | X40: =IF(AND('Mapa final'!#REF!="Muy Baja",'Mapa final'!#REF!="Moderado"),CONCATENATE("R",'Mapa final'!#REF!),"") -> #REF! | Z40: =IF(AND('Mapa final'!#REF!="Muy Baja",'Mapa final'!#REF!="Moderado"),CONCATENATE("R",'Mapa final'!#REF!),"") -> #REF! | AB40: =IF(AND('Mapa final'!#REF!="Muy Baja",'Mapa final'!#REF!="Mayor"),CONCATENATE("R",'Mapa final'!#REF!),"") -> #REF! | AD40: =IF(AND('Mapa final'!#REF!="Muy Baja",'Mapa final'!#REF!="Mayor"),CONCATENATE("R",'Mapa final'!#REF!),"") -> #REF! | AF40: =IF(AND('Mapa final'!#REF!="Muy Baja",'Mapa final'!#REF!="Mayor"),CONCATENATE("R",'Mapa final'!#REF!),"") -> #REF! | AH40: =IF(AND('Mapa final'!#REF!="Muy Baja",'Mapa final'!#REF!="Catastrófico"),CONCATENATE("R",'Mapa final'!#REF!),"") -> #REF! | AJ40: =IF(AND('Mapa final'!#REF!="Muy Baja",'Mapa final'!#REF!="Catastrófico"),CONCATENATE("R",'Mapa final'!#REF!),"") -> #REF! | AL40: =IF(AND('Mapa final'!#REF!="Muy Baja",'Mapa final'!#REF!="Catastrófico"),CONCATENATE("R",'Mapa final'!#REF!),"") -> #REF!
