Workbook

Sheet Instructivo
B2: Matriz Mapa de Riesgos
B4: Teniendo en cuenta que con la expedición del Decreto 1499 de 2017 “Por medio del cual se modifica el Decreto 1083 de 2015, Decreto Único Reglamentario del Sector Función Pública, en lo relacionado con el Sistema de Gestión establecido en el artículo 133 de la Ley 1753 de 2015”, se crea un solo Sistema de Gestión y se alinea con el Sistema de Control Interno, hoy todas las entidades públicas requieren actualizar y/o implementar el Modelo Integrado de Planeación y Gestión MIPG, modelo que incorpora el Modelo Estándar de Control Interno MECI a través de la 7a dimensión del mismo. En este marco general, el proceso de administración del riesgo es un esfuerzo conjunto entre la Alta Dirección y los servidores en todos sus niveles, ejercicio que inicia con la formulación de la política de Administración del Riesgo, la cual incluye los niveles de responsabilidad frente al seguimiento y evaluación, aspectos que deberán definirse acorde con el Esquema de Líneas de Defensa vinculado a la Dimensión 7. Teniendo en cuenta lo anterior y dada la necesidad de las entidades frente a la estructuración de los mapas de riesgos, como herramienta fundamental frente a la gestión del riesgo, el presente formato desarrolla un esquema completo acorde con los contenidos metodológicos de la Guía para la Administración del Riesgo y el diseño de controles V5. El formato cuenta con celdas parametrizadas y permite contar con los respectivos mapas de calor para riesgo inherente y riesgo residual.
B6: Orientaciones Generales
B7: Antes de iniciar con el diligenciamiento de la información en la matriz, se requiere haber avanzado en el análisis del proceso, su objetivo, alcance, actividades clave, considere los lineamientos establecidos en el Paso 2: identificación del riesgo, donde se explica ampliamente las bases para adelanter este análisis. Así mismo, considere en el Paso 3: valoración del riesgo los lineamientos para definir el No. de veces que se hace la actividad con la cual se relaciona el riesgo y su impacto en términos económicos o reputacionales. En este mismo paso se analizan los controles que deben responder a los atributos de eficiencia e informativos. NOTA: Si lo considera pertinente, es posible agregar hojas de trabajo adicionales al presente formato que permitan incluir la traza de estos análisis.
B9: El archivo contiene las siguientes hojas: - Hoja 1 Instructivo - Hoja 2 Mapa Final: Encontrará la totalidad de la estructura para la identificación y valoración de los riesgos por proceso, programa o proyecto, acorde con el nivel de desagregación que la entidad considere necesaria.
C12: Columna | E12: Descripción - Lineamientos para el diligenciamiento
C13: Proceso | E13: Diligencie el nombre del proceso al cual se le identificarán y valorarán los riesgos.
C14: Objetivo | E14: Diligencie el objetivo del proceso.
C15: Alcance | E15: Diligencie el alcance del proceso.
C16: Referencia | E16: Permite definir unl consecutivo de riesgos. Una entidad puede ir en el riesgo 150, pero tener 70 riesgos, lo que permite llevar una traza de los riesgos. Esta información la debe administrar la oficina asesora de planeación o gerencia de riesgos. Cuando un el riesgo salga del mapa no existirá otro riesgo con el mismo número.
C17: Impacto | E17: Analice las consecuencias que puede ocasionar a la organización la materialización del riesgo, redacte de la forma más concreta posible.
C18: Causa Inmediata | E18: Circunstancias bajo las cuales se presenta el riesgo, es la situación más evidente frente al riesgo, redacte de la forma más concreta posible.
C19: Causa Raíz | E19: Causa principal o básica, corresponde a las razones por la cuales se puede presentar el riesgo, redacte de la forma más concreta posible.
C20: Descripción del Riesgo | E20: Consolida o resume los análisis sobre impacto + causa inmediata + causa raíz, permitiendo contar con una redacción clara y concreta del riesgo indentificado. Tenga en cuenta la estructura de alto nivel establecida en al guía, inicia con POSIBILIDAD DE + Impacto para la entidad (Qué) + Causa Inmediata (Cómo) + Causa Raíz (Por qué)
C21: Clasificación del Riesgo | E21: Utilice la lista de despligue que se encuentra parametrizada, le aparecerán las opciones: i)Daños Activos Fisicos, ii)Ejecucion y Administracion de procesos, iii)Fallas Tecnologicas, iv)Fraude Externo, v)Fraude Interno, vi)Relaciones Laborales, vii)Usuarios, productos y practicas organizacionales.
C22: Frecuencia con la cual se lleva a cabo la actividad | E22: Defina el # de veces que se ejecuta la actividad durante el año, (Recuerde la probabilidad e ocurrencia del riesgo se defien como el No. de veces que se pasa por el punto de riesgo en el periodo de 1 año). La matriz automáticamente hará el cálculo para el nivel de probabilidad inherente (Columnas H-I)
C23: Criterios de Impacto | E23: Utilice la lista de despligue que se encuentra parametrizada, le aparecerán las opciones de la tabla de Impacto en la Hoja 6 del presente documento. La matriz automáticamente hará el cálculo para el nivel de impacto inherente (Columnas L-M)
... C37: Estado | E37: Utilice la lista de despligue que se encuentra parametrizada, le aparecerán las opciones: i)Finalizado, ii)En curso, la selección en este caso dependerá de las acciones del plan que se hayan establecido en cada caso.
B40: - Hoja 3 Matriz de Calor Inherente: En esta hoja, en la medida en que ese diligencia el Mapa Final, se verán reflejados los riesgos en su zona correspondiente. Esta hoja no se diligencia se genera de manera automática.
B41: - Hoja 4 Matriz de Calor Residual: En esta hoja, en la medida en que ese diligencia el Mapa Final, se verán reflejados los riesgos en su zona correspondiente. Esta hoja no se diligencia se genera de manera automática.
B42: - Hoja 5 Tabla de probabilidad: Tabla referente para todos los cálculos (no se diligencia)
B43: - Hoja 6 Tabla de Impacto: Tabla referente para todos los cálculos (no se diligencia)
B44: - Hoja 7 Tabla de Valoración de Controles: Tabla referente para todos los cálculos (no se diligencia)

Sheet Mapa final
D1: SISTEMA DE GESTIÓN DE CALIDAD
D3: GESTIÓN DE CALIDAD
D4: MAPA DE RIESGOS
D5: VERSIÓN: 05 | G5: FECHA: 07-05-2025 | J5: Página 1 de 1
D6: SISTEMA DE GESTIÓN DE CALIDAD
A7: Proceso: | C7: DIRECCIONAMIENTO ESTRATEGICO Y COMUNICACIONES
A8: Objetivo: | C8: Aprobar y hacer seguimiento a la ejecución del Plan de Acción de la Corporación, así como al funcionamiento administrativo de la misma acorde con la normatividad vigente, garantizando que la comunidad y los grupos de interés participen y cuenten con la información veraz y oportuna.
A9: Alcance: | C9: Inicia con la formulación del plan de acción de la Corporación y demás instrumentos de planeación, así como su oportuna divulgación y finaliza con el seguimiento y evaluación del Proceso.
A10: {=A10:G17Identificación del riesgo} -> #NAME? | H10: Análisis del riesgo inherente | O10: Evaluación del riesgo - Valoración de los controles | X10: Evaluación del riesgo - Nivel del riesgo residual | AE10: Plan de Acción | AH10: I SEGUIMIENTO 2025 Corte 30 de Abril | AK10: II SEGUIMIENTO 2025 Corte 31 de Agosto | AN10: III SEGUIMIENTO 2025 Corte 31 de Diciembre
A11: Referencia | B11: Impacto | C11: Causa Inmediata | D11: Causa Raíz | E11: Descripción del Riesgo | F11: Clasificación del Riesgo | G11: Frecuencia con la cual se realiza la actividad | H11: Probabilidad Inherente | I11: % | J11: Criterios de impacto | K11: Observación de criterio | L11: Impacto Inherente | M11: % | N11: Zona de Riesgo Inherente | O11: No. Control | P11: Descripción del Control | Q11: Afectación | R11: Atributos | X11: Probabilidad Residual | Y11: Probabilidad Residual Final | Z11: % | AA11: Impacto Residual Final | AB11: % | AC11: Zona de Riesgo Final | AD11: Tratamiento | AE11: Plan de Acción | AF11: Responsable | AG11: Fecha Implementación | AH11: Fecha Seguimiento | AI11: Seguimiento | AJ11: Estado del Plan de Acción | AK11: Fecha Seguimiento | AL11: Seguimiento | AM11: Estado del Plan de Acción | AN11: Fecha Seguimiento | AO11: Seguimiento | AP11: Estado del Plan de Acción
R12: Tipo | S12: Implementación | T12: Calificación | U12: Documentación | V12: Frecuencia | W12: Evidencia
A13: 1 | B13: Reputacional | C13: Desinformaciòn | D13: Por no seguir y realizar seguimiento a los lineamientos de comunicaciòn establecidos en el PEC | E13: Posiblidad de afectación de imagen institucional por desinformación debido a no seguir y realizar seguimiento a los lineamientos de comunicación establecidos en el PECO | F13: Usuarios, productos y practicas , organizacionales | G13: 365 | H13: =IF(G13<=0,"",IF(G13<=2,"Muy Baja",IF(G13<=24,"Baja",IF(G13<=500,"Media",IF(G13<=5000,"Alta","Muy Alta"))))) -> Media | I13: =IF(H13="","",IF(H13="Muy Baja",0.2,IF(H13="Baja",0.4,IF(H13="Media",0.6,IF(H13="Alta",0.8,IF(H13="Muy Alta",1,)))))) -> 0.6 | J13: El riesgo afecta la imagen de de la entidad con efecto publicitario sostenido a nivel de sector administrativo, nivel departamental o municipal | K13: =IF(NOT(ISERROR(MATCH(J13,#REF!,0))),#REF!&"Por favor no seleccionar los criterios de impacto(Afectación Económica o presupuestal y Pérdida Reputacional)",J13) -> El riesgo afecta la imagen de de la entidad con efecto publicitario sostenido a nivel de sector administrativo, nivel departamental o municipal | L13: Media | M13: 0.6 | N13: Media | O13: 1 | P13: El Jefe asesor de la Oficina de Prensa, verifica que la información que se solicita publicar sea veraz a través de revisión de fuentes, documental, jurídica y normativa, antes de su publicación a los públicos de interés. | Q13: Impacto | R13: Preventivo | S13: Manual | T13: =IF(AND(R13="Preventivo",S13="Automático"),"50%",IF(AND(R13="Preventivo",S13="Manual"),"40%",IF(AND(R13="Detectivo",S13="Automático"),"40%",IF(AND(R13="Detectivo",S13="Manual"),"30%",IF(AND(R13="Correctivo",S13="Automático"),"35%",IF(AND(R13="Correctivo",S13="Manual"),"25%","")))))) -> 40% | U13: Documentado | V13: Continua | W13: Sin Registro | X13: =IFERROR(IF(Q13="Probabilidad",(I13-(+I13*T13)),IF(Q13="Impacto",I13,"")),"") -> 0.6 | Y13: =IFERROR(IF(X13="","",IF(X13<=0.2,"Muy Baja",IF(X13<=0.4,"Baja",IF(X13<=0.6,"Media",IF(X13<=0.8,"Alta","Muy Alta"))))),"") -> Media | Z13: =+X13 -> 0.6 | AA13: =IFERROR(IF(AB13="","",IF(AB13<=0.2,"Leve",IF(AB13<=0.4,"Menor",IF(AB13<=0.6,"Moderado",IF(AB13<=0.8,"Mayor","Catastrófico"))))),"") -> Menor | AB13: =IFERROR(IF(Q13="Impacto",(M13-(+M13*T13)),IF(Q13="Probabilidad",M13,"")),"") -> 0.36 | AC13: =IFERROR(IF(OR(AND(Y13="Muy Baja",AA13="Leve"),AND(Y13="Muy Baja",AA13="Menor"),AND(Y13="Baja",AA13="Leve")),"Bajo",IF(OR(AND(Y13="Muy baja",AA13="Moderado"),AND(Y13="Baja",AA13="Menor"),AND(Y13="Baja",AA13="Moderado"),AND(Y13="Media",AA13="Leve"),AND(Y13="Media",AA13="Menor"),AND(Y13="Media",AA13="Moderado"),AND(Y13="Alta",AA13="Leve"),AND(Y13="Alta",AA13="Menor")),"Moderado",IF(OR(AND(Y13="Muy Baja",AA13="Mayor"),AND(Y13="Baja",AA13="Mayor"),AND(Y13="Media",AA13="Mayor"),AND(Y13="Alta",AA13="Moderado"),AND(Y13="Alta",AA13="Mayor"),AND(Y13="Muy Alta",AA13="Leve"),AND(Y13="Muy Alta",AA13="Menor"),AND(Y13="Muy Alta",AA13="Moderado"),AND(Y13="Muy Alta",AA13="Mayor")),"Alto",IF(OR(AND(Y13="Muy Baja",AA13="Catastrófico"),AND(Y13="Baja",AA13="Catastrófico"),AND(Y13="Media",AA13="Catastrófico"),AND(Y13="Alta",AA13="Catastrófico"),AND(Y13="Muy Alta",AA13="Catastrófico")),"Extremo","")))),"") -> Moderado | AD13: Reducir (mitigar) | AE13: Revisar con el apoyo de la Alta Dirección, el manual de crisis de la Corporación. | AF13: Jefe Asesora de Prensa | AG13: 45930 | AH13: 45775 | AI13: Revision del primer borrador del manual de crisis | AJ13: Abierta | AK13: 45894 | AL13: Se ajustó el Manual de Crisis desde la Oficina Asesora de Prensa y Comunicaciones. | AM13: Abierto | AN13: 46006
K14: =IF(NOT(ISERROR(MATCH(J14,_xlfn.ANCHORARRAY(#REF!),0))),#REF!&"Por favor no seleccionar los criterios de impacto",J14) -> 0 | O14: 2 | P14: El presidente verifica y aprueba la informaciòn a publicar, verificando la pertinencia e impacto de la informaciòn hacia sus públicos de valor. | Q14: Impacto | R14: Preventivo | S14: Manual | T14: =IF(AND(R14="Preventivo",S14="Automático"),"50%",IF(AND(R14="Preventivo",S14="Manual"),"40%",IF(AND(R14="Detectivo",S14="Automático"),"40%",IF(AND(R14="Detectivo",S14="Manual"),"30%",IF(AND(R14="Correctivo",S14="Automático"),"35%",IF(AND(R14="Correctivo",S14="Manual"),"25%","")))))) -> 40% | U14: Documentado | V14: Continua | W14: Sin Registro | X14: =IFERROR(IF(AND(Q13="Probabilidad",Q14="Probabilidad"),(Z13-(+Z13*T14)),IF(Q14="Probabilidad",(I13-(+I13*T14)),IF(Q14="Impacto",Z13,""))),"") -> 0.6 | Y14: =IFERROR(IF(X14="","",IF(X14<=0.2,"Muy Baja",IF(X14<=0.4,"Baja",IF(X14<=0.6,"Media",IF(X14<=0.8,"Alta","Muy Alta"))))),"") -> Media | Z14: =+X14 -> 0.6 | AA14: =IFERROR(IF(AB14="","",IF(AB14<=0.2,"Leve",IF(AB14<=0.4,"Menor",IF(AB14<=0.6,"Moderado",IF(AB14<=0.8,"Mayor","Catastrófico"))))),"") -> Menor | AB14: =IFERROR(IF(AND(Q13="Impacto",Q14="Impacto"),(AB13-(+AB13*T14)),IF(Q14="Impacto",($M$13-(+$M$13*T14)),IF(Q14="Probabilidad",AB13,""))),"") -> 0.216 | AC14: =IFERROR(IF(OR(AND(Y14="Muy Baja",AA14="Leve"),AND(Y14="Muy Baja",AA14="Menor"),AND(Y14="Baja",AA14="Leve")),"Bajo",IF(OR(AND(Y14="Muy baja",AA14="Moderado"),AND(Y14="Baja",AA14="Menor"),AND(Y14="Baja",AA14="Moderado"),AND(Y14="Media",AA14="Leve"),AND(Y14="Media",AA14="Menor"),AND(Y14="Media",AA14="Moderado"),AND(Y14="Alta",AA14="Leve"),AND(Y14="Alta",AA14="Menor")),"Moderado",IF(OR(AND(Y14="Muy Baja",AA14="Mayor"),AND(Y14="Baja",AA14="Mayor"),AND(Y14="Media",AA14="Mayor"),AND(Y14="Alta",AA14="Moderado"),AND(Y14="Alta",AA14="Mayor"),AND(Y14="Muy Alta",AA14="Leve"),AND(Y14="Muy Alta",AA14="Menor"),AND(Y14="Muy Alta",AA14="Moderado"),AND(Y14="Muy Alta",AA14="Mayor")),"Alto",IF(OR(AND(Y14="Muy Baja",AA14="Catastrófico"),AND(Y14="Baja",AA14="Catastrófico"),AND(Y14="Media",AA14="Catastrófico"),AND(Y14="Alta",AA14="Catastrófico"),AND(Y14="Muy Alta",AA14="Catastrófico")),"Extremo","")))),"") -> Moderado | AD14: Reducir (mitigar) | AE14: Solo se publica previo visto bueno o ok del presidente de la corporación. | AF14: Jefe Asesora de Prensa | AG14: 45662 | AH14: 45775 | AI14: Todas las publicaciones realizadas a la fecha tienen el visto bueno del presidente | AJ14: Abierta | AK14: 45894 | AL14: Todas las publicaciones realizadas a la fecha tienen el visto bueno del Presidente
K15: =IF(NOT(ISERROR(MATCH(J15,_xlfn.ANCHORARRAY(#REF!),0))),#REF!&"Por favor no seleccionar los criterios de impacto",J15) -> 0 | O15: 3 | P15: El jefe de prensa prepara al vocero antes de salir a medios de comunicación. | Q15: Impacto | R15: Preventivo | S15: Manual | T15: =IF(AND(R15="Preventivo",S15="Automático"),"50%",IF(AND(R15="Preventivo",S15="Manual"),"40%",IF(AND(R15="Detectivo",S15="Automático"),"40%",IF(AND(R15="Detectivo",S15="Manual"),"30%",IF(AND(R15="Correctivo",S15="Automático"),"35%",IF(AND(R15="Correctivo",S15="Manual"),"25%","")))))) -> 40% | U15: Documentado | V15: Continua | W15: Sin Registro | X15: =IFERROR(IF(AND(Q14="Probabilidad",Q15="Probabilidad"),(Z14-(+Z14*T15)),IF(Q15="Probabilidad",(I14-(+I14*T15)),IF(Q15="Impacto",Z14,""))),"") -> 0.6 | Y15: =IFERROR(IF(X15="","",IF(X15<=0.2,"Muy Baja",IF(X15<=0.4,"Baja",IF(X15<=0.6,"Media",IF(X15<=0.8,"Alta","Muy Alta"))))),"") -> Media | Z15: =+X15 -> 0.6 | AA15: =IFERROR(IF(AB15="","",IF(AB15<=0.2,"Leve",IF(AB15<=0.4,"Menor",IF(AB15<=0.6,"Moderado",IF(AB15<=0.8,"Mayor","Catastrófico"))))),"") -> Leve | AB15: =IFERROR(IF(AND(Q14="Impacto",Q15="Impacto"),(AB14-(+AB14*T15)),IF(Q15="Impacto",($M$13-(+$M$13*T15)),IF(Q15="Probabilidad",AB14,""))),"") -> 0.1296 | AC15: =IFERROR(IF(OR(AND(Y15="Muy Baja",AA15="Leve"),AND(Y15="Muy Baja",AA15="Menor"),AND(Y15="Baja",AA15="Leve")),"Bajo",IF(OR(AND(Y15="Muy baja",AA15="Moderado"),AND(Y15="Baja",AA15="Menor"),AND(Y15="Baja",AA15="Moderado"),AND(Y15="Media",AA15="Leve"),AND(Y15="Media",AA15="Menor"),AND(Y15="Media",AA15="Moderado"),AND(Y15="Alta",AA15="Leve"),AND(Y15="Alta",AA15="Menor")),"Moderado",IF(OR(AND(Y15="Muy Baja",AA15="Mayor"),AND(Y15="Baja",AA15="Mayor"),AND(Y15="Media",AA15="Mayor"),AND(Y15="Alta",AA15="Moderado"),AND(Y15="Alta",AA15="Mayor"),AND(Y15="Muy Alta",AA15="Leve"),AND(Y15="Muy Alta",AA15="Menor"),AND(Y15="Muy Alta",AA15="Moderado"),AND(Y15="Muy Alta",AA15="Mayor")),"Alto",IF(OR(AND(Y15="Muy Baja",AA15="Catastrófico"),AND(Y15="Baja",AA15="Catastrófico"),AND(Y15="Media",AA15="Catastrófico"),AND(Y15="Alta",AA15="Catastrófico"),AND(Y15="Muy Alta",AA15="Catastrófico")),"Extremo","")))),"") -> Moderado | AD15: Reducir (mitigar) | AE15: Solo se sale a medios con las líneas de mensajes, declaración y cuestionarios estructurados. | AF15: Jefe Asesora de Prensa | AG15: 45658 | AH15: 45775 | AI15: En el momento de dar alguna entrevista o declaración se prepara y se pone en contexto de los temas a tratar | AJ15: Abierta | AK15: 45894 | AL15: En el momento de dar alguna entrevista o declaración se prepara y se pone en contexto de los temas a tratar
A16: 2 | B16: Reputacional | C16: Percepción de imagen institucional negativa ante la comunidad. | D16: Por no articular las actividades de comunicación del PEC con las necesidades o temas de interés de la comunidad | E16: Posibilidad de afectación de la credibilidad institucional por negativa percepción de la imagen institucional debido a no articular las actividades de comunicacion del PECO con la realidad de los grupos de valor | F16: Usuarios, productos y practicas , organizacionales | G16: 365 | H16: =IF(G16<=0,"",IF(G16<=2,"Muy Baja",IF(G16<=24,"Baja",IF(G16<=500,"Media",IF(G16<=5000,"Alta","Muy Alta"))))) -> Media | I16: =IF(H16="","",IF(H16="Muy Baja",0.2,IF(H16="Baja",0.4,IF(H16="Media",0.6,IF(H16="Alta",0.8,IF(H16="Muy Alta",1,)))))) -> 0.6 | J16: El riesgo afecta la imagen de la entidad con efecto publicitario sostenido a nivel de sector administrativo, nivel departamental o municipal | K16: =IF(NOT(ISERROR(MATCH(J16,#REF!,0))),#REF!&"Por favor no seleccionar los criterios de impacto(Afectación Económica o presupuestal y Pérdida Reputacional)",J16) -> El riesgo afecta la imagen de la entidad con efecto publicitario sostenido a nivel de sector administrativo, nivel departamental o municipal | L16: Media | M16: 0.6 | N16: Media | O16: 1 | P16: El jefe asesor de la oficina de prensa, revisa que las acciones de comunicaciòn determinadas en el PECO sean de interes y utilidad para los grupos de valor a través de las métricas y estadísticas del sitio web y las redes sociales. | Q16: Impacto | R16: Preventivo | S16: Manual | T16: =IF(AND(R16="Preventivo",S16="Automático"),"50%",IF(AND(R16="Preventivo",S16="Manual"),"40%",IF(AND(R16="Detectivo",S16="Automático"),"40%",IF(AND(R16="Detectivo",S16="Manual"),"30%",IF(AND(R16="Correctivo",S16="Automático"),"35%",IF(AND(R16="Correctivo",S16="Manual"),"25%","")))))) -> 40% | U16: Documentado | V16: Aleatoria | W16: Con Registro | X16: =IFERROR(IF(Q16="Probabilidad",(I16-(+I16*T16)),IF(Q16="Impacto",I16,"")),"") -> 0.6 | Y16: =IFERROR(IF(X16="","",IF(X16<=0.2,"Muy Baja",IF(X16<=0.4,"Baja",IF(X16<=0.6,"Media",IF(X16<=0.8,"Alta","Muy Alta"))))),"") -> Media | Z16: =+X16 -> 0.6 | AA16: =IFERROR(IF(AB16="","",IF(AB16<=0.2,"Leve",IF(AB16<=0.4,"Menor",IF(AB16<=0.6,"Moderado",IF(AB16<=0.8,"Mayor","Catastrófico"))))),"") -> Menor | AB16: =IFERROR(IF(Q16="Impacto",(M16-(+M16*T16)),IF(Q16="Probabilidad",M16,"")),"") -> 0.36 | AC16: =IFERROR(IF(OR(AND(Y16="Muy Baja",AA16="Leve"),AND(Y16="Muy Baja",AA16="Menor"),AND(Y16="Baja",AA16="Leve")),"Bajo",IF(OR(AND(Y16="Muy baja",AA16="Moderado"),AND(Y16="Baja",AA16="Menor"),AND(Y16="Baja",AA16="Moderado"),AND(Y16="Media",AA16="Leve"),AND(Y16="Media",AA16="Menor"),AND(Y16="Media",AA16="Moderado"),AND(Y16="Alta",AA16="Leve"),AND(Y16="Alta",AA16="Menor")),"Moderado",IF(OR(AND(Y16="Muy Baja",AA16="Mayor"),AND(Y16="Baja",AA16="Mayor"),AND(Y16="Media",AA16="Mayor"),AND(Y16="Alta",AA16="Moderado"),AND(Y16="Alta",AA16="Mayor"),AND(Y16="Muy Alta",AA16="Leve"),AND(Y16="Muy Alta",AA16="Menor"),AND(Y16="Muy Alta",AA16="Moderado"),AND(Y16="Muy Alta",AA16="Mayor")),"Alto",IF(OR(AND(Y16="Muy Baja",AA16="Catastrófico"),AND(Y16="Baja",AA16="Catastrófico"),AND(Y16="Media",AA16="Catastrófico"),AND(Y16="Alta",AA16="Catastrófico"),AND(Y16="Muy Alta",AA16="Catastrófico")),"Extremo","")))),"") -> Moderado | AD16: Reducir (mitigar) | AE16: Analizar las métricas de Facebook, Instagram, Twitter y Youtube para conocer los datos de audiencias y consumo | AF16: Jefe Asesora de Prensa | AG16: 45807 | AH16: 45775 | AI16: Se analizaron las metricas de las Redes Sociales. El informe se presentó en la Audiencia Pública de Rendición de Cuentas | AJ16: Abierta | AK16: 45894 | AL16: Se analizaron las metricas de las Redes. Con corte agosto
K17: =IF(NOT(ISERROR(MATCH(J17,_xlfn.ANCHORARRAY(E18),0))),I20&"Por favor no seleccionar los criterios de impacto",J17) -> 0 | O17: 2 | P17: El presidente verifica la viabilidad de las estrategìas de comunicaciòn a ejecutar con base en los resultados de la aplicaciòn de encuestas de satisfacción aplicadas a los usuarios de algun servicio que preste el Concejo. | Q17: Impacto | R17: Preventivo | S17: Manual | T17: =IF(AND(R17="Preventivo",S17="Automático"),"50%",IF(AND(R17="Preventivo",S17="Manual"),"40%",IF(AND(R17="Detectivo",S17="Automático"),"40%",IF(AND(R17="Detectivo",S17="Manual"),"30%",IF(AND(R17="Correctivo",S17="Automático"),"35%",IF(AND(R17="Correctivo",S17="Manual"),"25%","")))))) -> 40% | U17: Documentado | V17: Aleatoria | W17: Con Registro | X17: =IFERROR(IF(AND(Q16="Probabilidad",Q17="Probabilidad"),(Z16-(+Z16*T17)),IF(Q17="Probabilidad",(I16-(+I16*T17)),IF(Q17="Impacto",Z16,""))),"") -> 0.6 | Y17: =IFERROR(IF(X17="","",IF(X17<=0.2,"Muy Baja",IF(X17<=0.4,"Baja",IF(X17<=0.6,"Media",IF(X17<=0.8,"Alta","Muy Alta"))))),"") -> Media | Z17: =+X17 -> 0.6 | AA17: =IFERROR(IF(AB17="","",IF(AB17<=0.2,"Leve",IF(AB17<=0.4,"Menor",IF(AB17<=0.6,"Moderado",IF(AB17<=0.8,"Mayor","Catastrófico"))))),"") -> Menor | AB17: =IFERROR(IF(AND(Q16="Impacto",Q17="Impacto"),(AB13-(+AB13*T17)),IF(Q17="Impacto",($M$16-(+$M$16*T17)),IF(Q17="Probabilidad",AB13,""))),"") -> 0.216 | AC17: =IFERROR(IF(OR(AND(Y17="Muy Baja",AA17="Leve"),AND(Y17="Muy Baja",AA17="Menor"),AND(Y17="Baja",AA17="Leve")),"Bajo",IF(OR(AND(Y17="Muy baja",AA17="Moderado"),AND(Y17="Baja",AA17="Menor"),AND(Y17="Baja",AA17="Moderado"),AND(Y17="Media",AA17="Leve"),AND(Y17="Media",AA17="Menor"),AND(Y17="Media",AA17="Moderado"),AND(Y17="Alta",AA17="Leve"),AND(Y17="Alta",AA17="Menor")),"Moderado",IF(OR(AND(Y17="Muy Baja",AA17="Mayor"),AND(Y17="Baja",AA17="Mayor"),AND(Y17="Media",AA17="Mayor"),AND(Y17="Alta",AA17="Moderado"),AND(Y17="Alta",AA17="Mayor"),AND(Y17="Muy Alta",AA17="Leve"),AND(Y17="Muy Alta",AA17="Menor"),AND(Y17="Muy Alta",AA17="Moderado"),AND(Y17="Muy Alta",AA17="Mayor")),"Alto",IF(OR(AND(Y17="Muy Baja",AA17="Catastrófico"),AND(Y17="Baja",AA17="Catastrófico"),AND(Y17="Media",AA17="Catastrófico"),AND(Y17="Alta",AA17="Catastrófico"),AND(Y17="Muy Alta",AA17="Catastrófico")),"Extremo","")))),"") -> Moderado | AD17: Reducir (mitigar) | AE17: Analizar las encuestas de satisfacción de la información para evaluar el impacto de las estrategias de comunicación interna y externa | AF17: Jefe Asesora de Prensa | AG17: 45930 | AH17: 45775 | AI17: Se han realizado las encuestas de satisfacción. | AJ17: Abierta | AK17: 45894 | AL17: Se realizaron las encuestas de satisfacción clientes internos.
B18: *Nota: La columna referencia se sugiere para mantener el consecutivo de riesgos, así el riesgo salga del mapa no existirá otro riesgo con el mismo número. Una entidad puede ir en el riesgo 150 pero tener 70 riesgos, lo que permite llevar una traza de los riesgos. Esta información la debe administrar la Oficina Asesora de Planeación o Gerencia de Riesgos.
B20: Fuente: Adaptado de Curso Riesgo Operativo Universidad del Rosario por Dirección de Gestión y Desempeño Institucional de Función Pública, 2020.

Sheet Matriz Calor Inherente
B2: Matriz de Calor Inherente | J2: Impacto
B6: Probabilidad | E6: Muy Alta 100% | J6: =IF(AND('Mapa final'!$H$13="Muy Alta",'Mapa final'!$L$13="Leve"),CONCATENATE("R",'Mapa final'!$A$13),"") | L6: =IF(AND('Mapa final'!$H$16="Muy Alta",'Mapa final'!$L$16="Leve"),CONCATENATE("R",'Mapa final'!$A$16),"") | N6: =IF(AND('Mapa final'!#REF!="Muy Alta",'Mapa final'!#REF!="Leve"),CONCATENATE("R",'Mapa final'!#REF!),"") -> #REF! | P6: =IF(AND('Mapa final'!$H$13="Muy Alta",'Mapa final'!$L$13="Menor"),CONCATENATE("R",'Mapa final'!$A$13),"") | R6: =IF(AND('Mapa final'!$H$16="Muy Alta",'Mapa final'!$L$16="Menor"),CONCATENATE("R",'Mapa final'!$A$16),"") | T6: =IF(AND('Mapa final'!#REF!="Muy Alta",'Mapa final'!#REF!="Menor"),CONCATENATE("R",'Mapa final'!#REF!),"") -> #REF! | V6: =IF(AND('Mapa final'!$H$13="Muy Alta",'Mapa final'!$L$13="Moderado"),CONCATENATE("R",'Mapa final'!$A$13),"") | X6: =IF(AND('Mapa final'!$H$16="Muy Alta",'Mapa final'!$L$16="Moderado"),CONCATENATE("R",'Mapa final'!$A$16),"") | Z6: =IF(AND('Mapa final'!#REF!="Muy Alta",'Mapa final'!#REF!="Moderado"),CONCATENATE("R",'Mapa final'!#REF!),"") -> #REF! | AB6: =IF(AND('Mapa final'!$H$13="Muy Alta",'Mapa final'!$L$13="Mayor"),CONCATENATE("R",'Mapa final'!$A$13),"") | AD6: =IF(AND('Mapa final'!$H$16="Muy Alta",'Mapa final'!$L$16="Mayor"),CONCATENATE("R",'Mapa final'!$A$16),"") | AF6: =IF(AND('Mapa final'!#REF!="Muy Alta",'Mapa final'!#REF!="Mayor"),CONCATENATE("R",'Mapa final'!#REF!),"") -> #REF! | AH6: =IF(AND('Mapa final'!$H$13="Muy Alta",'Mapa final'!$L$13="Catastrófico"),CONCATENATE("R",'Mapa final'!$A$13),"") | AJ6: =IF(AND('Mapa final'!$H$16="Muy Alta",'Mapa final'!$L$16="Catastrófico"),CONCATENATE("R",'Mapa final'!$A$16),"") | AL6: =IF(AND('Mapa final'!#REF!="Muy Alta",'Mapa final'!#REF!="Catastrófico"),CONCATENATE("R",'Mapa final'!#REF!),"") -> #REF! | AO6: Extremo
J8: =IF(AND('Mapa final'!#REF!="Muy Alta",'Mapa final'!#REF!="Leve"),CONCATENATE("R",'Mapa final'!#REF!),"") -> #REF! | L8: =IF(AND('Mapa final'!#REF!="Muy Alta",'Mapa final'!#REF!="Leve"),CONCATENATE("R",'Mapa final'!#REF!),"") -> #REF! | N8: =IF(AND('Mapa final'!#REF!="Muy Alta",'Mapa final'!#REF!="Leve"),CONCATENATE("R",'Mapa final'!#REF!),"") -> #REF! | P8: =IF(AND('Mapa final'!#REF!="Muy Alta",'Mapa final'!#REF!="Menor"),CONCATENATE("R",'Mapa final'!#REF!),"") -> #REF! | R8: =IF(AND('Mapa final'!#REF!="Muy Alta",'Mapa final'!#REF!="Menor"),CONCATENATE("R",'Mapa final'!#REF!),"") -> #REF! | T8: =IF(AND('Mapa final'!#REF!="Muy Alta",'Mapa final'!#REF!="Menor"),CONCATENATE("R",'Mapa final'!#REF!),"") -> #REF! | V8: =IF(AND('Mapa final'!#REF!="Muy Alta",'Mapa final'!#REF!="Moderado"),CONCATENATE("R",'Mapa final'!#REF!),"") -> #REF! | X8: =IF(AND('Mapa final'!#REF!="Muy Alta",'Mapa final'!#REF!="Moderado"),CONCATENATE("R",'Mapa final'!#REF!),"") -> #REF! | Z8: =IF(AND('Mapa final'!#REF!="Muy Alta",'Mapa final'!#REF!="Moderado"),CONCATENATE("R",'Mapa final'!#REF!),"") -> #REF! | AB8: =IF(AND('Mapa final'!#REF!="Muy Alta",'Mapa final'!#REF!="Mayor"),CONCATENATE("R",'Mapa final'!#REF!),"") -> #REF! | AD8: =IF(AND('Mapa final'!#REF!="Muy Alta",'Mapa final'!#REF!="Mayor"),CONCATENATE("R",'Mapa final'!#REF!),"") -> #REF! | AF8: =IF(AND('Mapa final'!#REF!="Muy Alta",'Mapa final'!#REF!="Mayor"),CONCATENATE("R",'Mapa final'!#REF!),"") -> #REF! | AH8: =IF(AND('Mapa final'!#REF!="Muy Alta",'Mapa final'!#REF!="Catastrófico"),CONCATENATE("R",'Mapa final'!#REF!),"") -> #REF! | AJ8: =IF(AND('Mapa final'!#REF!="Muy Alta",'Mapa final'!#REF!="Catastrófico"),CONCATENATE("R",'Mapa final'!#REF!),"") -> #REF! | AL8: =IF(AND('Mapa final'!#REF!="Muy Alta",'Mapa final'!#REF!="Catastrófico"),CONCATENATE("R",'Mapa final'!#REF!),"") -> #REF!
J10: =IF(AND('Mapa final'!#REF!="Muy Alta",'Mapa final'!#REF!="Leve"),CONCATENATE("R",'Mapa final'!#REF!),"") -> #REF! | L10: =IF(AND('Mapa final'!#REF!="Muy Alta",'Mapa final'!#REF!="Leve"),CONCATENATE("R",'Mapa final'!#REF!),"") -> #REF! | N10: =IF(AND('Mapa final'!#REF!="Muy Alta",'Mapa final'!#REF!="Leve"),CONCATENATE("R",'Mapa final'!#REF!),"") -> #REF! | P10: =IF(AND('Mapa final'!#REF!="Muy Alta",'Mapa final'!#REF!="Menor"),CONCATENATE("R",'Mapa final'!#REF!),"") -> #REF! | R10: =IF(AND('Mapa final'!#REF!="Muy Alta",'Mapa final'!#REF!="Menor"),CONCATENATE("R",'Mapa final'!#REF!),"") -> #REF! | T10: =IF(AND('Mapa final'!#REF!="Muy Alta",'Mapa final'!#REF!="Menor"),CONCATENATE("R",'Mapa final'!#REF!),"") -> #REF! | V10: =IF(AND('Mapa final'!#REF!="Muy Alta",'Mapa final'!#REF!="Moderado"),CONCATENATE("R",'Mapa final'!#REF!),"") -> #REF! | X10: =IF(AND('Mapa final'!#REF!="Muy Alta",'Mapa final'!#REF!="Moderado"),CONCATENATE("R",'Mapa final'!#REF!),"") -> #REF! | Z10: =IF(AND('Mapa final'!#REF!="Muy Alta",'Mapa final'!#REF!="Moderado"),CONCATENATE("R",'Mapa final'!#REF!),"") -> #REF! | AB10: =IF(AND('Mapa final'!#REF!="Muy Alta",'Mapa final'!#REF!="Mayor"),CONCATENATE("R",'Mapa final'!#REF!),"") -> #REF! | AD10: =IF(AND('Mapa final'!#REF!="Muy Alta",'Mapa final'!#REF!="Mayor"),CONCATENATE("R",'Mapa final'!#REF!),"") -> #REF! | AF10: =IF(AND('Mapa final'!#REF!="Muy Alta",'Mapa final'!#REF!="Mayor"),CONCATENATE("R",'Mapa final'!#REF!),"") -> #REF! | AH10: =IF(AND('Mapa final'!#REF!="Muy Alta",'Mapa final'!#REF!="Catastrófico"),CONCATENATE("R",'Mapa final'!#REF!),"") -> #REF! | AJ10: =IF(AND('Mapa final'!#REF!="Muy Alta",'Mapa final'!#REF!="Catastrófico"),CONCATENATE("R",'Mapa final'!#REF!),"") -> #REF! | AL10: =IF(AND('Mapa final'!#REF!="Muy Alta",'Mapa final'!#REF!="Catastrófico"),CONCATENATE("R",'Mapa final'!#REF!),"") -> #REF!
J12: =IF(AND('Mapa final'!#REF!="Muy Alta",'Mapa final'!#REF!="Leve"),CONCATENATE("R",'Mapa final'!#REF!),"") -> #REF! | L12: =IF(AND('Mapa final'!$H$18="Muy Alta",'Mapa final'!$L$18="Leve"),CONCATENATE("R",'Mapa final'!$A$18),"") | N12: =IF(AND('Mapa final'!$H$24="Muy Alta",'Mapa final'!$L$24="Leve"),CONCATENATE("R",'Mapa final'!$A$24),"") | P12: =IF(AND('Mapa final'!#REF!="Muy Alta",'Mapa final'!#REF!="Menor"),CONCATENATE("R",'Mapa final'!#REF!),"") -> #REF! | R12: =IF(AND('Mapa final'!$H$18="Muy Alta",'Mapa final'!$L$18="Menor"),CONCATENATE("R",'Mapa final'!$A$18),"") | T12: =IF(AND('Mapa final'!$H$24="Muy Alta",'Mapa final'!$L$24="Menor"),CONCATENATE("R",'Mapa final'!$A$24),"") | V12: =IF(AND('Mapa final'!#REF!="Muy Alta",'Mapa final'!#REF!="Moderado"),CONCATENATE("R",'Mapa final'!#REF!),"") -> #REF! | X12: =IF(AND('Mapa final'!$H$18="Muy Alta",'Mapa final'!$L$18="Moderado"),CONCATENATE("R",'Mapa final'!$A$18),"") | Z12: =IF(AND('Mapa final'!$H$24="Muy Alta",'Mapa final'!$L$24="Moderado"),CONCATENATE("R",'Mapa final'!$A$24),"") | AB12: =IF(AND('Mapa final'!#REF!="Muy Alta",'Mapa final'!#REF!="Mayor"),CONCATENATE("R",'Mapa final'!#REF!),"") -> #REF! | AD12: =IF(AND('Mapa final'!$H$18="Muy Alta",'Mapa final'!$L$18="Mayor"),CONCATENATE("R",'Mapa final'!$A$18),"") | AF12: =IF(AND('Mapa final'!$H$24="Muy Alta",'Mapa final'!$L$24="Mayor"),CONCATENATE("R",'Mapa final'!$A$24),"") | AH12: =IF(AND('Mapa final'!#REF!="Muy Alta",'Mapa final'!#REF!="Catastrófico"),CONCATENATE("R",'Mapa final'!#REF!),"") -> #REF! | AJ12: =IF(AND('Mapa final'!$H$18="Muy Alta",'Mapa final'!$L$18="Catastrófico"),CONCATENATE("R",'Mapa final'!$A$18),"") | AL12: =IF(AND('Mapa final'!$H$24="Muy Alta",'Mapa final'!$L$24="Catastrófico"),CONCATENATE("R",'Mapa final'!$A$24),"")
E14: Alta 80% | J14: =IF(AND('Mapa final'!$H$13="Alta",'Mapa final'!$L$13="Leve"),CONCATENATE("R",'Mapa final'!$A$13),"") | L14: =IF(AND('Mapa final'!$H$16="Alta",'Mapa final'!$L$16="Leve"),CONCATENATE("R",'Mapa final'!$A$16),"") | N14: =IF(AND('Mapa final'!#REF!="Alta",'Mapa final'!#REF!="Leve"),CONCATENATE("R",'Mapa final'!#REF!),"") -> #REF! | P14: =IF(AND('Mapa final'!$H$13="Alta",'Mapa final'!$L$13="Menor"),CONCATENATE("R",'Mapa final'!$A$13),"") | R14: =IF(AND('Mapa final'!$H$16="Alta",'Mapa final'!$L$16="Menor"),CONCATENATE("R",'Mapa final'!$A$16),"") | T14: =IF(AND('Mapa final'!#REF!="Alta",'Mapa final'!#REF!="Menor"),CONCATENATE("R",'Mapa final'!#REF!),"") -> #REF! | V14: =IF(AND('Mapa final'!$H$13="Alta",'Mapa final'!$L$13="Moderado"),CONCATENATE("R",'Mapa final'!$A$13),"") | X14: =IF(AND('Mapa final'!$H$16="Alta",'Mapa final'!$L$16="Moderado"),CONCATENATE("R",'Mapa final'!$A$16),"") | Z14: =IF(AND('Mapa final'!#REF!="Alta",'Mapa final'!#REF!="Moderado"),CONCATENATE("R",'Mapa final'!#REF!),"") -> #REF! | AB14: =IF(AND('Mapa final'!$H$13="Alta",'Mapa final'!$L$13="Mayor"),CONCATENATE("R",'Mapa final'!$A$13),"") | AD14: =IF(AND('Mapa final'!$H$16="Alta",'Mapa final'!$L$16="Mayor"),CONCATENATE("R",'Mapa final'!$A$16),"") | AF14: =IF(AND('Mapa final'!#REF!="Alta",'Mapa final'!#REF!="Mayor"),CONCATENATE("R",'Mapa final'!#REF!),"") -> #REF! | AH14: =IF(AND('Mapa final'!$H$13="Alta",'Mapa final'!$L$13="Catastrófico"),CONCATENATE("R",'Mapa final'!$A$13),"") | AJ14: =IF(AND('Mapa final'!$H$16="Alta",'Mapa final'!$L$16="Catastrófico"),CONCATENATE("R",'Mapa final'!$A$16),"") | AL14: =IF(AND('Mapa final'!#REF!="Alta",'Mapa final'!#REF!="Catastrófico"),CONCATENATE("R",'Mapa final'!#REF!),"") -> #REF! | AO14: Alto
J16: =IF(AND('Mapa final'!#REF!="Alta",'Mapa final'!#REF!="Leve"),CONCATENATE("R",'Mapa final'!#REF!),"") -> #REF! | L16: =IF(AND('Mapa final'!#REF!="Alta",'Mapa final'!#REF!="Leve"),CONCATENATE("R",'Mapa final'!#REF!),"") -> #REF! | N16: =IF(AND('Mapa final'!#REF!="Alta",'Mapa final'!#REF!="Leve"),CONCATENATE("R",'Mapa final'!#REF!),"") -> #REF! | P16: =IF(AND('Mapa final'!#REF!="Alta",'Mapa final'!#REF!="Menor"),CONCATENATE("R",'Mapa final'!#REF!),"") -> #REF! | R16: =IF(AND('Mapa final'!#REF!="Alta",'Mapa final'!#REF!="Menor"),CONCATENATE("R",'Mapa final'!#REF!),"") -> #REF! | T16: =IF(AND('Mapa final'!#REF!="Alta",'Mapa final'!#REF!="Menor"),CONCATENATE("R",'Mapa final'!#REF!),"") -> #REF! | V16: =IF(AND('Mapa final'!#REF!="Alta",'Mapa final'!#REF!="Moderado"),CONCATENATE("R",'Mapa final'!#REF!),"") -> #REF! | X16: =IF(AND('Mapa final'!#REF!="Alta",'Mapa final'!#REF!="Moderado"),CONCATENATE("R",'Mapa final'!#REF!),"") -> #REF! | Z16: =IF(AND('Mapa final'!#REF!="Alta",'Mapa final'!#REF!="Moderado"),CONCATENATE("R",'Mapa final'!#REF!),"") -> #REF! | AB16: =IF(AND('Mapa final'!#REF!="Alta",'Mapa final'!#REF!="Mayor"),CONCATENATE("R",'Mapa final'!#REF!),"") -> #REF! | AD16: =IF(AND('Mapa final'!#REF!="Alta",'Mapa final'!#REF!="Mayor"),CONCATENATE("R",'Mapa final'!#REF!),"") -> #REF! | AF16: =IF(AND('Mapa final'!#REF!="Alta",'Mapa final'!#REF!="Mayor"),CONCATENATE("R",'Mapa final'!#REF!),"") -> #REF! | AH16: =IF(AND('Mapa final'!#REF!="Alta",'Mapa final'!#REF!="Catastrófico"),CONCATENATE("R",'Mapa final'!#REF!),"") -> #REF! | AJ16: =IF(AND('Mapa final'!#REF!="Alta",'Mapa final'!#REF!="Catastrófico"),CONCATENATE("R",'Mapa final'!#REF!),"") -> #REF! | AL16: =IF(AND('Mapa final'!#REF!="Alta",'Mapa final'!#REF!="Catastrófico"),CONCATENATE("R",'Mapa final'!#REF!),"") -> #REF!
J18: =IF(AND('Mapa final'!#REF!="Alta",'Mapa final'!#REF!="Leve"),CONCATENATE("R",'Mapa final'!#REF!),"") -> #REF! | L18: =IF(AND('Mapa final'!#REF!="Alta",'Mapa final'!#REF!="Leve"),CONCATENATE("R",'Mapa final'!#REF!),"") -> #REF! | N18: =IF(AND('Mapa final'!#REF!="Alta",'Mapa final'!#REF!="Leve"),CONCATENATE("R",'Mapa final'!#REF!),"") -> #REF! | P18: =IF(AND('Mapa final'!#REF!="Alta",'Mapa final'!#REF!="Menor"),CONCATENATE("R",'Mapa final'!#REF!),"") -> #REF! | R18: =IF(AND('Mapa final'!#REF!="Alta",'Mapa final'!#REF!="Menor"),CONCATENATE("R",'Mapa final'!#REF!),"") -> #REF! | T18: =IF(AND('Mapa final'!#REF!="Alta",'Mapa final'!#REF!="Menor"),CONCATENATE("R",'Mapa final'!#REF!),"") -> #REF! | V18: =IF(AND('Mapa final'!#REF!="Alta",'Mapa final'!#REF!="Moderado"),CONCATENATE("R",'Mapa final'!#REF!),"") -> #REF! | X18: =IF(AND('Mapa final'!#REF!="Alta",'Mapa final'!#REF!="Moderado"),CONCATENATE("R",'Mapa final'!#REF!),"") -> #REF! | Z18: =IF(AND('Mapa final'!#REF!="Alta",'Mapa final'!#REF!="Moderado"),CONCATENATE("R",'Mapa final'!#REF!),"") -> #REF! | AB18: =IF(AND('Mapa final'!#REF!="Alta",'Mapa final'!#REF!="Mayor"),CONCATENATE("R",'Mapa final'!#REF!),"") -> #REF! | AD18: =IF(AND('Mapa final'!#REF!="Alta",'Mapa final'!#REF!="Mayor"),CONCATENATE("R",'Mapa final'!#REF!),"") -> #REF! | AF18: =IF(AND('Mapa final'!#REF!="Alta",'Mapa final'!#REF!="Mayor"),CONCATENATE("R",'Mapa final'!#REF!),"") -> #REF! | AH18: =IF(AND('Mapa final'!#REF!="Alta",'Mapa final'!#REF!="Catastrófico"),CONCATENATE("R",'Mapa final'!#REF!),"") -> #REF! | AJ18: =IF(AND('Mapa final'!#REF!="Alta",'Mapa final'!#REF!="Catastrófico"),CONCATENATE("R",'Mapa final'!#REF!),"") -> #REF! | AL18: =IF(AND('Mapa final'!#REF!="Alta",'Mapa final'!#REF!="Catastrófico"),CONCATENATE("R",'Mapa final'!#REF!),"") -> #REF!
J20: =IF(AND('Mapa final'!#REF!="Alta",'Mapa final'!#REF!="Leve"),CONCATENATE("R",'Mapa final'!#REF!),"") -> #REF! | L20: =IF(AND('Mapa final'!$H$18="Alta",'Mapa final'!$L$18="Leve"),CONCATENATE("R",'Mapa final'!$A$18),"") | N20: =IF(AND('Mapa final'!$H$24="Alta",'Mapa final'!$L$24="Leve"),CONCATENATE("R",'Mapa final'!$A$24),"") | P20: =IF(AND('Mapa final'!#REF!="Alta",'Mapa final'!#REF!="Menor"),CONCATENATE("R",'Mapa final'!#REF!),"") -> #REF! | R20: =IF(AND('Mapa final'!$H$18="Alta",'Mapa final'!$L$18="Menor"),CONCATENATE("R",'Mapa final'!$A$18),"") | T20: =IF(AND('Mapa final'!$H$24="Alta",'Mapa final'!$L$24="Menor"),CONCATENATE("R",'Mapa final'!$A$24),"") | V20: =IF(AND('Mapa final'!#REF!="Alta",'Mapa final'!#REF!="Moderado"),CONCATENATE("R",'Mapa final'!#REF!),"") -> #REF! | X20: =IF(AND('Mapa final'!$H$18="Alta",'Mapa final'!$L$18="Moderado"),CONCATENATE("R",'Mapa final'!$A$18),"") | Z20: =IF(AND('Mapa final'!$H$24="Alta",'Mapa final'!$L$24="Moderado"),CONCATENATE("R",'Mapa final'!$A$24),"") | AB20: =IF(AND('Mapa final'!#REF!="Alta",'Mapa final'!#REF!="Mayor"),CONCATENATE("R",'Mapa final'!#REF!),"") -> #REF! | AD20: =IF(AND('Mapa final'!$H$18="Alta",'Mapa final'!$L$18="Mayor"),CONCATENATE("R",'Mapa final'!$A$18),"") | AF20: =IF(AND('Mapa final'!$H$24="Alta",'Mapa final'!$L$24="Mayor"),CONCATENATE("R",'Mapa final'!$A$24),"") | AH20: =IF(AND('Mapa final'!#REF!="Alta",'Mapa final'!#REF!="Catastrófico"),CONCATENATE("R",'Mapa final'!#REF!),"") -> #REF! | AJ20: =IF(AND('Mapa final'!$H$18="Alta",'Mapa final'!$L$18="Catastrófico"),CONCATENATE("R",'Mapa final'!$A$18),"") | AL20: =IF(AND('Mapa final'!$H$24="Alta",'Mapa final'!$L$24="Catastrófico"),CONCATENATE("R",'Mapa final'!$A$24),"")
E22: Media 60% | J22: =IF(AND('Mapa final'!$H$13="Media",'Mapa final'!$L$13="Leve"),CONCATENATE("R",'Mapa final'!$A$13),"") | L22: =IF(AND('Mapa final'!$H$16="Media",'Mapa final'!$L$16="Leve"),CONCATENATE("R",'Mapa final'!$A$16),"") | N22: =IF(AND('Mapa final'!#REF!="Media",'Mapa final'!#REF!="Leve"),CONCATENATE("R",'Mapa final'!#REF!),"") -> #REF! | P22: =IF(AND('Mapa final'!$H$13="Media",'Mapa final'!$L$13="Menor"),CONCATENATE("R",'Mapa final'!$A$13),"") | R22: =IF(AND('Mapa final'!$H$16="Media",'Mapa final'!$L$16="Menor"),CONCATENATE("R",'Mapa final'!$A$16),"") | T22: =IF(AND('Mapa final'!#REF!="Media",'Mapa final'!#REF!="Menor"),CONCATENATE("R",'Mapa final'!#REF!),"") -> #REF! | V22: =IF(AND('Mapa final'!$H$13="Media",'Mapa final'!$L$13="Moderado"),CONCATENATE("R",'Mapa final'!$A$13),"") | X22: =IF(AND('Mapa final'!$H$16="Media",'Mapa final'!$L$16="Moderado"),CONCATENATE("R",'Mapa final'!$A$16),"") | Z22: =IF(AND('Mapa final'!#REF!="Media",'Mapa final'!#REF!="Moderado"),CONCATENATE("R",'Mapa final'!#REF!),"") -> #REF! | AB22: =IF(AND('Mapa final'!$H$13="Media",'Mapa final'!$L$13="Mayor"),CONCATENATE("R",'Mapa final'!$A$13),"") | AD22: =IF(AND('Mapa final'!$H$16="Media",'Mapa final'!$L$16="Mayor"),CONCATENATE("R",'Mapa final'!$A$16),"") | AF22: =IF(AND('Mapa final'!#REF!="Media",'Mapa final'!#REF!="Mayor"),CONCATENATE("R",'Mapa final'!#REF!),"") -> #REF! | AH22: =IF(AND('Mapa final'!$H$13="Media",'Mapa final'!$L$13="Catastrófico"),CONCATENATE("R",'Mapa final'!$A$13),"") | AJ22: =IF(AND('Mapa final'!$H$16="Media",'Mapa final'!$L$16="Catastrófico"),CONCATENATE("R",'Mapa final'!$A$16),"") | AL22: =IF(AND('Mapa final'!#REF!="Media",'Mapa final'!#REF!="Catastrófico"),CONCATENATE("R",'Mapa final'!#REF!),"") -> #REF! | AO22: Moderado
J24: =IF(AND('Mapa final'!#REF!="Media",'Mapa final'!#REF!="Leve"),CONCATENATE("R",'Mapa final'!#REF!),"") -> #REF! | L24: =IF(AND('Mapa final'!#REF!="Media",'Mapa final'!#REF!="Leve"),CONCATENATE("R",'Mapa final'!#REF!),"") -> #REF! | N24: =IF(AND('Mapa final'!#REF!="Media",'Mapa final'!#REF!="Leve"),CONCATENATE("R",'Mapa final'!#REF!),"") -> #REF! | P24: =IF(AND('Mapa final'!#REF!="Media",'Mapa final'!#REF!="Menor"),CONCATENATE("R",'Mapa final'!#REF!),"") -> #REF! | R24: =IF(AND('Mapa final'!#REF!="Media",'Mapa final'!#REF!="Menor"),CONCATENATE("R",'Mapa final'!#REF!),"") -> #REF! | T24: =IF(AND('Mapa final'!#REF!="Media",'Mapa final'!#REF!="Menor"),CONCATENATE("R",'Mapa final'!#REF!),"") -> #REF! | V24: =IF(AND('Mapa final'!#REF!="Media",'Mapa final'!#REF!="Moderado"),CONCATENATE("R",'Mapa final'!#REF!),"") -> #REF! | X24: =IF(AND('Mapa final'!#REF!="Media",'Mapa final'!#REF!="Moderado"),CONCATENATE("R",'Mapa final'!#REF!),"") -> #REF! | Z24: =IF(AND('Mapa final'!#REF!="Media",'Mapa final'!#REF!="Moderado"),CONCATENATE("R",'Mapa final'!#REF!),"") -> #REF! | AB24: =IF(AND('Mapa final'!#REF!="Media",'Mapa final'!#REF!="Mayor"),CONCATENATE("R",'Mapa final'!#REF!),"") -> #REF! | AD24: =IF(AND('Mapa final'!#REF!="Media",'Mapa final'!#REF!="Mayor"),CONCATENATE("R",'Mapa final'!#REF!),"") -> #REF! | AF24: =IF(AND('Mapa final'!#REF!="Media",'Mapa final'!#REF!="Mayor"),CONCATENATE("R",'Mapa final'!#REF!),"") -> #REF! | AH24: =IF(AND('Mapa final'!#REF!="Media",'Mapa final'!#REF!="Catastrófico"),CONCATENATE("R",'Mapa final'!#REF!),"") -> #REF! | AJ24: =IF(AND('Mapa final'!#REF!="Media",'Mapa final'!#REF!="Catastrófico"),CONCATENATE("R",'Mapa final'!#REF!),"") -> #REF! | AL24: =IF(AND('Mapa final'!#REF!="Media",'Mapa final'!#REF!="Catastrófico"),CONCATENATE("R",'Mapa final'!#REF!),"") -> #REF!
J26: =IF(AND('Mapa final'!#REF!="Media",'Mapa final'!#REF!="Leve"),CONCATENATE("R",'Mapa final'!#REF!),"") -> #REF! | L26: =IF(AND('Mapa final'!#REF!="Media",'Mapa final'!#REF!="Leve"),CONCATENATE("R",'Mapa final'!#REF!),"") -> #REF! | N26: =IF(AND('Mapa final'!#REF!="Media",'Mapa final'!#REF!="Leve"),CONCATENATE("R",'Mapa final'!#REF!),"") -> #REF! | P26: =IF(AND('Mapa final'!#REF!="Media",'Mapa final'!#REF!="Menor"),CONCATENATE("R",'Mapa final'!#REF!),"") -> #REF! | R26: =IF(AND('Mapa final'!#REF!="Media",'Mapa final'!#REF!="Menor"),CONCATENATE("R",'Mapa final'!#REF!),"") -> #REF! | T26: =IF(AND('Mapa final'!#REF!="Media",'Mapa final'!#REF!="Menor"),CONCATENATE("R",'Mapa final'!#REF!),"") -> #REF! | V26: =IF(AND('Mapa final'!#REF!="Media",'Mapa final'!#REF!="Moderado"),CONCATENATE("R",'Mapa final'!#REF!),"") -> #REF! | X26: =IF(AND('Mapa final'!#REF!="Media",'Mapa final'!#REF!="Moderado"),CONCATENATE("R",'Mapa final'!#REF!),"") -> #REF! | Z26: =IF(AND('Mapa final'!#REF!="Media",'Mapa final'!#REF!="Moderado"),CONCATENATE("R",'Mapa final'!#REF!),"") -> #REF! | AB26: =IF(AND('Mapa final'!#REF!="Media",'Mapa final'!#REF!="Mayor"),CONCATENATE("R",'Mapa final'!#REF!),"") -> #REF! | AD26: =IF(AND('Mapa final'!#REF!="Media",'Mapa final'!#REF!="Mayor"),CONCATENATE("R",'Mapa final'!#REF!),"") -> #REF! | AF26: =IF(AND('Mapa final'!#REF!="Media",'Mapa final'!#REF!="Mayor"),CONCATENATE("R",'Mapa final'!#REF!),"") -> #REF! | AH26: =IF(AND('Mapa final'!#REF!="Media",'Mapa final'!#REF!="Catastrófico"),CONCATENATE("R",'Mapa final'!#REF!),"") -> #REF! | AJ26: =IF(AND('Mapa final'!#REF!="Media",'Mapa final'!#REF!="Catastrófico"),CONCATENATE("R",'Mapa final'!#REF!),"") -> #REF! | AL26: =IF(AND('Mapa final'!#REF!="Media",'Mapa final'!#REF!="Catastrófico"),CONCATENATE("R",'Mapa final'!#REF!),"") -> #REF!
J28: =IF(AND('Mapa final'!#REF!="Media",'Mapa final'!#REF!="Leve"),CONCATENATE("R",'Mapa final'!#REF!),"") -> #REF! | L28: =IF(AND('Mapa final'!$H$18="Media",'Mapa final'!$L$18="Leve"),CONCATENATE("R",'Mapa final'!$A$18),"") | N28: =IF(AND('Mapa final'!$H$24="Media",'Mapa final'!$L$24="Leve"),CONCATENATE("R",'Mapa final'!$A$24),"") | P28: =IF(AND('Mapa final'!#REF!="Media",'Mapa final'!#REF!="Menor"),CONCATENATE("R",'Mapa final'!#REF!),"") -> #REF! | R28: =IF(AND('Mapa final'!$H$18="Media",'Mapa final'!$L$18="Menor"),CONCATENATE("R",'Mapa final'!$A$18),"") | T28: =IF(AND('Mapa final'!$H$24="Media",'Mapa final'!$L$24="Menor"),CONCATENATE("R",'Mapa final'!$A$24),"") | V28: =IF(AND('Mapa final'!#REF!="Media",'Mapa final'!#REF!="Moderado"),CONCATENATE("R",'Mapa final'!#REF!),"") -> #REF! | X28: =IF(AND('Mapa final'!$H$18="Media",'Mapa final'!$L$18="Moderado"),CONCATENATE("R",'Mapa final'!$A$18),"") | Z28: =IF(AND('Mapa final'!$H$24="Media",'Mapa final'!$L$24="Moderado"),CONCATENATE("R",'Mapa final'!$A$24),"") | AB28: =IF(AND('Mapa final'!#REF!="Media",'Mapa final'!#REF!="Mayor"),CONCATENATE("R",'Mapa final'!#REF!),"") -> #REF! | AD28: =IF(AND('Mapa final'!$H$18="Media",'Mapa final'!$L$18="Mayor"),CONCATENATE("R",'Mapa final'!$A$18),"") | AF28: =IF(AND('Mapa final'!$H$24="Media",'Mapa final'!$L$24="Mayor"),CONCATENATE("R",'Mapa final'!$A$24),"") | AH28: =IF(AND('Mapa final'!#REF!="Media",'Mapa final'!#REF!="Catastrófico"),CONCATENATE("R",'Mapa final'!#REF!),"") -> #REF! | AJ28: =IF(AND('Mapa final'!$H$18="Media",'Mapa final'!$L$18="Catastrófico"),CONCATENATE("R",'Mapa final'!$A$18),"") | AL28: =IF(AND('Mapa final'!$H$24="Media",'Mapa final'!$L$24="Catastrófico"),CONCATENATE("R",'Mapa final'!$A$24),"")
E30: Baja 40% | J30: =IF(AND('Mapa final'!$H$13="Baja",'Mapa final'!$L$13="Leve"),CONCATENATE("R",'Mapa final'!$A$13),"") | L30: =IF(AND('Mapa final'!$H$16="Baja",'Mapa final'!$L$16="Leve"),CONCATENATE("R",'Mapa final'!$A$16),"") | N30: =IF(AND('Mapa final'!#REF!="Baja",'Mapa final'!#REF!="Leve"),CONCATENATE("R",'Mapa final'!#REF!),"") -> #REF! | P30: =IF(AND('Mapa final'!$H$13="Baja",'Mapa final'!$L$13="Menor"),CONCATENATE("R",'Mapa final'!$A$13),"") | R30: =IF(AND('Mapa final'!$H$16="Baja",'Mapa final'!$L$16="Menor"),CONCATENATE("R",'Mapa final'!$A$16),"") | T30: =IF(AND('Mapa final'!#REF!="Baja",'Mapa final'!#REF!="Menor"),CONCATENATE("R",'Mapa final'!#REF!),"") -> #REF! | V30: =IF(AND('Mapa final'!$H$13="Baja",'Mapa final'!$L$13="Moderado"),CONCATENATE("R",'Mapa final'!$A$13),"") | X30: =IF(AND('Mapa final'!$H$16="Baja",'Mapa final'!$L$16="Moderado"),CONCATENATE("R",'Mapa final'!$A$16),"") | Z30: =IF(AND('Mapa final'!#REF!="Baja",'Mapa final'!#REF!="Moderado"),CONCATENATE("R",'Mapa final'!#REF!),"") -> #REF! | AB30: =IF(AND('Mapa final'!$H$13="Baja",'Mapa final'!$L$13="Mayor"),CONCATENATE("R",'Mapa final'!$A$13),"") | AD30: =IF(AND('Mapa final'!$H$16="Baja",'Mapa final'!$L$16="Mayor"),CONCATENATE("R",'Mapa final'!$A$16),"") | AF30: =IF(AND('Mapa final'!#REF!="Baja",'Mapa final'!#REF!="Mayor"),CONCATENATE("R",'Mapa final'!#REF!),"") -> #REF! | AH30: =IF(AND('Mapa final'!$H$13="Baja",'Mapa final'!$L$13="Catastrófico"),CONCATENATE("R",'Mapa final'!$A$13),"") | AJ30: =IF(AND('Mapa final'!$H$16="Baja",'Mapa final'!$L$16="Catastrófico"),CONCATENATE("R",'Mapa final'!$A$16),"") | AL30: =IF(AND('Mapa final'!#REF!="Baja",'Mapa final'!#REF!="Catastrófico"),CONCATENATE("R",'Mapa final'!#REF!),"") -> #REF! | AO30: Bajo
J32: =IF(AND('Mapa final'!#REF!="Baja",'Mapa final'!#REF!="Leve"),CONCATENATE("R",'Mapa final'!#REF!),"") -> #REF! | L32: =IF(AND('Mapa final'!#REF!="Baja",'Mapa final'!#REF!="Leve"),CONCATENATE("R",'Mapa final'!#REF!),"") -> #REF! | N32: =IF(AND('Mapa final'!#REF!="Baja",'Mapa final'!#REF!="Leve"),CONCATENATE("R",'Mapa final'!#REF!),"") -> #REF! | P32: =IF(AND('Mapa final'!#REF!="Baja",'Mapa final'!#REF!="Menor"),CONCATENATE("R",'Mapa final'!#REF!),"") -> #REF! | R32: =IF(AND('Mapa final'!#REF!="Baja",'Mapa final'!#REF!="Menor"),CONCATENATE("R",'Mapa final'!#REF!),"") -> #REF! | T32: =IF(AND('Mapa final'!#REF!="Baja",'Mapa final'!#REF!="Menor"),CONCATENATE("R",'Mapa final'!#REF!),"") -> #REF! | V32: =IF(AND('Mapa final'!#REF!="Baja",'Mapa final'!#REF!="Moderado"),CONCATENATE("R",'Mapa final'!#REF!),"") -> #REF! | X32: =IF(AND('Mapa final'!#REF!="Baja",'Mapa final'!#REF!="Moderado"),CONCATENATE("R",'Mapa final'!#REF!),"") -> #REF! | Z32: =IF(AND('Mapa final'!#REF!="Baja",'Mapa final'!#REF!="Moderado"),CONCATENATE("R",'Mapa final'!#REF!),"") -> #REF! | AB32: =IF(AND('Mapa final'!#REF!="Baja",'Mapa final'!#REF!="Mayor"),CONCATENATE("R",'Mapa final'!#REF!),"") -> #REF! | AD32: =IF(AND('Mapa final'!#REF!="Baja",'Mapa final'!#REF!="Mayor"),CONCATENATE("R",'Mapa final'!#REF!),"") -> #REF! | AF32: =IF(AND('Mapa final'!#REF!="Baja",'Mapa final'!#REF!="Mayor"),CONCATENATE("R",'Mapa final'!#REF!),"") -> #REF! | AH32: =IF(AND('Mapa final'!#REF!="Baja",'Mapa final'!#REF!="Catastrófico"),CONCATENATE("R",'Mapa final'!#REF!),"") -> #REF! | AJ32: =IF(AND('Mapa final'!#REF!="Baja",'Mapa final'!#REF!="Catastrófico"),CONCATENATE("R",'Mapa final'!#REF!),"") -> #REF! | AL32: =IF(AND('Mapa final'!#REF!="Baja",'Mapa final'!#REF!="Catastrófico"),CONCATENATE("R",'Mapa final'!#REF!),"") -> #REF!
J34: =IF(AND('Mapa final'!#REF!="Baja",'Mapa final'!#REF!="Leve"),CONCATENATE("R",'Mapa final'!#REF!),"") -> #REF! | L34: =IF(AND('Mapa final'!#REF!="Baja",'Mapa final'!#REF!="Leve"),CONCATENATE("R",'Mapa final'!#REF!),"") -> #REF! | N34: =IF(AND('Mapa final'!#REF!="Baja",'Mapa final'!#REF!="Leve"),CONCATENATE("R",'Mapa final'!#REF!),"") -> #REF! | P34: =IF(AND('Mapa final'!#REF!="Baja",'Mapa final'!#REF!="Menor"),CONCATENATE("R",'Mapa final'!#REF!),"") -> #REF! | R34: =IF(AND('Mapa final'!#REF!="Baja",'Mapa final'!#REF!="Menor"),CONCATENATE("R",'Mapa final'!#REF!),"") -> #REF! | T34: =IF(AND('Mapa final'!#REF!="Baja",'Mapa final'!#REF!="Menor"),CONCATENATE("R",'Mapa final'!#REF!),"") -> #REF! | V34: =IF(AND('Mapa final'!#REF!="Baja",'Mapa final'!#REF!="Moderado"),CONCATENATE("R",'Mapa final'!#REF!),"") -> #REF! | X34: =IF(AND('Mapa final'!#REF!="Baja",'Mapa final'!#REF!="Moderado"),CONCATENATE("R",'Mapa final'!#REF!),"") -> #REF! | Z34: =IF(AND('Mapa final'!#REF!="Baja",'Mapa final'!#REF!="Moderado"),CONCATENATE("R",'Mapa final'!#REF!),"") -> #REF! | AB34: =IF(AND('Mapa final'!#REF!="Baja",'Mapa final'!#REF!="Mayor"),CONCATENATE("R",'Mapa final'!#REF!),"") -> #REF! | AD34: =IF(AND('Mapa final'!#REF!="Baja",'Mapa final'!#REF!="Mayor"),CONCATENATE("R",'Mapa final'!#REF!),"") -> #REF! | AF34: =IF(AND('Mapa final'!#REF!="Baja",'Mapa final'!#REF!="Mayor"),CONCATENATE("R",'Mapa final'!#REF!),"") -> #REF! | AH34: =IF(AND('Mapa final'!#REF!="Baja",'Mapa final'!#REF!="Catastrófico"),CONCATENATE("R",'Mapa final'!#REF!),"") -> #REF! | AJ34: =IF(AND('Mapa final'!#REF!="Baja",'Mapa final'!#REF!="Catastrófico"),CONCATENATE("R",'Mapa final'!#REF!),"") -> #REF! | AL34: =IF(AND('Mapa final'!#REF!="Baja",'Mapa final'!#REF!="Catastrófico"),CONCATENATE("R",'Mapa final'!#REF!),"") -> #REF!
J36: =IF(AND('Mapa final'!#REF!="Baja",'Mapa final'!#REF!="Leve"),CONCATENATE("R",'Mapa final'!#REF!),"") -> #REF! | L36: =IF(AND('Mapa final'!$H$18="Baja",'Mapa final'!$L$18="Leve"),CONCATENATE("R",'Mapa final'!$A$18),"") | N36: =IF(AND('Mapa final'!$H$24="Baja",'Mapa final'!$L$24="Leve"),CONCATENATE("R",'Mapa final'!$A$24),"") | P36: =IF(AND('Mapa final'!#REF!="Baja",'Mapa final'!#REF!="Menor"),CONCATENATE("R",'Mapa final'!#REF!),"") -> #REF! | R36: =IF(AND('Mapa final'!$H$18="Baja",'Mapa final'!$L$18="Menor"),CONCATENATE("R",'Mapa final'!$A$18),"") | T36: =IF(AND('Mapa final'!$H$24="Baja",'Mapa final'!$L$24="Menor"),CONCATENATE("R",'Mapa final'!$A$24),"") | V36: =IF(AND('Mapa final'!#REF!="Baja",'Mapa final'!#REF!="Moderado"),CONCATENATE("R",'Mapa final'!#REF!),"") -> #REF! | X36: =IF(AND('Mapa final'!$H$18="Baja",'Mapa final'!$L$18="Moderado"),CONCATENATE("R",'Mapa final'!$A$18),"") | Z36: =IF(AND('Mapa final'!$H$24="Baja",'Mapa final'!$L$24="Moderado"),CONCATENATE("R",'Mapa final'!$A$24),"") | AB36: =IF(AND('Mapa final'!#REF!="Baja",'Mapa final'!#REF!="Mayor"),CONCATENATE("R",'Mapa final'!#REF!),"") -> #REF! | AD36: =IF(AND('Mapa final'!$H$18="Baja",'Mapa final'!$L$18="Mayor"),CONCATENATE("R",'Mapa final'!$A$18),"") | AF36: =IF(AND('Mapa final'!$H$24="Baja",'Mapa final'!$L$24="Mayor"),CONCATENATE("R",'Mapa final'!$A$24),"") | AH36: =IF(AND('Mapa final'!#REF!="Baja",'Mapa final'!#REF!="Catastrófico"),CONCATENATE("R",'Mapa final'!#REF!),"") -> #REF! | AJ36: =IF(AND('Mapa final'!$H$18="Baja",'Mapa final'!$L$18="Catastrófico"),CONCATENATE("R",'Mapa final'!$A$18),"") | AL36: =IF(AND('Mapa final'!$H$24="Baja",'Mapa final'!$L$24="Catastrófico"),CONCATENATE("R",'Mapa final'!$A$24),"")
E38: Muy Baja 20% | J38: =IF(AND('Mapa final'!$H$13="Muy Baja",'Mapa final'!$L$13="Leve"),CONCATENATE("R",'Mapa final'!$A$13),"") | L38: =IF(AND('Mapa final'!$H$16="Muy Baja",'Mapa final'!$L$16="Leve"),CONCATENATE("R",'Mapa final'!$A$16),"") | N38: =IF(AND('Mapa final'!#REF!="Muy Baja",'Mapa final'!#REF!="Leve"),CONCATENATE("R",'Mapa final'!#REF!),"") -> #REF! | P38: =IF(AND('Mapa final'!$H$13="Muy Baja",'Mapa final'!$L$13="Menor"),CONCATENATE("R",'Mapa final'!$A$13),"") | R38: =IF(AND('Mapa final'!$H$16="Muy Baja",'Mapa final'!$L$16="Menor"),CONCATENATE("R",'Mapa final'!$A$16),"") | T38: =IF(AND('Mapa final'!#REF!="Muy Baja",'Mapa final'!#REF!="Menor"),CONCATENATE("R",'Mapa final'!#REF!),"") -> #REF! | V38: =IF(AND('Mapa final'!$H$13="Muy Baja",'Mapa final'!$L$13="Moderado"),CONCATENATE("R",'Mapa final'!$A$13),"") | X38: =IF(AND('Mapa final'!$H$16="Muy Baja",'Mapa final'!$L$16="Moderado"),CONCATENATE("R",'Mapa final'!$A$16),"") | Z38: =IF(AND('Mapa final'!#REF!="Muy Baja",'Mapa final'!#REF!="Moderado"),CONCATENATE("R",'Mapa final'!#REF!),"") -> #REF! | AB38: =IF(AND('Mapa final'!$H$13="Muy Baja",'Mapa final'!$L$13="Mayor"),CONCATENATE("R",'Mapa final'!$A$13),"") | AD38: =IF(AND('Mapa final'!$H$16="Muy Baja",'Mapa final'!$L$16="Mayor"),CONCATENATE("R",'Mapa final'!$A$16),"") | AF38: =IF(AND('Mapa final'!#REF!="Muy Baja",'Mapa final'!#REF!="Mayor"),CONCATENATE("R",'Mapa final'!#REF!),"") -> #REF! | AH38: =IF(AND('Mapa final'!$H$13="Muy Baja",'Mapa final'!$L$13="Catastrófico"),CONCATENATE("R",'Mapa final'!$A$13),"") | AJ38: =IF(AND('Mapa final'!$H$16="Muy Baja",'Mapa final'!$L$16="Catastrófico"),CONCATENATE("R",'Mapa final'!$A$16),"") | AL38: =IF(AND('Mapa final'!#REF!="Muy Baja",'Mapa final'!#REF!="Catastrófico"),CONCATENATE("R",'Mapa final'!#REF!),"") -> #REF!
J40: =IF(AND('Mapa final'!#REF!="Muy Baja",'Mapa final'!#REF!="Leve"),CONCATENATE("R",'Mapa final'!#REF!),"") -> #REF! | L40: =IF(AND('Mapa final'!#REF!="Muy Baja",'Mapa final'!#REF!="Leve"),CONCATENATE("R",'Mapa final'!#REF!),"") -> #REF! | N40: =IF(AND('Mapa final'!#REF!="Muy Baja",'Mapa final'!#REF!="Leve"),CONCATENATE("R",'Mapa final'!#REF!),"") -> #REF! | P40: =IF(AND('Mapa final'!#REF!="Muy Baja",'Mapa final'!#REF!="Menor"),CONCATENATE("R",'Mapa final'!#REF!),"") -> #REF! | R40: =IF(AND('Mapa final'!#REF!="Muy Baja",'Mapa final'!#REF!="Menor"),CONCATENATE("R",'Mapa final'!#REF!),"") -> #REF! | T40: =IF(AND('Mapa final'!#REF!="Muy Baja",'Mapa final'!#REF!="Menor"),CONCATENATE("R",'Mapa final'!#REF!),"") -> #REF! | V40: =IF(AND('Mapa final'!#REF!="Muy Baja",'Mapa final'!#REF!="Moderado"),CONCATENATE("R",'Mapa final'!#REF!),"") -> #REF! | X40: =IF(AND('Mapa final'!#REF!="Muy Baja",'Mapa final'!#REF!="Moderado"),CONCATENATE("R",'Mapa final'!#REF!),"") -> #REF! | Z40: =IF(AND('Mapa final'!#REF!="Muy Baja",'Mapa final'!#REF!="Moderado"),CONCATENATE("R",'Mapa final'!#REF!),"") -> #REF! | AB40: =IF(AND('Mapa final'!#REF!="Muy Baja",'Mapa final'!#REF!="Mayor"),CONCATENATE("R",'Mapa final'!#REF!),"") -> #REF! | AD40: =IF(AND('Mapa final'!#REF!="Muy Baja",'Mapa final'!#REF!="Mayor"),CONCATENATE("R",'Mapa final'!#REF!),"") -> #REF! | AF40: =IF(AND('Mapa final'!#REF!="Muy Baja",'Mapa final'!#REF!="Mayor"),CONCATENATE("R",'Mapa final'!#REF!),"") -> #REF! | AH40: =IF(AND('Mapa final'!#REF!="Muy Baja",'Mapa final'!#REF!="Catastrófico"),CONCATENATE("R",'Mapa final'!#REF!),"") -> #REF! | AJ40: =IF(AND('Mapa final'!#REF!="Muy Baja",'Mapa final'!#REF!="Catastrófico"),CONCATENATE("R",'Mapa final'!#REF!),"") -> #REF! | AL40: =IF(AND('Mapa final'!#REF!="Muy Baja",'Mapa final'!#REF!="Catastrófico"),CONCATENATE("R",'Mapa final'!#REF!),"") -> #REF!
J42: =IF(AND('Mapa final'!#REF!="Muy Baja",'Mapa final'!#REF!="Leve"),CONCATENATE("R",'Mapa final'!#REF!),"") -> #REF! | L42: =IF(AND('Mapa final'!#REF!="Muy Baja",'Mapa final'!#REF!="Leve"),CONCATENATE("R",'Mapa final'!#REF!),"") -> #REF! | N42: =IF(AND('Mapa final'!#REF!="Muy Baja",'Mapa final'!#REF!="Leve"),CONCATENATE("R",'Mapa final'!#REF!),"") -> #REF! | P42: =IF(AND('Mapa final'!#REF!="Muy Baja",'Mapa final'!#REF!="Menor"),CONCATENATE("R",'Mapa final'!#REF!),"") -> #REF! | R42: =IF(AND('Mapa final'!#REF!="Muy Baja",'Mapa final'!#REF!="Menor"),CONCATENATE("R",'Mapa final'!#REF!),"") -> #REF! | T42: =IF(AND('Mapa final'!#REF!="Muy Baja",'Mapa final'!#REF!="Menor"),CONCATENATE("R",'Mapa final'!#REF!),"") -> #REF! | V42: =IF(AND('Mapa final'!#REF!="Muy Baja",'Mapa final'!#REF!="Moderado"),CONCATENATE("R",'Mapa final'!#REF!),"") -> #REF! | X42: =IF(AND('Mapa final'!#REF!="Muy Baja",'Mapa final'!#REF!="Moderado"),CONCATENATE("R",'Mapa final'!#REF!),"") -> #REF! | Z42: =IF(AND('Mapa final'!#REF!="Muy Baja",'Mapa final'!#REF!="Moderado"),CONCATENATE("R",'Mapa final'!#REF!),"") -> #REF! | AB42: =IF(AND('Mapa final'!#REF!="Muy Baja",'Mapa final'!#REF!="Mayor"),CONCATENATE("R",'Mapa final'!#REF!),"") -> #REF! | AD42: =IF(AND('Mapa final'!#REF!="Muy Baja",'Mapa final'!#REF!="Mayor"),CONCATENATE("R",'Mapa final'!#REF!),"") -> #REF! | AF42: =IF(AND('Mapa final'!#REF!="Muy Baja",'Mapa final'!#REF!="Mayor"),CONCATENATE("R",'Mapa final'!#REF!),"") -> #REF! | AH42: =IF(AND('Mapa final'!#REF!="Muy Baja",'Mapa final'!#REF!="Catastrófico"),CONCATENATE("R",'Mapa final'!#REF!),"") -> #REF! | AJ42: =IF(AND('Mapa final'!#REF!="Muy Baja",'Mapa final'!#REF!="Catastrófico"),CONCATENATE("R",'Mapa final'!#REF!),"") -> #REF! | AL42: =IF(AND('Mapa final'!#REF!="Muy Baja",'Mapa final'!#REF!="Catastrófico"),CONCATENATE("R",'Mapa final'!#REF!),"") -> #REF!
J44: =IF(AND('Mapa final'!#REF!="Muy Baja",'Mapa final'!#REF!="Leve"),CONCATENATE("R",'Mapa final'!#REF!),"") -> #REF! | L44: =IF(AND('Mapa final'!$H$18="Muy Baja",'Mapa final'!$L$18="Leve"),CONCATENATE("R",'Mapa final'!$A$18),"") | N44: =IF(AND('Mapa final'!$H$24="Muy Baja",'Mapa final'!$L$24="Leve"),CONCATENATE("R",'Mapa final'!$A$24),"") | P44: =IF(AND('Mapa final'!#REF!="Muy Baja",'Mapa final'!#REF!="Menor"),CONCATENATE("R",'Mapa final'!#REF!),"") -> #REF! | R44: =IF(AND('Mapa final'!$H$18="Muy Baja",'Mapa final'!$L$18="Menor"),CONCATENATE("R",'Mapa final'!$A$18),"") | T44: =IF(AND('Mapa final'!$H$24="Muy Baja",'Mapa final'!$L$24="Menor"),CONCATENATE("R",'Mapa final'!$A$24),"") | V44: =IF(AND('Mapa final'!#REF!="Muy Baja",'Mapa final'!#REF!="Moderado"),CONCATENATE("R",'Mapa final'!#REF!),"") -> #REF! | X44: =IF(AND('Mapa final'!$H$18="Muy Baja",'Mapa final'!$L$18="Moderado"),CONCATENATE("R",'Mapa final'!$A$18),"") | Z44: =IF(AND('Mapa final'!$H$24="Muy Baja",'Mapa final'!$L$24="Moderado"),CONCATENATE("R",'Mapa final'!$A$24),"") | AB44: =IF(AND('Mapa final'!#REF!="Muy Baja",'Mapa final'!#REF!="Mayor"),CONCATENATE("R",'Mapa final'!#REF!),"") -> #REF! | AD44: =IF(AND('Mapa final'!$H$18="Muy Baja",'Mapa final'!$L$18="Mayor"),CONCATENATE("R",'Mapa final'!$A$18),"") | AF44: =IF(AND('Mapa final'!$H$24="Muy Baja",'Mapa final'!$L$24="Mayor"),CONCATENATE("R",'Mapa final'!$A$24),"") | AH44: =IF(AND('Mapa final'!#REF!="Muy Baja",'Mapa final'!#REF!="Catastrófico"),CONCATENATE("R",'Mapa final'!#REF!),"") -> #REF! | AJ44: =IF(AND('Mapa final'!$H$18="Muy Baja",'Mapa final'!$L$18="Catastrófico"),CONCATENATE("R",'Mapa final'!$A$18),"") | AL44: =IF(AND('Mapa final'!$H$24="Muy Baja",'Mapa final'!$L$24="Catastrófico"),CONCATENATE("R",'Mapa final'!$A$24),"")
J46: Leve 20% | P46: Menor 40% | V46: Moderado 60% | AB46: Mayor 80% | AH46: Catastrófico 100%

