Workbook

Sheet Intructivo
B2: Matriz Mapa de Riesgos
B4: Teniendo en cuenta que con la expedición del Decreto 1499 de 2017 “Por medio del cual se modifica el Decreto 1083 de 2015, Decreto Único Reglamentario del Sector Función Pública, en lo relacionado con el Sistema de Gestión establecido en el artículo 133 de la Ley 1753 de 2015”, se crea un solo Sistema de Gestión y se alinea con el Sistema de Control Interno, hoy todas las entidades públicas requieren actualizar y/o implementar el Modelo Integrado de Planeación y Gestión MIPG, modelo que incorpora el Modelo Estándar de Control Interno MECI a través de la 7a dimensión del mismo. En este marco general, el proceso de administración del riesgo es un esfuerzo conjunto entre la Alta Dirección y los servidores en todos sus niveles, ejercicio que inicia con la formulación de la política de Administración del Riesgo, la cual incluye los niveles de responsabilidad frente al seguimiento y evaluación, aspectos que deberán definirse acorde con el Esquema de Líneas de Defensa vinculado a la Dimensión 7. Teniendo en cuenta lo anterior y dada la necesidad de las entidades frente a la estructuración de los mapas de riesgos, como herramienta fundamental frente a la gestión del riesgo, el presente formato desarrolla un esquema completo acorde con los contenidos metodológicos de la Guía para la Administración del Riesgo y el diseño de controles V5. El formato cuenta con celdas parametrizadas y permite contar con los respectivos mapas de calor para riesgo inherente y riesgo residual.
B6: Orientaciones Generales
B7: Antes de iniciar con el diligenciamiento de la información en la matriz, se requiere haber avanzado en el análisis del proceso, su objetivo, alcance, actividades clave, considere los lineamientos establecidos en el Paso 2: identificación del riesgo, donde se explica ampliamente las bases para adelanter este análisis. Así mismo, considere en el Paso 3: valoración del riesgo los lineamientos para definir el No. de veces que se hace la actividad con la cual se relaciona el riesgo y su impacto en términos económicos o reputacionales. En este mismo paso se analizan los controles que deben responder a los atributos de eficiencia e informativos. NOTA: Si lo considera pertinente, es posible agregar hojas de trabajo adicionales al presente formato que permitan incluir la traza de estos análisis.
B9: El archivo contiene las siguientes hojas: - Hoja 1 Instructivo - Hoja 2 Mapa Final: Encontrará la totalidad de la estructura para la identificación y valoración de los riesgos por proceso, programa o proyecto, acorde con el nivel de desagregación que la entidad considere necesaria.
C12: Columna | E12: Descripción - Lineamientos para el diligenciamiento
C13: Proceso | E13: Diligencie el nombre del proceso al cual se le identificarán y valorarán los riesgos.
C14: Objetivo | E14: Diligencie el objetivo del proceso.
C15: Alcance | E15: Diligencie el alcance del proceso.
C16: Referencia | E16: Permite definir unl consecutivo de riesgos. Una entidad puede ir en el riesgo 150, pero tener 70 riesgos, lo que permite llevar una traza de los riesgos. Esta información la debe administrar la oficina asesora de planeación o gerencia de riesgos. Cuando un el riesgo salga del mapa no existirá otro riesgo con el mismo número.
C17: Impacto | E17: Analice las consecuencias que puede ocasionar a la organización la materialización del riesgo, redacte de la forma más concreta posible.
C18: Causa Inmediata | E18: Circunstancias bajo las cuales se presenta el riesgo, es la situación más evidente frente al riesgo, redacte de la forma más concreta posible.
C19: Causa Raíz | E19: Causa principal o básica, corresponde a las razones por la cuales se puede presentar el riesgo, redacte de la forma más concreta posible.
C20: Descripción del Riesgo | E20: Consolida o resume los análisis sobre impacto + causa inmediata + causa raíz, permitiendo contar con una redacción clara y concreta del riesgo indentificado. Tenga en cuenta la estructura de alto nivel establecida en al guía, inicia con POSIBILIDAD DE + Impacto para la entidad (Qué) + Causa Inmediata (Cómo) + Causa Raíz (Por qué)
C21: Clasificación del Riesgo | E21: Utilice la lista de despligue que se encuentra parametrizada, le aparecerán las opciones: i)Daños Activos Fisicos, ii)Ejecucion y Administracion de procesos, iii)Fallas Tecnologicas, iv)Fraude Externo, v)Fraude Interno, vi)Relaciones Laborales, vii)Usuarios, productos y practicas organizacionales.
C22: Frecuencia con la cual se lleva a cabo la actividad | E22: Defina el # de veces que se ejecuta la actividad durante el año, (Recuerde la probabilidad e ocurrencia del riesgo se defien como el No. de veces que se pasa por el punto de riesgo en el periodo de 1 año). La matriz automáticamente hará el cálculo para el nivel de probabilidad inherente (Columnas H-I)
C23: Criterios de Impacto | E23: Utilice la lista de despligue que se encuentra parametrizada, le aparecerán las opciones de la tabla de Impacto en la Hoja 6 del presente documento. La matriz automáticamente hará el cálculo para el nivel de impacto inherente (Columnas L-M)
... C37: Estado | E37: Utilice la lista de despligue que se encuentra parametrizada, le aparecerán las opciones: i)Finalizado, ii)En curso, la selección en este caso dependerá de las acciones del plan que se hayan establecido en cada caso.
B40: - Hoja 3 Matriz de Calor Inherente: En esta hoja, en la medida en que ese diligencia el Mapa Final, se verán reflejados los riesgos en su zona correspondiente. Esta hoja no se diligencia se genera de manera automática.
B41: - Hoja 4 Matriz de Calor Residual: En esta hoja, en la medida en que ese diligencia el Mapa Final, se verán reflejados los riesgos en su zona correspondiente. Esta hoja no se diligencia se genera de manera automática.
B42: - Hoja 5 Tabla de probabilidad: Tabla referente para todos los cálculos (no se diligencia)
B43: - Hoja 6 Tabla de Impacto: Tabla referente para todos los cálculos (no se diligencia)
B44: - Hoja 7 Tabla de Valoración de Controles: Tabla referente para todos los cálculos (no se diligencia)

Sheet Mapa final
D1: SISTEMA DE GESTIÓN DE CALIDAD
D3: GESTIÓN DE CALIDAD
D4: MAPA DE RIESGOS
D5: VERSIÓN: 05 | G5: FECHA: 07/05/2025 | J5: Página 1 de 1
A7: Proceso: | C7: GESTION CONTRACTUAL
A8: Objetivo: | C8: Ejecutar las etapas pre-contractual, contractual, post-contractual para la adquisición de bienes y servicios requeridos por el Concejo Municipal de Chía dentro del marco legal establecido para cada modalidad de contratación. Asistir, apoyar, y asesorar jurídicamente a la Corporación de manera oportuna y efectiva en los procesos judiciales, administrativos, consultas internas y externas con el fin de dar cumplimiento.
A9: Alcance: | C9: Inicia con la formulación del Plan de Acción del proceso, la recepción, priorización de las solicitudes realizadas que requieran un apoyo jurídico y la planificación de las actividades contractuales y finaliza con los seguimientos al cumplimiento de requisitos de los procesos contractuales y al cumplimiento oportuno de las solicitudes y requerimientos realizados al proceso jurídico.
A10: Identificación del riesgo | H10: Análisis del riesgo inherente | O10: Evaluación del riesgo - Valoración de los controles | X10: Evaluación del riesgo - Nivel del riesgo residual | AE10: Plan de Acción | AH10: I SEGUIMIENTO 2025 Corte 30 de Abril | AK10: II SEGUIMIENTO 2025 Corte 31 de Agosto | AN10: III SEGUIMIENTO 2025 Corte 31 de Diciembre
A11: Referencia | B11: Impacto | C11: Causa Inmediata | D11: Causa Raíz | E11: Descripción del Riesgo | F11: Clasificación del Riesgo | G11: Frecuencia con la cual se realiza la actividad | H11: Probabilidad Inherente | I11: % | J11: Criterios de impacto | K11: Observación de criterio | L11: Impacto Inherente | M11: % | N11: Zona de Riesgo Inherente | O11: No. Control | P11: Descripción del Control | Q11: Afectación | R11: Atributos | X11: Probabilidad Residual | Y11: Probabilidad Residual Final | Z11: % | AA11: Impacto Residual Final | AB11: % | AC11: Zona de Riesgo Final | AD11: Tratamiento | AE11: Plan de Acción | AF11: Responsable | AG11: Fecha Implementación | AH11: Fecha Seguimiento | AI11: Seguimiento | AJ11: Estado del Plan de Acción | AK11: Fecha Seguimiento | AL11: Seguimiento | AM11: Estado del Plan de Acción | AN11: Fecha Seguimiento | AO11: Seguimiento | AP11: Estado del Plan de Acción
R12: Tipo | S12: Implementación | T12: Calificación | U12: Documentación | V12: Frecuencia | W12: Evidencia
A13: 1 | B13: Económico | C13: Pèrdida economica por demandas y reclamaciones | D13: Por controversias contractuales | E13: Posibilidad de pèrdida economica por demandas y reclamaciones debido a controversias contractuales | F13: Usuarios, productos y practicas , organizacionales | G13: 12 | H13: =IF(G13<=0,"",IF(G13<=2,"Muy Baja",IF(G13<=24,"Baja",IF(G13<=500,"Media",IF(G13<=5000,"Alta","Muy Alta"))))) -> Baja | I13: =IF(H13="","",IF(H13="Muy Baja",0.2,IF(H13="Baja",0.4,IF(H13="Media",0.6,IF(H13="Alta",0.8,IF(H13="Muy Alta",1,)))))) -> 0.4 | J13: Entre 50 y 100 SMLMV | K13: =IF(NOT(ISERROR(MATCH(J13,#REF!,0))),#REF!&"Por favor no seleccionar los criterios de impacto(Afectación Económica o presupuestal y Pérdida Reputacional)",J13) -> Entre 50 y 100 SMLMV | L13: =IF(OR(K13='[1]Tabla Impacto'!$C$11,K13='[1]Tabla Impacto'!$D$11),"Leve",IF(OR(K13='[1]Tabla Impacto'!$C$12,K13='[1]Tabla Impacto'!$D$12),"Menor",IF(OR(K13='[1]Tabla Impacto'!$C$13,K13='[1]Tabla Impacto'!$D$13),"Moderado",IF(OR(K13='[1]Tabla Impacto'!$C$14,K13='[1]Tabla Impacto'!$D$14),"Mayor",IF(OR(K13='[1]Tabla Impacto'!$C$15,K13='[1]Tabla Impacto'!$D$15),"Catastrófico",""))))) -> Moderado | M13: =IF(L13="","",IF(L13="Leve",0.2,IF(L13="Menor",0.4,IF(L13="Moderado",0.6,IF(L13="Mayor",0.8,IF(L13="Catastrófico",1,)))))) -> 0.6 | N13: =IF(OR(AND(H13="Muy Baja",L13="Leve"),AND(H13="Muy Baja",L13="Menor"),AND(H13="Baja",L13="Leve")),"Bajo",IF(OR(AND(H13="Muy baja",L13="Moderado"),AND(H13="Baja",L13="Menor"),AND(H13="Baja",L13="Moderado"),AND(H13="Media",L13="Leve"),AND(H13="Media",L13="Menor"),AND(H13="Media",L13="Moderado"),AND(H13="Alta",L13="Leve"),AND(H13="Alta",L13="Menor")),"Moderado",IF(OR(AND(H13="Muy Baja",L13="Mayor"),AND(H13="Baja",L13="Mayor"),AND(H13="Media",L13="Mayor"),AND(H13="Alta",L13="Moderado"),AND(H13="Alta",L13="Mayor"),AND(H13="Muy Alta",L13="Leve"),AND(H13="Muy Alta",L13="Menor"),AND(H13="Muy Alta",L13="Moderado"),AND(H13="Muy Alta",L13="Mayor")),"Alto",IF(OR(AND(H13="Muy Baja",L13="Catastrófico"),AND(H13="Baja",L13="Catastrófico"),AND(H13="Media",L13="Catastrófico"),AND(H13="Alta",L13="Catastrófico"),AND(H13="Muy Alta",L13="Catastrófico")),"Extremo","")))) -> Moderado | O13: 1 | P13: El supervisor de cada contrato debera realizar un seguimiento permamente al desarrollo de la ejecuciòn del contrato. Siguiendo los lineamientos establecidos en el Manual de Contrataciòn, en caso de encontrar un incumplimiento debera manifestarlo al proveedor o contratista a traves de requerimiento y en caso de ser necesario se informa al ordenador del gasto. | Q13: =IF(OR(R13="Preventivo",R13="Detectivo"),"Probabilidad",IF(R13="Correctivo","Impacto","")) -> Probabilidad | R13: Detectivo | S13: Manual | T13: =IF(AND(R13="Preventivo",S13="Automático"),"50%",IF(AND(R13="Preventivo",S13="Manual"),"40%",IF(AND(R13="Detectivo",S13="Automático"),"40%",IF(AND(R13="Detectivo",S13="Manual"),"30%",IF(AND(R13="Correctivo",S13="Automático"),"35%",IF(AND(R13="Correctivo",S13="Manual"),"25%","")))))) -> 30% | U13: Documentado | V13: Continua | W13: Con Registro | X13: =IFERROR(IF(Q13="Probabilidad",(I13-(+I13*T13)),IF(Q13="Impacto",I13,"")),"") -> 0.28 | Y13: =IFERROR(IF(X13="","",IF(X13<=0.2,"Muy Baja",IF(X13<=0.4,"Baja",IF(X13<=0.6,"Media",IF(X13<=0.8,"Alta","Muy Alta"))))),"") -> Baja | Z13: =+X13 -> 0.28 | AA13: =IFERROR(IF(AB13="","",IF(AB13<=0.2,"Leve",IF(AB13<=0.4,"Menor",IF(AB13<=0.6,"Moderado",IF(AB13<=0.8,"Mayor","Catastrófico"))))),"") -> Moderado | AB13: =IFERROR(IF(Q13="Impacto",(M13-(+M13*T13)),IF(Q13="Probabilidad",M13,"")),"") -> 0.6 | AC13: =IFERROR(IF(OR(AND(Y13="Muy Baja",AA13="Leve"),AND(Y13="Muy Baja",AA13="Menor"),AND(Y13="Baja",AA13="Leve")),"Bajo",IF(OR(AND(Y13="Muy baja",AA13="Moderado"),AND(Y13="Baja",AA13="Menor"),AND(Y13="Baja",AA13="Moderado"),AND(Y13="Media",AA13="Leve"),AND(Y13="Media",AA13="Menor"),AND(Y13="Media",AA13="Moderado"),AND(Y13="Alta",AA13="Leve"),AND(Y13="Alta",AA13="Menor")),"Moderado",IF(OR(AND(Y13="Muy Baja",AA13="Mayor"),AND(Y13="Baja",AA13="Mayor"),AND(Y13="Media",AA13="Mayor"),AND(Y13="Alta",AA13="Moderado"),AND(Y13="Alta",AA13="Mayor"),AND(Y13="Muy Alta",AA13="Leve"),AND(Y13="Muy Alta",AA13="Menor"),AND(Y13="Muy Alta",AA13="Moderado"),AND(Y13="Muy Alta",AA13="Mayor")),"Alto",IF(OR(AND(Y13="Muy Baja",AA13="Catastrófico"),AND(Y13="Baja",AA13="Catastrófico"),AND(Y13="Media",AA13="Catastrófico"),AND(Y13="Alta",AA13="Catastrófico"),AND(Y13="Muy Alta",AA13="Catastrófico")),"Extremo","")))),"") -> Moderado | AD13: Reducir (mitigar) | AE13: Acompañamiento a los supervosres en la etapa de ejecucion contractual | AF13: Asesor Contratación | AG13: 45688
K14: =IF(NOT(ISERROR(MATCH(J14,_xlfn.ANCHORARRAY(E18),0))),#REF!&"Por favor no seleccionar los criterios de impacto",J14) -> 0 | O14: 2 | P14: El Asesor Contractual verifica que cada vez que se vaya a realizar el pago, el Supervisor haya realizado el correspondiente informe de supervisión. | Q14: Probabilidad | R14: Preventivo | S14: Manual | T14: =IF(AND(R14="Preventivo",S14="Automático"),"50%",IF(AND(R14="Preventivo",S14="Manual"),"40%",IF(AND(R14="Detectivo",S14="Automático"),"40%",IF(AND(R14="Detectivo",S14="Manual"),"30%",IF(AND(R14="Correctivo",S14="Automático"),"35%",IF(AND(R14="Correctivo",S14="Manual"),"25%","")))))) -> 40% | U14: Documentado | V14: Continua | W14: Sin Registro | X14: =IFERROR(IF(AND(Q13="Probabilidad",Q14="Probabilidad"),(Z13-(+Z13*T14)),IF(Q14="Probabilidad",(I13-(+I13*T14)),IF(Q14="Impacto",Z13,""))),"") -> 0.168 | Y14: =IFERROR(IF(X14="","",IF(X14<=0.2,"Muy Baja",IF(X14<=0.4,"Baja",IF(X14<=0.6,"Media",IF(X14<=0.8,"Alta","Muy Alta"))))),"") -> Muy Baja | Z14: =+X14 -> 0.168 | AB14: =IFERROR(IF(AND(Q13="Impacto",Q14="Impacto"),(AB13-(+AB13*T14)),IF(Q14="Impacto",($M$13-(+$M$13*T14)),IF(Q14="Probabilidad",AB13,""))),"") -> 0.6 | AE14: Seguimiento al cumplimiento por parte del supervisor en la generacion de informe de supervisión como requisito de pago | AF14: Asesor Contratación | AG14: 45688
K15: =IF(NOT(ISERROR(MATCH(J15,_xlfn.ANCHORARRAY(#REF!),0))),#REF!&"Por favor no seleccionar los criterios de impacto",J15) -> 0 | O15: 3 | P15: El supervisor debera verificar que se entregue y se cargue el informe de actividades con soportes del contratista con todos sus soportes en la plataforma Secop II | Q15: Probabilidad | R15: Detectivo | S15: Manual | T15: =IF(AND(R15="Preventivo",S15="Automático"),"50%",IF(AND(R15="Preventivo",S15="Manual"),"40%",IF(AND(R15="Detectivo",S15="Automático"),"40%",IF(AND(R15="Detectivo",S15="Manual"),"30%",IF(AND(R15="Correctivo",S15="Automático"),"35%",IF(AND(R15="Correctivo",S15="Manual"),"25%","")))))) -> 30% | U15: Documentado | V15: Continua | W15: Con Registro | X15: =IFERROR(IF(AND(Q14="Probabilidad",Q15="Probabilidad"),(Z14-(+Z14*T15)),IF(AND(Q14="Impacto",Q15="Probabilidad"),(Z13-(+Z13*T15)),IF(Q15="Impacto",Z14,""))),"") -> 0.1176 | Y15: =IFERROR(IF(X15="","",IF(X15<=0.2,"Muy Baja",IF(X15<=0.4,"Baja",IF(X15<=0.6,"Media",IF(X15<=0.8,"Alta","Muy Alta"))))),"") -> Muy Baja | Z15: =+X15 -> 0.1176 | AA15: =IFERROR(IF(AB15="","",IF(AB15<=0.2,"Leve",IF(AB15<=0.4,"Menor",IF(AB15<=0.6,"Moderado",IF(AB15<=0.8,"Mayor","Catastrófico"))))),"") -> Moderado | AB15: =IFERROR(IF(AND(Q14="Impacto",Q15="Impacto"),(AB14-(+AB14*T15)),IF(AND(Q14="Probabilidad",Q15="Impacto"),(AB13-(+AB13*T15)),IF(Q15="Probabilidad",AB14,""))),"") -> 0.6 | AC15: =IFERROR(IF(OR(AND(Y15="Muy Baja",AA15="Leve"),AND(Y15="Muy Baja",AA15="Menor"),AND(Y15="Baja",AA15="Leve")),"Bajo",IF(OR(AND(Y15="Muy baja",AA15="Moderado"),AND(Y15="Baja",AA15="Menor"),AND(Y15="Baja",AA15="Moderado"),AND(Y15="Media",AA15="Leve"),AND(Y15="Media",AA15="Menor"),AND(Y15="Media",AA15="Moderado"),AND(Y15="Alta",AA15="Leve"),AND(Y15="Alta",AA15="Menor")),"Moderado",IF(OR(AND(Y15="Muy Baja",AA15="Mayor"),AND(Y15="Baja",AA15="Mayor"),AND(Y15="Media",AA15="Mayor"),AND(Y15="Alta",AA15="Moderado"),AND(Y15="Alta",AA15="Mayor"),AND(Y15="Muy Alta",AA15="Leve"),AND(Y15="Muy Alta",AA15="Menor"),AND(Y15="Muy Alta",AA15="Moderado"),AND(Y15="Muy Alta",AA15="Mayor")),"Alto",IF(OR(AND(Y15="Muy Baja",AA15="Catastrófico"),AND(Y15="Baja",AA15="Catastrófico"),AND(Y15="Media",AA15="Catastrófico"),AND(Y15="Alta",AA15="Catastrófico"),AND(Y15="Muy Alta",AA15="Catastrófico")),"Extremo","")))),"") -> Moderado | AD15: Reducir (mitigar) | AE15: Verificación en la plataforma Secop II el cargue de informe de actividades y supervisión | AF15: Asesor Contratación | AG15: 45688
A16: 2 | B16: Económico | C16: Multa y sanciòn de ente regulador | D16: Adquisiciòn de bienes y servicios sin el cummplimiento de los requisitos normativos | E16: Posibilidad de afectaciòn economica por multa y sanciòn del ente regulador debido a la adquisiciòn de bienes y servicios sin el cumplimiento de los requisitos normativos | F16: Usuarios, productos y practicas , organizacionales | G16: 12 | H16: =IF(G16<=0,"",IF(G16<=2,"Muy Baja",IF(G16<=24,"Baja",IF(G16<=500,"Media",IF(G16<=5000,"Alta","Muy Alta"))))) -> Baja | I16: =IF(H16="","",IF(H16="Muy Baja",0.2,IF(H16="Baja",0.4,IF(H16="Media",0.6,IF(H16="Alta",0.8,IF(H16="Muy Alta",1,)))))) -> 0.4 | J16: Entre 50 y 100 SMLMV | K16: =IF(NOT(ISERROR(MATCH(J16,#REF!,0))),#REF!&"Por favor no seleccionar los criterios de impacto(Afectación Económica o presupuestal y Pérdida Reputacional)",J16) -> Entre 50 y 100 SMLMV | L16: =IF(OR(K16='[1]Tabla Impacto'!$C$11,K16='[1]Tabla Impacto'!$D$11),"Leve",IF(OR(K16='[1]Tabla Impacto'!$C$12,K16='[1]Tabla Impacto'!$D$12),"Menor",IF(OR(K16='[1]Tabla Impacto'!$C$13,K16='[1]Tabla Impacto'!$D$13),"Moderado",IF(OR(K16='[1]Tabla Impacto'!$C$14,K16='[1]Tabla Impacto'!$D$14),"Mayor",IF(OR(K16='[1]Tabla Impacto'!$C$15,K16='[1]Tabla Impacto'!$D$15),"Catastrófico",""))))) -> Moderado | M16: =IF(L16="","",IF(L16="Leve",0.2,IF(L16="Menor",0.4,IF(L16="Moderado",0.6,IF(L16="Mayor",0.8,IF(L16="Catastrófico",1,)))))) -> 0.6 | N16: =IF(OR(AND(H16="Muy Baja",L16="Leve"),AND(H16="Muy Baja",L16="Menor"),AND(H16="Baja",L16="Leve")),"Bajo",IF(OR(AND(H16="Muy baja",L16="Moderado"),AND(H16="Baja",L16="Menor"),AND(H16="Baja",L16="Moderado"),AND(H16="Media",L16="Leve"),AND(H16="Media",L16="Menor"),AND(H16="Media",L16="Moderado"),AND(H16="Alta",L16="Leve"),AND(H16="Alta",L16="Menor")),"Moderado",IF(OR(AND(H16="Muy Baja",L16="Mayor"),AND(H16="Baja",L16="Mayor"),AND(H16="Media",L16="Mayor"),AND(H16="Alta",L16="Moderado"),AND(H16="Alta",L16="Mayor"),AND(H16="Muy Alta",L16="Leve"),AND(H16="Muy Alta",L16="Menor"),AND(H16="Muy Alta",L16="Moderado"),AND(H16="Muy Alta",L16="Mayor")),"Alto",IF(OR(AND(H16="Muy Baja",L16="Catastrófico"),AND(H16="Baja",L16="Catastrófico"),AND(H16="Media",L16="Catastrófico"),AND(H16="Alta",L16="Catastrófico"),AND(H16="Muy Alta",L16="Catastrófico")),"Extremo","")))) -> Moderado | O16: 1 | P16: El Asesor de contrataciòn debera verificar previamente que la contrataciòn que este desarollando desde su etapa previa hasta la adjudicaciòn y posterior liquidaciòn del contrato, este ceñida bajo el marco nomativo, estatuto general de contrataciòn, el manual de contrataciòn de la Corporaciòn y a su vez incluyendo los conceptos emitidos por colombia compra eficiente y las sentencias de unificaciòn, de acuerdo a las listas de chequeo por cada modalidad de contratación | Q16: =IF(OR(R16="Preventivo",R16="Detectivo"),"Probabilidad",IF(R16="Correctivo","Impacto","")) -> Probabilidad | R16: Preventivo | S16: Manual | T16: =IF(AND(R16="Preventivo",S16="Automático"),"50%",IF(AND(R16="Preventivo",S16="Manual"),"40%",IF(AND(R16="Detectivo",S16="Automático"),"40%",IF(AND(R16="Detectivo",S16="Manual"),"30%",IF(AND(R16="Correctivo",S16="Automático"),"35%",IF(AND(R16="Correctivo",S16="Manual"),"25%","")))))) -> 40% | U16: Documentado | V16: Continua | W16: Con Registro | X16: =IFERROR(IF(Q16="Probabilidad",(I16-(+I16*T16)),IF(Q16="Impacto",I16,"")),"") -> 0.24 | Y16: =IFERROR(IF(X16="","",IF(X16<=0.2,"Muy Baja",IF(X16<=0.4,"Baja",IF(X16<=0.6,"Media",IF(X16<=0.8,"Alta","Muy Alta"))))),"") -> Baja | Z16: =+X16 -> 0.24 | AA16: =IFERROR(IF(AB16="","",IF(AB16<=0.2,"Leve",IF(AB16<=0.4,"Menor",IF(AB16<=0.6,"Moderado",IF(AB16<=0.8,"Mayor","Catastrófico"))))),"") -> Moderado | AB16: =IFERROR(IF(Q16="Impacto",(M16-(+M16*T16)),IF(Q16="Probabilidad",M16,"")),"") -> 0.6 | AC16: =IFERROR(IF(OR(AND(Y16="Muy Baja",AA16="Leve"),AND(Y16="Muy Baja",AA16="Menor"),AND(Y16="Baja",AA16="Leve")),"Bajo",IF(OR(AND(Y16="Muy baja",AA16="Moderado"),AND(Y16="Baja",AA16="Menor"),AND(Y16="Baja",AA16="Moderado"),AND(Y16="Media",AA16="Leve"),AND(Y16="Media",AA16="Menor"),AND(Y16="Media",AA16="Moderado"),AND(Y16="Alta",AA16="Leve"),AND(Y16="Alta",AA16="Menor")),"Moderado",IF(OR(AND(Y16="Muy Baja",AA16="Mayor"),AND(Y16="Baja",AA16="Mayor"),AND(Y16="Media",AA16="Mayor"),AND(Y16="Alta",AA16="Moderado"),AND(Y16="Alta",AA16="Mayor"),AND(Y16="Muy Alta",AA16="Leve"),AND(Y16="Muy Alta",AA16="Menor"),AND(Y16="Muy Alta",AA16="Moderado"),AND(Y16="Muy Alta",AA16="Mayor")),"Alto",IF(OR(AND(Y16="Muy Baja",AA16="Catastrófico"),AND(Y16="Baja",AA16="Catastrófico"),AND(Y16="Media",AA16="Catastrófico"),AND(Y16="Alta",AA16="Catastrófico"),AND(Y16="Muy Alta",AA16="Catastrófico")),"Extremo","")))),"") -> Moderado | AD16: Reducir (mitigar) | AE16: Verificación de cumplimiento de señalamientos establecidos en el Estatuto General de Contratacion Pública y demas concordantes para la adquisicion de bienes y/o servicios en la Corporación | AF16: Asesor Contratación | AG16: 45688
K17: =IF(NOT(ISERROR(MATCH(J17,_xlfn.ANCHORARRAY(#REF!),0))),#REF!&"Por favor no seleccionar los criterios de impacto",J17) -> 0 | O17: 2 | P17: El Asesor de Contratación verifca el cumpimiento de requisitos juridicos, tecnicos y economicos minimos exigidos de acuerdo a la modalidad de contratacon utilizada a traves de certificacion de cumplimiento de requisitos minimos legales o verificacion o evaluaciones a documentacion presentada. | Q17: =IF(OR(R17="Preventivo",R17="Detectivo"),"Probabilidad",IF(R17="Correctivo","Impacto","")) -> Probabilidad | R17: Preventivo | S17: Manual | T17: =IF(AND(R17="Preventivo",S17="Automático"),"50%",IF(AND(R17="Preventivo",S17="Manual"),"40%",IF(AND(R17="Detectivo",S17="Automático"),"40%",IF(AND(R17="Detectivo",S17="Manual"),"30%",IF(AND(R17="Correctivo",S17="Automático"),"35%",IF(AND(R17="Correctivo",S17="Manual"),"25%","")))))) -> 40% | U17: Documentado | V17: Continua | W17: Con Registro | X17: =IFERROR(IF(Q17="Probabilidad",(I17-(+I17*T17)),IF(Q17="Impacto",I17,"")),"") -> 0 | Y17: =IFERROR(IF(X17="","",IF(X17<=0.2,"Muy Baja",IF(X17<=0.4,"Baja",IF(X17<=0.6,"Media",IF(X17<=0.8,"Alta","Muy Alta"))))),"") -> Muy Baja | Z17: =+X17 -> 0 | AA17: =IFERROR(IF(AB17="","",IF(AB17<=0.2,"Leve",IF(AB17<=0.4,"Menor",IF(AB17<=0.6,"Moderado",IF(AB17<=0.8,"Mayor","Catastrófico"))))),"") -> Moderado | AB17: =IFERROR(IF(AND(Q16="Impacto",Q17="Impacto"),(AB13-(+AB13*T17)),IF(Q17="Impacto",($M$16-(+$M$16*T17)),IF(Q17="Probabilidad",AB13,""))),"") -> 0.6 | AC17: =IFERROR(IF(OR(AND(Y17="Muy Baja",AA17="Leve"),AND(Y17="Muy Baja",AA17="Menor"),AND(Y17="Baja",AA17="Leve")),"Bajo",IF(OR(AND(Y17="Muy baja",AA17="Moderado"),AND(Y17="Baja",AA17="Menor"),AND(Y17="Baja",AA17="Moderado"),AND(Y17="Media",AA17="Leve"),AND(Y17="Media",AA17="Menor"),AND(Y17="Media",AA17="Moderado"),AND(Y17="Alta",AA17="Leve"),AND(Y17="Alta",AA17="Menor")),"Moderado",IF(OR(AND(Y17="Muy Baja",AA17="Mayor"),AND(Y17="Baja",AA17="Mayor"),AND(Y17="Media",AA17="Mayor"),AND(Y17="Alta",AA17="Moderado"),AND(Y17="Alta",AA17="Mayor"),AND(Y17="Muy Alta",AA17="Leve"),AND(Y17="Muy Alta",AA17="Menor"),AND(Y17="Muy Alta",AA17="Moderado"),AND(Y17="Muy Alta",AA17="Mayor")),"Alto",IF(OR(AND(Y17="Muy Baja",AA17="Catastrófico"),AND(Y17="Baja",AA17="Catastrófico"),AND(Y17="Media",AA17="Catastrófico"),AND(Y17="Alta",AA17="Catastrófico"),AND(Y17="Muy Alta",AA17="Catastrófico")),"Extremo","")))),"") -> Moderado | AE17: Verificar cumpliiento de requisitos minimos legales para la modalidad de contratacon que corresponda | AF17: Asesor Contratación | AG17: 45688
A18: 3 | B18: Económico y Reputacional | C18: Multa y sanciòn del ente regulador | D18: Liquidaciòn de contratos fuera de los tèrminos normativos | E18: Posibilidad de afectaciòn economica y reputacional por multa y sanciòn del ente regulador, debido a la liquidaciòn de contratos fuera de los tèrminos normativos | F18: Usuarios, productos y practicas , organizacionales | G18: 12 | H18: =IF(G18<=0,"",IF(G18<=2,"Muy Baja",IF(G18<=24,"Baja",IF(G18<=500,"Media",IF(G18<=5000,"Alta","Muy Alta"))))) -> Baja | I18: =IF(H18="","",IF(H18="Muy Baja",0.2,IF(H18="Baja",0.4,IF(H18="Media",0.6,IF(H18="Alta",0.8,IF(H18="Muy Alta",1,)))))) -> 0.4 | J18: Entre 50 y 100 SMLMV | K18: =IF(NOT(ISERROR(MATCH(J18,#REF!,0))),#REF!&"Por favor no seleccionar los criterios de impacto(Afectación Económica o presupuestal y Pérdida Reputacional)",J18) -> Entre 50 y 100 SMLMV | L18: =IF(OR(K18='[1]Tabla Impacto'!$C$11,K18='[1]Tabla Impacto'!$D$11),"Leve",IF(OR(K18='[1]Tabla Impacto'!$C$12,K18='[1]Tabla Impacto'!$D$12),"Menor",IF(OR(K18='[1]Tabla Impacto'!$C$13,K18='[1]Tabla Impacto'!$D$13),"Moderado",IF(OR(K18='[1]Tabla Impacto'!$C$14,K18='[1]Tabla Impacto'!$D$14),"Mayor",IF(OR(K18='[1]Tabla Impacto'!$C$15,K18='[1]Tabla Impacto'!$D$15),"Catastrófico",""))))) -> Moderado | M18: =IF(L18="","",IF(L18="Leve",0.2,IF(L18="Menor",0.4,IF(L18="Moderado",0.6,IF(L18="Mayor",0.8,IF(L18="Catastrófico",1,)))))) -> 0.6 | N18: =IF(OR(AND(H18="Muy Baja",L18="Leve"),AND(H18="Muy Baja",L18="Menor"),AND(H18="Baja",L18="Leve")),"Bajo",IF(OR(AND(H18="Muy baja",L18="Moderado"),AND(H18="Baja",L18="Menor"),AND(H18="Baja",L18="Moderado"),AND(H18="Media",L18="Leve"),AND(H18="Media",L18="Menor"),AND(H18="Media",L18="Moderado"),AND(H18="Alta",L18="Leve"),AND(H18="Alta",L18="Menor")),"Moderado",IF(OR(AND(H18="Muy Baja",L18="Mayor"),AND(H18="Baja",L18="Mayor"),AND(H18="Media",L18="Mayor"),AND(H18="Alta",L18="Moderado"),AND(H18="Alta",L18="Mayor"),AND(H18="Muy Alta",L18="Leve"),AND(H18="Muy Alta",L18="Menor"),AND(H18="Muy Alta",L18="Moderado"),AND(H18="Muy Alta",L18="Mayor")),"Alto",IF(OR(AND(H18="Muy Baja",L18="Catastrófico"),AND(H18="Baja",L18="Catastrófico"),AND(H18="Media",L18="Catastrófico"),AND(H18="Alta",L18="Catastrófico"),AND(H18="Muy Alta",L18="Catastrófico")),"Extremo","")))) -> Moderado | O18: 1 | P18: El Asesor de contrataciòn debera realizar segumiento permanente a los procesos que requieran liquidaciòn, con la finalidad de no superar el tèrmino previsto dentro de la Ley. | Q18: =IF(OR(R18="Preventivo",R18="Detectivo"),"Probabilidad",IF(R18="Correctivo","Impacto","")) -> Probabilidad | R18: Preventivo | S18: Manual | T18: =IF(AND(R18="Preventivo",S18="Automático"),"50%",IF(AND(R18="Preventivo",S18="Manual"),"40%",IF(AND(R18="Detectivo",S18="Automático"),"40%",IF(AND(R18="Detectivo",S18="Manual"),"30%",IF(AND(R18="Correctivo",S18="Automático"),"35%",IF(AND(R18="Correctivo",S18="Manual"),"25%","")))))) -> 40% | U18: Documentado | V18: Continua | W18: Sin Registro | X18: =IFERROR(IF(Q18="Probabilidad",(I18-(+I18*T18)),IF(Q18="Impacto",I18,"")),"") -> 0.24 | Y18: =IFERROR(IF(X18="","",IF(X18<=0.2,"Muy Baja",IF(X18<=0.4,"Baja",IF(X18<=0.6,"Media",IF(X18<=0.8,"Alta","Muy Alta"))))),"") -> Baja | Z18: =+X18 -> 0.24 | AA18: =IFERROR(IF(AB18="","",IF(AB18<=0.2,"Leve",IF(AB18<=0.4,"Menor",IF(AB18<=0.6,"Moderado",IF(AB18<=0.8,"Mayor","Catastrófico"))))),"") -> Moderado | AB18: =IFERROR(IF(Q18="Impacto",(M18-(+M18*T18)),IF(Q18="Probabilidad",M18,"")),"") -> 0.6 | AC18: =IFERROR(IF(OR(AND(Y18="Muy Baja",AA18="Leve"),AND(Y18="Muy Baja",AA18="Menor"),AND(Y18="Baja",AA18="Leve")),"Bajo",IF(OR(AND(Y18="Muy baja",AA18="Moderado"),AND(Y18="Baja",AA18="Menor"),AND(Y18="Baja",AA18="Moderado"),AND(Y18="Media",AA18="Leve"),AND(Y18="Media",AA18="Menor"),AND(Y18="Media",AA18="Moderado"),AND(Y18="Alta",AA18="Leve"),AND(Y18="Alta",AA18="Menor")),"Moderado",IF(OR(AND(Y18="Muy Baja",AA18="Mayor"),AND(Y18="Baja",AA18="Mayor"),AND(Y18="Media",AA18="Mayor"),AND(Y18="Alta",AA18="Moderado"),AND(Y18="Alta",AA18="Mayor"),AND(Y18="Muy Alta",AA18="Leve"),AND(Y18="Muy Alta",AA18="Menor"),AND(Y18="Muy Alta",AA18="Moderado"),AND(Y18="Muy Alta",AA18="Mayor")),"Alto",IF(OR(AND(Y18="Muy Baja",AA18="Catastrófico"),AND(Y18="Baja",AA18="Catastrófico"),AND(Y18="Media",AA18="Catastrófico"),AND(Y18="Alta",AA18="Catastrófico"),AND(Y18="Muy Alta",AA18="Catastrófico")),"Extremo","")))),"") -> Moderado | AD18: Reducir (mitigar) | AE18: Verificación, seguimiento y realizacón actas de liquidación de contratos | AF18: Asesor Contratación | AG18: 45688
B19: *Nota: La columna referencia se sugiere para mantener el consecutivo de riesgos, así el riesgo salga del mapa no existirá otro riesgo con el mismo número. Una entidad puede ir en el riesgo 150 pero tener 70 riesgos, lo que permite llevar una traza de los riesgos. Esta información la debe administrar la Oficina Asesora de Planeación o Gerencia de Riesgos.
B21: Fuente: Adaptado de Curso Riesgo Operativo Universidad del Rosario por Dirección de Gestión y Desempeño Institucional de Función Pública, 2020.

Sheet Matriz Calor Inherente
B2: Matriz de Calor Inherente | J2: Impacto
B6: Probabilidad | E6: Muy Alta 100% | J6: =IF(AND('Mapa final'!$H$13="Muy Alta",'Mapa final'!$L$13="Leve"),CONCATENATE("R",'Mapa final'!$A$13),"") | L6: =IF(AND('Mapa final'!#REF!="Muy Alta",'Mapa final'!#REF!="Leve"),CONCATENATE("R",'Mapa final'!#REF!),"") -> #REF! | N6: =IF(AND('Mapa final'!#REF!="Muy Alta",'Mapa final'!#REF!="Leve"),CONCATENATE("R",'Mapa final'!#REF!),"") -> #REF! | P6: =IF(AND('Mapa final'!$H$13="Muy Alta",'Mapa final'!$L$13="Menor"),CONCATENATE("R",'Mapa final'!$A$13),"") | R6: =IF(AND('Mapa final'!#REF!="Muy Alta",'Mapa final'!#REF!="Menor"),CONCATENATE("R",'Mapa final'!#REF!),"") -> #REF! | T6: =IF(AND('Mapa final'!#REF!="Muy Alta",'Mapa final'!#REF!="Menor"),CONCATENATE("R",'Mapa final'!#REF!),"") -> #REF! | V6: =IF(AND('Mapa final'!$H$13="Muy Alta",'Mapa final'!$L$13="Moderado"),CONCATENATE("R",'Mapa final'!$A$13),"") | X6: =IF(AND('Mapa final'!#REF!="Muy Alta",'Mapa final'!#REF!="Moderado"),CONCATENATE("R",'Mapa final'!#REF!),"") -> #REF! | Z6: =IF(AND('Mapa final'!#REF!="Muy Alta",'Mapa final'!#REF!="Moderado"),CONCATENATE("R",'Mapa final'!#REF!),"") -> #REF! | AB6: =IF(AND('Mapa final'!$H$13="Muy Alta",'Mapa final'!$L$13="Mayor"),CONCATENATE("R",'Mapa final'!$A$13),"") | AD6: =IF(AND('Mapa final'!#REF!="Muy Alta",'Mapa final'!#REF!="Mayor"),CONCATENATE("R",'Mapa final'!#REF!),"") -> #REF! | AF6: =IF(AND('Mapa final'!#REF!="Muy Alta",'Mapa final'!#REF!="Mayor"),CONCATENATE("R",'Mapa final'!#REF!),"") -> #REF! | AH6: =IF(AND('Mapa final'!$H$13="Muy Alta",'Mapa final'!$L$13="Catastrófico"),CONCATENATE("R",'Mapa final'!$A$13),"") | AJ6: =IF(AND('Mapa final'!#REF!="Muy Alta",'Mapa final'!#REF!="Catastrófico"),CONCATENATE("R",'Mapa final'!#REF!),"") -> #REF! | AL6: =IF(AND('Mapa final'!#REF!="Muy Alta",'Mapa final'!#REF!="Catastrófico"),CONCATENATE("R",'Mapa final'!#REF!),"") -> #REF! | AO6: Extremo
N8: =IF(AND('Mapa final'!#REF!="Muy Alta",'Mapa final'!#REF!="Leve"),CONCATENATE("R",'Mapa final'!#REF!),"") -> #REF! | P8: =IF(AND('Mapa final'!#REF!="Muy Alta",'Mapa final'!#REF!="Menor"),CONCATENATE("R",'Mapa final'!#REF!),"") -> #REF! | R8: =IF(AND('Mapa final'!#REF!="Muy Alta",'Mapa final'!#REF!="Menor"),CONCATENATE("R",'Mapa final'!#REF!),"") -> #REF! | T8: =IF(AND('Mapa final'!#REF!="Muy Alta",'Mapa final'!#REF!="Menor"),CONCATENATE("R",'Mapa final'!#REF!),"") -> #REF! | V8: =IF(AND('Mapa final'!#REF!="Muy Alta",'Mapa final'!#REF!="Moderado"),CONCATENATE("R",'Mapa final'!#REF!),"") -> #REF! | X8: =IF(AND('Mapa final'!#REF!="Muy Alta",'Mapa final'!#REF!="Moderado"),CONCATENATE("R",'Mapa final'!#REF!),"") -> #REF! | Z8: =IF(AND('Mapa final'!#REF!="Muy Alta",'Mapa final'!#REF!="Moderado"),CONCATENATE("R",'Mapa final'!#REF!),"") -> #REF! | AB8: =IF(AND('Mapa final'!#REF!="Muy Alta",'Mapa final'!#REF!="Mayor"),CONCATENATE("R",'Mapa final'!#REF!),"") -> #REF! | AD8: =IF(AND('Mapa final'!#REF!="Muy Alta",'Mapa final'!#REF!="Mayor"),CONCATENATE("R",'Mapa final'!#REF!),"") -> #REF! | AF8: =IF(AND('Mapa final'!#REF!="Muy Alta",'Mapa final'!#REF!="Mayor"),CONCATENATE("R",'Mapa final'!#REF!),"") -> #REF! | AH8: =IF(AND('Mapa final'!#REF!="Muy Alta",'Mapa final'!#REF!="Catastrófico"),CONCATENATE("R",'Mapa final'!#REF!),"") -> #REF! | AJ8: =IF(AND('Mapa final'!#REF!="Muy Alta",'Mapa final'!#REF!="Catastrófico"),CONCATENATE("R",'Mapa final'!#REF!),"") -> #REF! | AL8: =IF(AND('Mapa final'!#REF!="Muy Alta",'Mapa final'!#REF!="Catastrófico"),CONCATENATE("R",'Mapa final'!#REF!),"") -> #REF!
J10: =IF(AND('Mapa final'!#REF!="Muy Alta",'Mapa final'!#REF!="Leve"),CONCATENATE("R",'Mapa final'!#REF!),"") -> #REF! | L10: =IF(AND('Mapa final'!#REF!="Muy Alta",'Mapa final'!#REF!="Leve"),CONCATENATE("R",'Mapa final'!#REF!),"") -> #REF! | N10: =IF(AND('Mapa final'!#REF!="Muy Alta",'Mapa final'!#REF!="Leve"),CONCATENATE("R",'Mapa final'!#REF!),"") -> #REF! | P10: =IF(AND('Mapa final'!#REF!="Muy Alta",'Mapa final'!#REF!="Menor"),CONCATENATE("R",'Mapa final'!#REF!),"") -> #REF! | R10: =IF(AND('Mapa final'!#REF!="Muy Alta",'Mapa final'!#REF!="Menor"),CONCATENATE("R",'Mapa final'!#REF!),"") -> #REF! | T10: =IF(AND('Mapa final'!#REF!="Muy Alta",'Mapa final'!#REF!="Menor"),CONCATENATE("R",'Mapa final'!#REF!),"") -> #REF! | V10: =IF(AND('Mapa final'!#REF!="Muy Alta",'Mapa final'!#REF!="Moderado"),CONCATENATE("R",'Mapa final'!#REF!),"") -> #REF! | X10: =IF(AND('Mapa final'!#REF!="Muy Alta",'Mapa final'!#REF!="Moderado"),CONCATENATE("R",'Mapa final'!#REF!),"") -> #REF! | Z10: =IF(AND('Mapa final'!#REF!="Muy Alta",'Mapa final'!#REF!="Moderado"),CONCATENATE("R",'Mapa final'!#REF!),"") -> #REF! | AB10: =IF(AND('Mapa final'!#REF!="Muy Alta",'Mapa final'!#REF!="Mayor"),CONCATENATE("R",'Mapa final'!#REF!),"") -> #REF! | AD10: =IF(AND('Mapa final'!#REF!="Muy Alta",'Mapa final'!#REF!="Mayor"),CONCATENATE("R",'Mapa final'!#REF!),"") -> #REF! | AF10: =IF(AND('Mapa final'!#REF!="Muy Alta",'Mapa final'!#REF!="Mayor"),CONCATENATE("R",'Mapa final'!#REF!),"") -> #REF! | AH10: =IF(AND('Mapa final'!#REF!="Muy Alta",'Mapa final'!#REF!="Catastrófico"),CONCATENATE("R",'Mapa final'!#REF!),"") -> #REF! | AJ10: =IF(AND('Mapa final'!#REF!="Muy Alta",'Mapa final'!#REF!="Catastrófico"),CONCATENATE("R",'Mapa final'!#REF!),"") -> #REF! | AL10: =IF(AND('Mapa final'!#REF!="Muy Alta",'Mapa final'!#REF!="Catastrófico"),CONCATENATE("R",'Mapa final'!#REF!),"") -> #REF!
J12: =IF(AND('Mapa final'!#REF!="Muy Alta",'Mapa final'!#REF!="Leve"),CONCATENATE("R",'Mapa final'!#REF!),"") -> #REF! | L12: =IF(AND('Mapa final'!$H$19="Muy Alta",'Mapa final'!$L$19="Leve"),CONCATENATE("R",'Mapa final'!$A$19),"") | N12: =IF(AND('Mapa final'!$H$25="Muy Alta",'Mapa final'!$L$25="Leve"),CONCATENATE("R",'Mapa final'!$A$25),"") | P12: =IF(AND('Mapa final'!#REF!="Muy Alta",'Mapa final'!#REF!="Menor"),CONCATENATE("R",'Mapa final'!#REF!),"") -> #REF! | R12: =IF(AND('Mapa final'!$H$19="Muy Alta",'Mapa final'!$L$19="Menor"),CONCATENATE("R",'Mapa final'!$A$19),"") | T12: =IF(AND('Mapa final'!$H$25="Muy Alta",'Mapa final'!$L$25="Menor"),CONCATENATE("R",'Mapa final'!$A$25),"") | V12: =IF(AND('Mapa final'!#REF!="Muy Alta",'Mapa final'!#REF!="Moderado"),CONCATENATE("R",'Mapa final'!#REF!),"") -> #REF! | X12: =IF(AND('Mapa final'!$H$19="Muy Alta",'Mapa final'!$L$19="Moderado"),CONCATENATE("R",'Mapa final'!$A$19),"") | Z12: =IF(AND('Mapa final'!$H$25="Muy Alta",'Mapa final'!$L$25="Moderado"),CONCATENATE("R",'Mapa final'!$A$25),"") | AB12: =IF(AND('Mapa final'!#REF!="Muy Alta",'Mapa final'!#REF!="Mayor"),CONCATENATE("R",'Mapa final'!#REF!),"") -> #REF! | AD12: =IF(AND('Mapa final'!$H$19="Muy Alta",'Mapa final'!$L$19="Mayor"),CONCATENATE("R",'Mapa final'!$A$19),"") | AF12: =IF(AND('Mapa final'!$H$25="Muy Alta",'Mapa final'!$L$25="Mayor"),CONCATENATE("R",'Mapa final'!$A$25),"") | AH12: =IF(AND('Mapa final'!#REF!="Muy Alta",'Mapa final'!#REF!="Catastrófico"),CONCATENATE("R",'Mapa final'!#REF!),"") -> #REF! | AJ12: =IF(AND('Mapa final'!$H$19="Muy Alta",'Mapa final'!$L$19="Catastrófico"),CONCATENATE("R",'Mapa final'!$A$19),"") | AL12: =IF(AND('Mapa final'!$H$25="Muy Alta",'Mapa final'!$L$25="Catastrófico"),CONCATENATE("R",'Mapa final'!$A$25),"")
E14: Alta 80% | J14: =IF(AND('Mapa final'!$H$13="Alta",'Mapa final'!$L$13="Leve"),CONCATENATE("R",'Mapa final'!$A$13),"") | L14: =IF(AND('Mapa final'!#REF!="Alta",'Mapa final'!#REF!="Leve"),CONCATENATE("R",'Mapa final'!#REF!),"") -> #REF! | N14: =IF(AND('Mapa final'!#REF!="Alta",'Mapa final'!#REF!="Leve"),CONCATENATE("R",'Mapa final'!#REF!),"") -> #REF! | P14: =IF(AND('Mapa final'!$H$13="Alta",'Mapa final'!$L$13="Menor"),CONCATENATE("R",'Mapa final'!$A$13),"") | R14: =IF(AND('Mapa final'!#REF!="Alta",'Mapa final'!#REF!="Menor"),CONCATENATE("R",'Mapa final'!#REF!),"") -> #REF! | T14: =IF(AND('Mapa final'!#REF!="Alta",'Mapa final'!#REF!="Menor"),CONCATENATE("R",'Mapa final'!#REF!),"") -> #REF! | V14: =IF(AND('Mapa final'!$H$13="Alta",'Mapa final'!$L$13="Moderado"),CONCATENATE("R",'Mapa final'!$A$13),"") | X14: =IF(AND('Mapa final'!#REF!="Alta",'Mapa final'!#REF!="Moderado"),CONCATENATE("R",'Mapa final'!#REF!),"") -> #REF! | Z14: =IF(AND('Mapa final'!#REF!="Alta",'Mapa final'!#REF!="Moderado"),CONCATENATE("R",'Mapa final'!#REF!),"") -> #REF! | AB14: =IF(AND('Mapa final'!$H$13="Alta",'Mapa final'!$L$13="Mayor"),CONCATENATE("R",'Mapa final'!$A$13),"") | AD14: =IF(AND('Mapa final'!#REF!="Alta",'Mapa final'!#REF!="Mayor"),CONCATENATE("R",'Mapa final'!#REF!),"") -> #REF! | AF14: =IF(AND('Mapa final'!#REF!="Alta",'Mapa final'!#REF!="Mayor"),CONCATENATE("R",'Mapa final'!#REF!),"") -> #REF! | AH14: =IF(AND('Mapa final'!$H$13="Alta",'Mapa final'!$L$13="Catastrófico"),CONCATENATE("R",'Mapa final'!$A$13),"") | AJ14: =IF(AND('Mapa final'!#REF!="Alta",'Mapa final'!#REF!="Catastrófico"),CONCATENATE("R",'Mapa final'!#REF!),"") -> #REF! | AL14: =IF(AND('Mapa final'!#REF!="Alta",'Mapa final'!#REF!="Catastrófico"),CONCATENATE("R",'Mapa final'!#REF!),"") -> #REF! | AO14: Alto
J16: =IF(AND('Mapa final'!#REF!="Alta",'Mapa final'!#REF!="Leve"),CONCATENATE("R",'Mapa final'!#REF!),"") -> #REF! | L16: =IF(AND('Mapa final'!#REF!="Alta",'Mapa final'!#REF!="Leve"),CONCATENATE("R",'Mapa final'!#REF!),"") -> #REF! | N16: =IF(AND('Mapa final'!#REF!="Alta",'Mapa final'!#REF!="Leve"),CONCATENATE("R",'Mapa final'!#REF!),"") -> #REF! | P16: =IF(AND('Mapa final'!#REF!="Alta",'Mapa final'!#REF!="Menor"),CONCATENATE("R",'Mapa final'!#REF!),"") -> #REF! | R16: =IF(AND('Mapa final'!#REF!="Alta",'Mapa final'!#REF!="Menor"),CONCATENATE("R",'Mapa final'!#REF!),"") -> #REF! | T16: =IF(AND('Mapa final'!#REF!="Alta",'Mapa final'!#REF!="Menor"),CONCATENATE("R",'Mapa final'!#REF!),"") -> #REF! | V16: =IF(AND('Mapa final'!#REF!="Alta",'Mapa final'!#REF!="Moderado"),CONCATENATE("R",'Mapa final'!#REF!),"") -> #REF! | X16: =IF(AND('Mapa final'!#REF!="Alta",'Mapa final'!#REF!="Moderado"),CONCATENATE("R",'Mapa final'!#REF!),"") -> #REF! | Z16: =IF(AND('Mapa final'!#REF!="Alta",'Mapa final'!#REF!="Moderado"),CONCATENATE("R",'Mapa final'!#REF!),"") -> #REF! | AB16: =IF(AND('Mapa final'!#REF!="Alta",'Mapa final'!#REF!="Mayor"),CONCATENATE("R",'Mapa final'!#REF!),"") -> #REF! | AD16: =IF(AND('Mapa final'!#REF!="Alta",'Mapa final'!#REF!="Mayor"),CONCATENATE("R",'Mapa final'!#REF!),"") -> #REF! | AF16: =IF(AND('Mapa final'!#REF!="Alta",'Mapa final'!#REF!="Mayor"),CONCATENATE("R",'Mapa final'!#REF!),"") -> #REF! | AH16: =IF(AND('Mapa final'!#REF!="Alta",'Mapa final'!#REF!="Catastrófico"),CONCATENATE("R",'Mapa final'!#REF!),"") -> #REF! | AJ16: =IF(AND('Mapa final'!#REF!="Alta",'Mapa final'!#REF!="Catastrófico"),CONCATENATE("R",'Mapa final'!#REF!),"") -> #REF! | AL16: =IF(AND('Mapa final'!#REF!="Alta",'Mapa final'!#REF!="Catastrófico"),CONCATENATE("R",'Mapa final'!#REF!),"") -> #REF!
J18: =IF(AND('Mapa final'!#REF!="Alta",'Mapa final'!#REF!="Leve"),CONCATENATE("R",'Mapa final'!#REF!),"") -> #REF! | L18: =IF(AND('Mapa final'!#REF!="Alta",'Mapa final'!#REF!="Leve"),CONCATENATE("R",'Mapa final'!#REF!),"") -> #REF! | N18: =IF(AND('Mapa final'!#REF!="Alta",'Mapa final'!#REF!="Leve"),CONCATENATE("R",'Mapa final'!#REF!),"") -> #REF! | P18: =IF(AND('Mapa final'!#REF!="Alta",'Mapa final'!#REF!="Menor"),CONCATENATE("R",'Mapa final'!#REF!),"") -> #REF! | R18: =IF(AND('Mapa final'!#REF!="Alta",'Mapa final'!#REF!="Menor"),CONCATENATE("R",'Mapa final'!#REF!),"") -> #REF! | T18: =IF(AND('Mapa final'!#REF!="Alta",'Mapa final'!#REF!="Menor"),CONCATENATE("R",'Mapa final'!#REF!),"") -> #REF! | V18: =IF(AND('Mapa final'!#REF!="Alta",'Mapa final'!#REF!="Moderado"),CONCATENATE("R",'Mapa final'!#REF!),"") -> #REF! | X18: =IF(AND('Mapa final'!#REF!="Alta",'Mapa final'!#REF!="Moderado"),CONCATENATE("R",'Mapa final'!#REF!),"") -> #REF! | Z18: =IF(AND('Mapa final'!#REF!="Alta",'Mapa final'!#REF!="Moderado"),CONCATENATE("R",'Mapa final'!#REF!),"") -> #REF! | AB18: =IF(AND('Mapa final'!#REF!="Alta",'Mapa final'!#REF!="Mayor"),CONCATENATE("R",'Mapa final'!#REF!),"") -> #REF! | AD18: =IF(AND('Mapa final'!#REF!="Alta",'Mapa final'!#REF!="Mayor"),CONCATENATE("R",'Mapa final'!#REF!),"") -> #REF! | AF18: =IF(AND('Mapa final'!#REF!="Alta",'Mapa final'!#REF!="Mayor"),CONCATENATE("R",'Mapa final'!#REF!),"") -> #REF! | AH18: =IF(AND('Mapa final'!#REF!="Alta",'Mapa final'!#REF!="Catastrófico"),CONCATENATE("R",'Mapa final'!#REF!),"") -> #REF! | AJ18: =IF(AND('Mapa final'!#REF!="Alta",'Mapa final'!#REF!="Catastrófico"),CONCATENATE("R",'Mapa final'!#REF!),"") -> #REF! | AL18: =IF(AND('Mapa final'!#REF!="Alta",'Mapa final'!#REF!="Catastrófico"),CONCATENATE("R",'Mapa final'!#REF!),"") -> #REF!
J20: =IF(AND('Mapa final'!#REF!="Alta",'Mapa final'!#REF!="Leve"),CONCATENATE("R",'Mapa final'!#REF!),"") -> #REF! | L20: =IF(AND('Mapa final'!$H$19="Alta",'Mapa final'!$L$19="Leve"),CONCATENATE("R",'Mapa final'!$A$19),"") | N20: =IF(AND('Mapa final'!$H$25="Alta",'Mapa final'!$L$25="Leve"),CONCATENATE("R",'Mapa final'!$A$25),"") | P20: =IF(AND('Mapa final'!#REF!="Alta",'Mapa final'!#REF!="Menor"),CONCATENATE("R",'Mapa final'!#REF!),"") -> #REF! | R20: =IF(AND('Mapa final'!$H$19="Alta",'Mapa final'!$L$19="Menor"),CONCATENATE("R",'Mapa final'!$A$19),"") | T20: =IF(AND('Mapa final'!$H$25="Alta",'Mapa final'!$L$25="Menor"),CONCATENATE("R",'Mapa final'!$A$25),"") | V20: =IF(AND('Mapa final'!#REF!="Alta",'Mapa final'!#REF!="Moderado"),CONCATENATE("R",'Mapa final'!#REF!),"") -> #REF! | X20: =IF(AND('Mapa final'!$H$19="Alta",'Mapa final'!$L$19="Moderado"),CONCATENATE("R",'Mapa final'!$A$19),"") | Z20: =IF(AND('Mapa final'!$H$25="Alta",'Mapa final'!$L$25="Moderado"),CONCATENATE("R",'Mapa final'!$A$25),"") | AB20: =IF(AND('Mapa final'!#REF!="Alta",'Mapa final'!#REF!="Mayor"),CONCATENATE("R",'Mapa final'!#REF!),"") -> #REF! | AD20: =IF(AND('Mapa final'!$H$19="Alta",'Mapa final'!$L$19="Mayor"),CONCATENATE("R",'Mapa final'!$A$19),"") | AF20: =IF(AND('Mapa final'!$H$25="Alta",'Mapa final'!$L$25="Mayor"),CONCATENATE("R",'Mapa final'!$A$25),"") | AH20: =IF(AND('Mapa final'!#REF!="Alta",'Mapa final'!#REF!="Catastrófico"),CONCATENATE("R",'Mapa final'!#REF!),"") -> #REF! | AJ20: =IF(AND('Mapa final'!$H$19="Alta",'Mapa final'!$L$19="Catastrófico"),CONCATENATE("R",'Mapa final'!$A$19),"") | AL20: =IF(AND('Mapa final'!$H$25="Alta",'Mapa final'!$L$25="Catastrófico"),CONCATENATE("R",'Mapa final'!$A$25),"")
E22: Media 60% | J22: =IF(AND('Mapa final'!$H$13="Media",'Mapa final'!$L$13="Leve"),CONCATENATE("R",'Mapa final'!$A$13),"") | L22: =IF(AND('Mapa final'!#REF!="Media",'Mapa final'!#REF!="Leve"),CONCATENATE("R",'Mapa final'!#REF!),"") -> #REF! | N22: =IF(AND('Mapa final'!#REF!="Media",'Mapa final'!#REF!="Leve"),CONCATENATE("R",'Mapa final'!#REF!),"") -> #REF! | P22: =IF(AND('Mapa final'!$H$13="Media",'Mapa final'!$L$13="Menor"),CONCATENATE("R",'Mapa final'!$A$13),"") | R22: =IF(AND('Mapa final'!#REF!="Media",'Mapa final'!#REF!="Menor"),CONCATENATE("R",'Mapa final'!#REF!),"") -> #REF! | T22: =IF(AND('Mapa final'!#REF!="Media",'Mapa final'!#REF!="Menor"),CONCATENATE("R",'Mapa final'!#REF!),"") -> #REF! | V22: =IF(AND('Mapa final'!$H$13="Media",'Mapa final'!$L$13="Moderado"),CONCATENATE("R",'Mapa final'!$A$13),"") | X22: =IF(AND('Mapa final'!#REF!="Media",'Mapa final'!#REF!="Moderado"),CONCATENATE("R",'Mapa final'!#REF!),"") -> #REF! | Z22: =IF(AND('Mapa final'!#REF!="Media",'Mapa final'!#REF!="Moderado"),CONCATENATE("R",'Mapa final'!#REF!),"") -> #REF! | AB22: =IF(AND('Mapa final'!$H$13="Media",'Mapa final'!$L$13="Mayor"),CONCATENATE("R",'Mapa final'!$A$13),"") | AD22: =IF(AND('Mapa final'!#REF!="Media",'Mapa final'!#REF!="Mayor"),CONCATENATE("R",'Mapa final'!#REF!),"") -> #REF! | AF22: =IF(AND('Mapa final'!#REF!="Media",'Mapa final'!#REF!="Mayor"),CONCATENATE("R",'Mapa final'!#REF!),"") -> #REF! | AH22: =IF(AND('Mapa final'!$H$13="Media",'Mapa final'!$L$13="Catastrófico"),CONCATENATE("R",'Mapa final'!$A$13),"") | AJ22: =IF(AND('Mapa final'!#REF!="Media",'Mapa final'!#REF!="Catastrófico"),CONCATENATE("R",'Mapa final'!#REF!),"") -> #REF! | AL22: =IF(AND('Mapa final'!#REF!="Media",'Mapa final'!#REF!="Catastrófico"),CONCATENATE("R",'Mapa final'!#REF!),"") -> #REF! | AO22: Moderado
J24: =IF(AND('Mapa final'!#REF!="Media",'Mapa final'!#REF!="Leve"),CONCATENATE("R",'Mapa final'!#REF!),"") -> #REF! | L24: =IF(AND('Mapa final'!#REF!="Media",'Mapa final'!#REF!="Leve"),CONCATENATE("R",'Mapa final'!#REF!),"") -> #REF! | N24: =IF(AND('Mapa final'!#REF!="Media",'Mapa final'!#REF!="Leve"),CONCATENATE("R",'Mapa final'!#REF!),"") -> #REF! | P24: =IF(AND('Mapa final'!#REF!="Media",'Mapa final'!#REF!="Menor"),CONCATENATE("R",'Mapa final'!#REF!),"") -> #REF! | R24: =IF(AND('Mapa final'!#REF!="Media",'Mapa final'!#REF!="Menor"),CONCATENATE("R",'Mapa final'!#REF!),"") -> #REF! | T24: =IF(AND('Mapa final'!#REF!="Media",'Mapa final'!#REF!="Menor"),CONCATENATE("R",'Mapa final'!#REF!),"") -> #REF! | V24: =IF(AND('Mapa final'!#REF!="Media",'Mapa final'!#REF!="Moderado"),CONCATENATE("R",'Mapa final'!#REF!),"") -> #REF! | X24: =IF(AND('Mapa final'!#REF!="Media",'Mapa final'!#REF!="Moderado"),CONCATENATE("R",'Mapa final'!#REF!),"") -> #REF! | Z24: =IF(AND('Mapa final'!#REF!="Media",'Mapa final'!#REF!="Moderado"),CONCATENATE("R",'Mapa final'!#REF!),"") -> #REF! | AB24: =IF(AND('Mapa final'!#REF!="Media",'Mapa final'!#REF!="Mayor"),CONCATENATE("R",'Mapa final'!#REF!),"") -> #REF! | AD24: =IF(AND('Mapa final'!#REF!="Media",'Mapa final'!#REF!="Mayor"),CONCATENATE("R",'Mapa final'!#REF!),"") -> #REF! | AF24: =IF(AND('Mapa final'!#REF!="Media",'Mapa final'!#REF!="Mayor"),CONCATENATE("R",'Mapa final'!#REF!),"") -> #REF! | AH24: =IF(AND('Mapa final'!#REF!="Media",'Mapa final'!#REF!="Catastrófico"),CONCATENATE("R",'Mapa final'!#REF!),"") -> #REF! | AJ24: =IF(AND('Mapa final'!#REF!="Media",'Mapa final'!#REF!="Catastrófico"),CONCATENATE("R",'Mapa final'!#REF!),"") -> #REF! | AL24: =IF(AND('Mapa final'!#REF!="Media",'Mapa final'!#REF!="Catastrófico"),CONCATENATE("R",'Mapa final'!#REF!),"") -> #REF!
J26: =IF(AND('Mapa final'!#REF!="Media",'Mapa final'!#REF!="Leve"),CONCATENATE("R",'Mapa final'!#REF!),"") -> #REF! | L26: =IF(AND('Mapa final'!#REF!="Media",'Mapa final'!#REF!="Leve"),CONCATENATE("R",'Mapa final'!#REF!),"") -> #REF! | N26: =IF(AND('Mapa final'!#REF!="Media",'Mapa final'!#REF!="Leve"),CONCATENATE("R",'Mapa final'!#REF!),"") -> #REF! | P26: =IF(AND('Mapa final'!#REF!="Media",'Mapa final'!#REF!="Menor"),CONCATENATE("R",'Mapa final'!#REF!),"") -> #REF! | R26: =IF(AND('Mapa final'!#REF!="Media",'Mapa final'!#REF!="Menor"),CONCATENATE("R",'Mapa final'!#REF!),"") -> #REF! | T26: =IF(AND('Mapa final'!#REF!="Media",'Mapa final'!#REF!="Menor"),CONCATENATE("R",'Mapa final'!#REF!),"") -> #REF! | V26: =IF(AND('Mapa final'!#REF!="Media",'Mapa final'!#REF!="Moderado"),CONCATENATE("R",'Mapa final'!#REF!),"") -> #REF! | X26: =IF(AND('Mapa final'!#REF!="Media",'Mapa final'!#REF!="Moderado"),CONCATENATE("R",'Mapa final'!#REF!),"") -> #REF! | Z26: =IF(AND('Mapa final'!#REF!="Media",'Mapa final'!#REF!="Moderado"),CONCATENATE("R",'Mapa final'!#REF!),"") -> #REF! | AB26: =IF(AND('Mapa final'!#REF!="Media",'Mapa final'!#REF!="Mayor"),CONCATENATE("R",'Mapa final'!#REF!),"") -> #REF! | AD26: =IF(AND('Mapa final'!#REF!="Media",'Mapa final'!#REF!="Mayor"),CONCATENATE("R",'Mapa final'!#REF!),"") -> #REF! | AF26: =IF(AND('Mapa final'!#REF!="Media",'Mapa final'!#REF!="Mayor"),CONCATENATE("R",'Mapa final'!#REF!),"") -> #REF! | AH26: =IF(AND('Mapa final'!#REF!="Media",'Mapa final'!#REF!="Catastrófico"),CONCATENATE("R",'Mapa final'!#REF!),"") -> #REF! | AJ26: =IF(AND('Mapa final'!#REF!="Media",'Mapa final'!#REF!="Catastrófico"),CONCATENATE("R",'Mapa final'!#REF!),"") -> #REF! | AL26: =IF(AND('Mapa final'!#REF!="Media",'Mapa final'!#REF!="Catastrófico"),CONCATENATE("R",'Mapa final'!#REF!),"") -> #REF!
J28: =IF(AND('Mapa final'!#REF!="Media",'Mapa final'!#REF!="Leve"),CONCATENATE("R",'Mapa final'!#REF!),"") -> #REF! | L28: =IF(AND('Mapa final'!$H$19="Media",'Mapa final'!$L$19="Leve"),CONCATENATE("R",'Mapa final'!$A$19),"") | N28: =IF(AND('Mapa final'!$H$25="Media",'Mapa final'!$L$25="Leve"),CONCATENATE("R",'Mapa final'!$A$25),"") | P28: =IF(AND('Mapa final'!#REF!="Media",'Mapa final'!#REF!="Menor"),CONCATENATE("R",'Mapa final'!#REF!),"") -> #REF! | R28: =IF(AND('Mapa final'!$H$19="Media",'Mapa final'!$L$19="Menor"),CONCATENATE("R",'Mapa final'!$A$19),"") | T28: =IF(AND('Mapa final'!$H$25="Media",'Mapa final'!$L$25="Menor"),CONCATENATE("R",'Mapa final'!$A$25),"") | V28: =IF(AND('Mapa final'!#REF!="Media",'Mapa final'!#REF!="Moderado"),CONCATENATE("R",'Mapa final'!#REF!),"") -> #REF! | X28: =IF(AND('Mapa final'!$H$19="Media",'Mapa final'!$L$19="Moderado"),CONCATENATE("R",'Mapa final'!$A$19),"") | Z28: =IF(AND('Mapa final'!$H$25="Media",'Mapa final'!$L$25="Moderado"),CONCATENATE("R",'Mapa final'!$A$25),"") | AB28: =IF(AND('Mapa final'!#REF!="Media",'Mapa final'!#REF!="Mayor"),CONCATENATE("R",'Mapa final'!#REF!),"") -> #REF! | AD28: =IF(AND('Mapa final'!$H$19="Media",'Mapa final'!$L$19="Mayor"),CONCATENATE("R",'Mapa final'!$A$19),"") | AF28: =IF(AND('Mapa final'!$H$25="Media",'Mapa final'!$L$25="Mayor"),CONCATENATE("R",'Mapa final'!$A$25),"") | AH28: =IF(AND('Mapa final'!#REF!="Media",'Mapa final'!#REF!="Catastrófico"),CONCATENATE("R",'Mapa final'!#REF!),"") -> #REF! | AJ28: =IF(AND('Mapa final'!$H$19="Media",'Mapa final'!$L$19="Catastrófico"),CONCATENATE("R",'Mapa final'!$A$19),"") | AL28: =IF(AND('Mapa final'!$H$25="Media",'Mapa final'!$L$25="Catastrófico"),CONCATENATE("R",'Mapa final'!$A$25),"")
E30: Baja 40% | J30: =IF(AND('Mapa final'!$H$13="Baja",'Mapa final'!$L$13="Leve"),CONCATENATE("R",'Mapa final'!$A$13),"") | L30: =IF(AND('Mapa final'!#REF!="Baja",'Mapa final'!#REF!="Leve"),CONCATENATE("R",'Mapa final'!#REF!),"") -> #REF! | N30: =IF(AND('Mapa final'!#REF!="Baja",'Mapa final'!#REF!="Leve"),CONCATENATE("R",'Mapa final'!#REF!),"") -> #REF! | P30: =IF(AND('Mapa final'!$H$13="Baja",'Mapa final'!$L$13="Menor"),CONCATENATE("R",'Mapa final'!$A$13),"") | R30: =IF(AND('Mapa final'!#REF!="Baja",'Mapa final'!#REF!="Menor"),CONCATENATE("R",'Mapa final'!#REF!),"") -> #REF! | T30: =IF(AND('Mapa final'!#REF!="Baja",'Mapa final'!#REF!="Menor"),CONCATENATE("R",'Mapa final'!#REF!),"") -> #REF! | V30: =IF(AND('Mapa final'!$H$13="Baja",'Mapa final'!$L$13="Moderado"),CONCATENATE("R",'Mapa final'!$A$13),"") -> R1 | X30: =IF(AND('Mapa final'!#REF!="Baja",'Mapa final'!#REF!="Moderado"),CONCATENATE("R",'Mapa final'!#REF!),"") -> #REF! | Z30: =IF(AND('Mapa final'!#REF!="Baja",'Mapa final'!#REF!="Moderado"),CONCATENATE("R",'Mapa final'!#REF!),"") -> #REF! | AB30: =IF(AND('Mapa final'!$H$13="Baja",'Mapa final'!$L$13="Mayor"),CONCATENATE("R",'Mapa final'!$A$13),"") | AD30: =IF(AND('Mapa final'!#REF!="Baja",'Mapa final'!#REF!="Mayor"),CONCATENATE("R",'Mapa final'!#REF!),"") -> #REF! | AF30: =IF(AND('Mapa final'!#REF!="Baja",'Mapa final'!#REF!="Mayor"),CONCATENATE("R",'Mapa final'!#REF!),"") -> #REF! | AH30: =IF(AND('Mapa final'!$H$13="Baja",'Mapa final'!$L$13="Catastrófico"),CONCATENATE("R",'Mapa final'!$A$13),"") | AJ30: =IF(AND('Mapa final'!#REF!="Baja",'Mapa final'!#REF!="Catastrófico"),CONCATENATE("R",'Mapa final'!#REF!),"") -> #REF! | AL30: =IF(AND('Mapa final'!#REF!="Baja",'Mapa final'!#REF!="Catastrófico"),CONCATENATE("R",'Mapa final'!#REF!),"") -> #REF! | AO30: Bajo
J32: =IF(AND('Mapa final'!#REF!="Baja",'Mapa final'!#REF!="Leve"),CONCATENATE("R",'Mapa final'!#REF!),"") -> #REF! | L32: =IF(AND('Mapa final'!#REF!="Baja",'Mapa final'!#REF!="Leve"),CONCATENATE("R",'Mapa final'!#REF!),"") -> #REF! | N32: =IF(AND('Mapa final'!#REF!="Baja",'Mapa final'!#REF!="Leve"),CONCATENATE("R",'Mapa final'!#REF!),"") -> #REF! | P32: =IF(AND('Mapa final'!#REF!="Baja",'Mapa final'!#REF!="Menor"),CONCATENATE("R",'Mapa final'!#REF!),"") -> #REF! | R32: =IF(AND('Mapa final'!#REF!="Baja",'Mapa final'!#REF!="Menor"),CONCATENATE("R",'Mapa final'!#REF!),"") -> #REF! | T32: =IF(AND('Mapa final'!#REF!="Baja",'Mapa final'!#REF!="Menor"),CONCATENATE("R",'Mapa final'!#REF!),"") -> #REF! | V32: =IF(AND('Mapa final'!#REF!="Baja",'Mapa final'!#REF!="Moderado"),CONCATENATE("R",'Mapa final'!#REF!),"") -> #REF! | X32: =IF(AND('Mapa final'!#REF!="Baja",'Mapa final'!#REF!="Moderado"),CONCATENATE("R",'Mapa final'!#REF!),"") -> #REF! | Z32: =IF(AND('Mapa final'!#REF!="Baja",'Mapa final'!#REF!="Moderado"),CONCATENATE("R",'Mapa final'!#REF!),"") -> #REF! | AB32: =IF(AND('Mapa final'!#REF!="Baja",'Mapa final'!#REF!="Mayor"),CONCATENATE("R",'Mapa final'!#REF!),"") -> #REF! | AD32: =IF(AND('Mapa final'!#REF!="Baja",'Mapa final'!#REF!="Mayor"),CONCATENATE("R",'Mapa final'!#REF!),"") -> #REF! | AF32: =IF(AND('Mapa final'!#REF!="Baja",'Mapa final'!#REF!="Mayor"),CONCATENATE("R",'Mapa final'!#REF!),"") -> #REF! | AH32: =IF(AND('Mapa final'!#REF!="Baja",'Mapa final'!#REF!="Catastrófico"),CONCATENATE("R",'Mapa final'!#REF!),"") -> #REF! | AJ32: =IF(AND('Mapa final'!#REF!="Baja",'Mapa final'!#REF!="Catastrófico"),CONCATENATE("R",'Mapa final'!#REF!),"") -> #REF! | AL32: =IF(AND('Mapa final'!#REF!="Baja",'Mapa final'!#REF!="Catastrófico"),CONCATENATE("R",'Mapa final'!#REF!),"") -> #REF!
J34: =IF(AND('Mapa final'!#REF!="Baja",'Mapa final'!#REF!="Leve"),CONCATENATE("R",'Mapa final'!#REF!),"") -> #REF! | L34: =IF(AND('Mapa final'!#REF!="Baja",'Mapa final'!#REF!="Leve"),CONCATENATE("R",'Mapa final'!#REF!),"") -> #REF! | N34: =IF(AND('Mapa final'!#REF!="Baja",'Mapa final'!#REF!="Leve"),CONCATENATE("R",'Mapa final'!#REF!),"") -> #REF! | P34: =IF(AND('Mapa final'!#REF!="Baja",'Mapa final'!#REF!="Menor"),CONCATENATE("R",'Mapa final'!#REF!),"") -> #REF! | R34: =IF(AND('Mapa final'!#REF!="Baja",'Mapa final'!#REF!="Menor"),CONCATENATE("R",'Mapa final'!#REF!),"") -> #REF! | T34: =IF(AND('Mapa final'!#REF!="Baja",'Mapa final'!#REF!="Menor"),CONCATENATE("R",'Mapa final'!#REF!),"") -> #REF! | V34: =IF(AND('Mapa final'!#REF!="Baja",'Mapa final'!#REF!="Moderado"),CONCATENATE("R",'Mapa final'!#REF!),"") -> #REF! | X34: =IF(AND('Mapa final'!#REF!="Baja",'Mapa final'!#REF!="Moderado"),CONCATENATE("R",'Mapa final'!#REF!),"") -> #REF! | Z34: =IF(AND('Mapa final'!#REF!="Baja",'Mapa final'!#REF!="Moderado"),CONCATENATE("R",'Mapa final'!#REF!),"") -> #REF! | AB34: =IF(AND('Mapa final'!#REF!="Baja",'Mapa final'!#REF!="Mayor"),CONCATENATE("R",'Mapa final'!#REF!),"") -> #REF! | AD34: =IF(AND('Mapa final'!#REF!="Baja",'Mapa final'!#REF!="Mayor"),CONCATENATE("R",'Mapa final'!#REF!),"") -> #REF! | AF34: =IF(AND('Mapa final'!#REF!="Baja",'Mapa final'!#REF!="Mayor"),CONCATENATE("R",'Mapa final'!#REF!),"") -> #REF! | AH34: =IF(AND('Mapa final'!#REF!="Baja",'Mapa final'!#REF!="Catastrófico"),CONCATENATE("R",'Mapa final'!#REF!),"") -> #REF! | AJ34: =IF(AND('Mapa final'!#REF!="Baja",'Mapa final'!#REF!="Catastrófico"),CONCATENATE("R",'Mapa final'!#REF!),"") -> #REF! | AL34: =IF(AND('Mapa final'!#REF!="Baja",'Mapa final'!#REF!="Catastrófico"),CONCATENATE("R",'Mapa final'!#REF!),"") -> #REF!
J36: =IF(AND('Mapa final'!#REF!="Baja",'Mapa final'!#REF!="Leve"),CONCATENATE("R",'Mapa final'!#REF!),"") -> #REF! | L36: =IF(AND('Mapa final'!$H$19="Baja",'Mapa final'!$L$19="Leve"),CONCATENATE("R",'Mapa final'!$A$19),"") | N36: =IF(AND('Mapa final'!$H$25="Baja",'Mapa final'!$L$25="Leve"),CONCATENATE("R",'Mapa final'!$A$25),"") | P36: =IF(AND('Mapa final'!#REF!="Baja",'Mapa final'!#REF!="Menor"),CONCATENATE("R",'Mapa final'!#REF!),"") -> #REF! | R36: =IF(AND('Mapa final'!$H$19="Baja",'Mapa final'!$L$19="Menor"),CONCATENATE("R",'Mapa final'!$A$19),"") | T36: =IF(AND('Mapa final'!$H$25="Baja",'Mapa final'!$L$25="Menor"),CONCATENATE("R",'Mapa final'!$A$25),"") | V36: =IF(AND('Mapa final'!#REF!="Baja",'Mapa final'!#REF!="Moderado"),CONCATENATE("R",'Mapa final'!#REF!),"") -> #REF! | X36: =IF(AND('Mapa final'!$H$19="Baja",'Mapa final'!$L$19="Moderado"),CONCATENATE("R",'Mapa final'!$A$19),"") | Z36: =IF(AND('Mapa final'!$H$25="Baja",'Mapa final'!$L$25="Moderado"),CONCATENATE("R",'Mapa final'!$A$25),"") | AB36: =IF(AND('Mapa final'!#REF!="Baja",'Mapa final'!#REF!="Mayor"),CONCATENATE("R",'Mapa final'!#REF!),"") -> #REF! | AD36: =IF(AND('Mapa final'!$H$19="Baja",'Mapa final'!$L$19="Mayor"),CONCATENATE("R",'Mapa final'!$A$19),"") | AF36: =IF(AND('Mapa final'!$H$25="Baja",'Mapa final'!$L$25="Mayor"),CONCATENATE("R",'Mapa final'!$A$25),"") | AH36: =IF(AND('Mapa final'!#REF!="Baja",'Mapa final'!#REF!="Catastrófico"),CONCATENATE("R",'Mapa final'!#REF!),"") -> #REF! | AJ36: =IF(AND('Mapa final'!$H$19="Baja",'Mapa final'!$L$19="Catastrófico"),CONCATENATE("R",'Mapa final'!$A$19),"") | AL36: =IF(AND('Mapa final'!$H$25="Baja",'Mapa final'!$L$25="Catastrófico"),CONCATENATE("R",'Mapa final'!$A$25),"")
E38: Muy Baja 20% | J38: =IF(AND('Mapa final'!$H$13="Muy Baja",'Mapa final'!$L$13="Leve"),CONCATENATE("R",'Mapa final'!$A$13),"") | L38: =IF(AND('Mapa final'!#REF!="Muy Baja",'Mapa final'!#REF!="Leve"),CONCATENATE("R",'Mapa final'!#REF!),"") -> #REF! | N38: =IF(AND('Mapa final'!#REF!="Muy Baja",'Mapa final'!#REF!="Leve"),CONCATENATE("R",'Mapa final'!#REF!),"") -> #REF! | P38: =IF(AND('Mapa final'!$H$13="Muy Baja",'Mapa final'!$L$13="Menor"),CONCATENATE("R",'Mapa final'!$A$13),"") | R38: =IF(AND('Mapa final'!#REF!="Muy Baja",'Mapa final'!#REF!="Menor"),CONCATENATE("R",'Mapa final'!#REF!),"") -> #REF! | T38: =IF(AND('Mapa final'!#REF!="Muy Baja",'Mapa final'!#REF!="Menor"),CONCATENATE("R",'Mapa final'!#REF!),"") -> #REF! | V38: =IF(AND('Mapa final'!$H$13="Muy Baja",'Mapa final'!$L$13="Moderado"),CONCATENATE("R",'Mapa final'!$A$13),"") | X38: =IF(AND('Mapa final'!#REF!="Muy Baja",'Mapa final'!#REF!="Moderado"),CONCATENATE("R",'Mapa final'!#REF!),"") -> #REF! | Z38: =IF(AND('Mapa final'!#REF!="Muy Baja",'Mapa final'!#REF!="Moderado"),CONCATENATE("R",'Mapa final'!#REF!),"") -> #REF! | AB38: =IF(AND('Mapa final'!$H$13="Muy Baja",'Mapa final'!$L$13="Mayor"),CONCATENATE("R",'Mapa final'!$A$13),"") | AD38: =IF(AND('Mapa final'!#REF!="Muy Baja",'Mapa final'!#REF!="Mayor"),CONCATENATE("R",'Mapa final'!#REF!),"") -> #REF! | AF38: =IF(AND('Mapa final'!#REF!="Muy Baja",'Mapa final'!#REF!="Mayor"),CONCATENATE("R",'Mapa final'!#REF!),"") -> #REF! | AH38: =IF(AND('Mapa final'!$H$13="Muy Baja",'Mapa final'!$L$13="Catastrófico"),CONCATENATE("R",'Mapa final'!$A$13),"") | AJ38: =IF(AND('Mapa final'!#REF!="Muy Baja",'Mapa final'!#REF!="Catastrófico"),CONCATENATE("R",'Mapa final'!#REF!),"") -> #REF! | AL38: =IF(AND('Mapa final'!#REF!="Muy Baja",'Mapa final'!#REF!="Catastrófico"),CONCATENATE("R",'Mapa final'!#REF!),"") -> #REF!
