Workbook
Name __ric1: #REF!
Name __ric2: #REF!
Name __ric3: #REF!
Name _ric1: #REF!
Name _ric2: #REF!
Name _ric3: #REF!
Name Afeb: [1]Resumen!$D$30
Name Ajul: [2]Resumen!$I$31
Name CLASE: #REF!
Name CLASEFICAZ: #REF!
Name CLASERFICAZ: #REF!
Name DESEMPEÑO: [3]listas!#REF!
Name DESEMPEÑO: [3]listas!#REF!
Name DESEMPEÑO: [3]listas!#REF!
Name DESEMPEÑO: [4]listas!#REF!
Name Efectividad: [3]listas!$O$4:$O$12
Name Efectividad: [3]listas!$O$4:$O$12
Name Efectividad: [3]listas!$O$4:$O$12
Name Efectividad: [4]listas!$O$4:$O$12
Name Eficacia: [3]listas!$M$4:$M$16
Name Eficacia: [3]listas!$M$4:$M$16
Name Eficacia: [3]listas!$M$4:$M$16
Name Eficacia: [4]listas!$M$4:$M$16
Name Eficiencia: [3]listas!$N$4:$N$21
Name Eficiencia: [3]listas!$N$4:$N$21
Name Eficiencia: [3]listas!$N$4:$N$21
Name Eficiencia: [4]listas!$N$4:$N$21
Name Formato: [5]Indicadores!#REF!
Name lista: [3]listas!$L$26:$L$28
Name lista: [3]listas!$L$26:$L$28
Name lista: [3]listas!$L$26:$L$28
Name lista: [4]listas!#REF!
Name mm: #REF!
Name NIVEL: [4]listas!$L$25:$L$27
Name njh: #REF!
Name Objetivo: 'despliegue politica y obj'!$B$8:$B$19
Name OBJETIVOS: Hoja3!$A$3:$A$13
Name objetivoscalidad: Hoja3!$A$4:$A$13
Name Procesos: [3]listas!$K$4:$K$27
Name Procesos: [3]listas!$K$4:$K$27
Name Procesos: [3]listas!$K$4:$K$27
Name Procesos: [4]listas!$K$4:$K$27
Name Sector: [3]listas!$L$4:$L$10
Name Sector: [3]listas!$L$4:$L$10
Name Sector: [3]listas!$L$4:$L$10
Name TEMA: [3]listas!$L$3:$L$23
Name TEMA: [3]listas!$L$3:$L$23
Name TEMA: [3]listas!$L$3:$L$23
Name TEMA: [4]listas!$L$3:$L$23
Name Tfeb: [1]Resumen!$D$29
Name TIPO: [3]listas!$M$25
Name TIPO: [3]listas!$M$25
Name TIPO: [3]listas!$M$25
Name TIPO: [4]listas!$M$25:$M$27
Name Tjul: [2]Resumen!$I$30

Sheet despliegue politica y obj
A8: DIRECTRIZ DE POLITICA | B8: OBJETIVO DE CALIDAD | C8: PROCESO | D8: INDICADOR | E8: RESPONSABLE
A9: Prestamos un excelente servicio en el suministro de materiales y equipos para uso en laboratorio | B9: Verificar que los requisitos del cliente se cumplan. | C9: Comercial | D9: % satisfacción de los clientes | E9: Asistente de Ventas
B10: Aumentar la satisfacción de nuestros clientes | C10: Servicio al Cliente
B11: Dar solución rápida y eficaz a las quejas y reclamos de nuestros clientes | C11: Servicio al Cliente | D11: % Cumplimiento tiempo de respuesta quejas y reclamos | E11: Asistente de Ventas
A12: Asesoria Especializada | B12: Asesorar a nuestros clientes en forma eficaz | C12: Comercial | D12: =+Bateria!#REF! -> #REF! | E12: Asesor Comercial
A13: Productos de calidad | B13: Ofrecer materiales y equipos de calidad y de marcas reconocidas | C13: Despachos | D13: =+Bateria!#REF! -> #REF! | E13: Almacenista
C14: Compras y Almacen | D14: =+Bateria!#REF! -> #REF! | E14: Asistente de Inventarios
A15: Entregas Oportunas | B15: Cumplir con los tiempos de entrega especificados en las cotizaciones | C15: Despachos | D15: =+Bateria!#REF! -> #REF! | E15: Asistente de Inventarios
A16: Disribuciones Autorizadas | B16: Contar con el respaldo de proveedores reconocidos en el mercado | C16: Compras y Almacen | D16: Resultado Evaluación de Proveedores | E16: Asistente de Inventarios
A17: Sistema de gestiòn de calidad para la mejora continua | B17: Verificar la conformidad y eficacia del SGC | C17: Auditorias Internas de calidad | D17: Seguimiento al programa de auditorias | E17: Director de Calidad
C18: Gestión Gerencial | D18: Eficacia del sistema de gestión decalidad | E18: Director de Calidad
B19: Generar acciones que permitan mejorar continuamente el SGC | C19: Acciones de Mejora | D19: Balance de Acciones de Mejora | E19: Director de Calidad

Sheet Bateria
D1: SISTEMA DE GESTIÓN DE CALIDAD
D3: DIRECCIONAMIENTO ESTRATÉGICO
D4: BATERIA DE INDICADORES
D5: VERSIÓN: 02 | G5: FECHA: 07-05-2025 | K5: Página 1 de 1
J7: CONDICIÓN | N7: RESULTADO | Z7: RESULTADO | AA7: % CUMPLIMIENTO
A8: OBJETIVO DE CALIDAD | B8: PROCESO | C8: OBJETIVO DEL PROCESO | D8: NOMBRE INDICADOR | E8: FORMULA | F8: ORIGEN DE DATOS | G8: FRECUENCIA | H8: TIPO | I8: RESPONSABLE | J8: META | K8: CRITICA | L8: NORMAL | M8: SATISFACTORIA | N8: ENE | O8: FEB | P8: MAR | Q8: ABR | R8: MAY | S8: JUN | T8: JUL | U8: AGO | V8: SEP | W8: OCT | X8: NOV | Y8: DIC
A9: Generar acciones que permitan mejorar continuamente el SGC | B9: Gestión de Tecnologías de la Información | C9: =+'Indicador 1'!E8 -> Administrar, planificar, gestionar y evaluar los recursos de infraestructura tecnológica de la información y comunicación, asegurando la disponibilidad y optimización de los servicios tecnológicos mediante planes, programas y proyectos orientados al cumplimiento de la misionalidad del Concejo Municipal de Chía. | D9: =+'Indicador 1'!B11 -> Cumplimiento de mantenimientos preventivos y correctivos a equipos de computo | E9: =+'Indicador 1'!B19 -> (N° de mantenimientos ejecutados en el periodo / N° de mantenimientos programados en el periodo)*100 | F9: =+'Indicador 1'!H24 -> Consolidado de la ejecución de mantenimientos preventivos y correctivos programados 2025 | G9: =+'Indicador 1'!H33 -> SEMESTRAL | H9: =+'Indicador 1'!L11 -> EFICACIA | I9: =+'Indicador 1'!H27 -> Contratista TI | J9: 0.95 | K9: <90% | L9: 91%-95% | M9: >95% | S9: =+'Indicador 1'!C39 -> 1 | Y9: =+'Indicador 1'!D39 -> 0 | Z9: =AVERAGE(P9:Y9) -> 0.5 | AA9: =+Z9/J9 -> 0.52631579
B10: Gestión de Tecnologías de la Información | C10: =+'Indicador 2'!$E$8 -> Administrar, planificar, gestionar y evaluar los recursos de infraestructura tecnológica de la información y comunicación, asegurando la disponibilidad y optimización de los servicios tecnológicos mediante planes, programas y proyectos orientados al cumplimiento de la misionalidad del Concejo Municipal de Chía. | D10: =+'Indicador 2'!$B$12 -> Incidencias TIC gestionadas Oportunamente | E10: =+'Indicador 2'!$B$20 -> (N° solicitudes de servicios tecnológicos gestionadas oportunamente en el periódio / N° de solicitudes de servicios tecnológicos reportadas en el periodo)*100 | F10: =+'Indicador 2'!$H$25 -> Correo electronico | G10: =+'Indicador 2'!$H$34 -> Mensual - Indicador Trimestral | H10: =+'Indicador 2'!$L$12 -> EFICACIA | I10: =+'Indicador 2'!$H$28 -> Contratista TI | J10: 0.95 | K10: <90% | L10: 91-98% | M10: >98% | N10: =+'Indicador 2'!C40 -> 1 | O10: =+'Indicador 2'!D40 -> 1 | P10: =+'Indicador 2'!E40 -> 0 | Q10: =+'Indicador 2'!F40 -> 0 | R10: =+'Indicador 2'!G40 -> 0 | S10: =+'Indicador 2'!H40 -> 0 | T10: =+'Indicador 2'!I40 -> 0 | U10: =+'Indicador 2'!J40 -> 0 | W10: =+'Indicador 2'!L40 -> 0 | X10: =+'Indicador 2'!M40 -> 0 | Y10: =+'Indicador 2'!N40 -> 0 | Z10: =+AVERAGE(N10:Y10) -> 0.18181818 | AA10: =+IF(Z10<=90%,0%,IF(AND(Z10>90%,Z10<=98%),Z10/J10,100%)) -> 0
A11: OBJETIVOS DE CALIDAD | B11: =+'Indicador 3'!E7 -> Gestión Documental y de Tecnologías de la Información | C11: =+'Indicador 3'!E8 -> Administrar, planificar, gestionar y evaluar los recursos de infraestructura tecnológica de la información y comunicación, asegurando la disponibilidad y optimización de los servicios tecnológicos mediante planes, programas y proyectos orientados al cumplimiento de la misionalidad del Concejo Municipal de Chía. | D11: =+'Indicador 3'!B12 -> Cumplimiento de la ejecución del PETI | E11: =+'Indicador 3'!B20 -> (N° de Iniciativas ejecutadas de manera satisfactoria en el periodo / N° de iniciativas planeadas a ejecutar en el periodo)*100 | F11: =+'Indicador 3'!H25 -> Plan Estratégico de Tecnologias de la Información - PETI. | G11: =+'Indicador 3'!H34 -> Semestral | H11: =+'Indicador 3'!L12 -> EFICACIA | I11: =+'Indicador 3'!H28 -> Contratista TI | J11: =+'Indicador 3'!B31 -> 0.9 | K11: =+'Indicador 3'!E32 -> <90% | L11: =+'Indicador 3'!H32 -> 90% - 95% | M11: =+'Indicador 3'!L32 -> >95% | P11: =+'Indicador 3'!C40 -> 1 | S11: =+'Indicador 3'!D40 -> 0 | V11: =+'Indicador 3'!E40 -> 0 | Y11: =+'Indicador 3'!F40 -> 0 | Z11: =+S11 -> 0 | AA11: =+J11 -> 0.9
A12: Asesorar a nuestros clientes en forma eficaz | Z12: EFICACIA PROCESO | AA12: =AVERAGE(AA9:AA11) -> 0.4754386
A13: Ofrecer materiales y equipos de calidad y de marcas reconocidas
A14: Cumplir con los tiempos de entrega especificados en las cotizaciones
A15: Contar con el respaldo de proveedores reconocidos en el mercado
A16: Verificar la conformidad y eficacia del SGC
A18: Generar acciones que permitan mejorar continuamente el SGC

Sheet Indicador 1
C2: SISTEMA DE GESTIÓN DE CALIDAD
C3: DIRECCIONAMIENTO ESTRATÉGICO
C4: FICHA TÉCNICA DEL INDICADOR
C5: VERSIÓN: 03 | G5: FECHA: 07-05-2025 | K5: Página 1 de 1
B7: PROCESO | E7: Gestión Documental y de Tecnologias de la Información
B8: OBJETIVO DEL PROCESO | E8: Administrar, planificar, gestionar y evaluar los recursos de infraestructura tecnológica de la información y comunicación, asegurando la disponibilidad y optimización de los servicios tecnológicos mediante planes, programas y proyectos orientados al cumplimiento de la misionalidad del Concejo Municipal de Chía.
B10: NOMBRE DEL INDICADOR | L10: TIPO INDICADOR
B11: Cumplimiento de mantenimientos preventivos y correctivos a equipos de computo | L11: EFICACIA
B17: FÓRMULA
B19: (N° de mantenimientos ejecutados en el periodo / N° de mantenimientos programados en el periodo)*100
B23: DATOS REQUERIDOS PARA EL CALCULO | H23: ORIGEN DE LOS DATOS
B24: A.N° de mantenimientos preventivos ejecutados en el periodo. B. N° de mantenimientos preventivos programados. | H24: Consolidado de la ejecución de mantenimientos preventivos y correctivos programados 2025
B26: RESPONSABLE DE LA RECOPILACIÓN DE DATOS | H26: RESPONSABLE DEL ANÁLISIS
B27: Contratista TI | H27: Contratista TI
B29: META ESTABLECIDA | E29: CRITERIO DE ANALISIS
B30: =+Bateria!J9 -> 0.95 | E30: CONDICIÓN CRITICA | H30: CONDICIÓN NORMAL | L30: CONDICIÓN SATISFACTORIA
E31: <90% | H31: 91%-95% | L31: >95%
B32: UNIDAD DE MEDIDA | H32: FRECUENCIA DE MEDICIÓN
B33: Porcentaje | H33: SEMESTRAL
B35: HISTÓRICO
B36: PERIODO | C36: I SEMESTRE | D36: II SEMESTRE
B37: Cond.Satisfactoria
B38: Cond. Crítica
B39: Resultado | C39: 1
B40: TENDENCIA
B41: TECNICA ESTADISTICA APLICADA
B68: TRIMESTRE | C68: N° de mantenimiento ejecutado | D68: N° de Mantenimientos planificados | E68: % de Cumplimiento
B69: I SEMESTRE | C69: 30 | D69: 30 | E69: =+C69/D69 -> 1
B71: II SEMESTRE
B73: TOTAL | C73: =SUM(C69:C72) -> 30 | D73: =SUM(D69:D72) -> 30 | E73: =+C73/D73 -> 1
B90: ANALISIS DE INDICADORES
B92: PERIODO | C92: ANALISIS | H92: PLAN DE ACCION
B93: I SEMESTRE | C93: Como se observa en el grafico,se realizaron 30 mantenimientos preventivos de los 30 que estaban programados para el primer semestre, obteniendo un resultado satisfactorio. Por tal motivo se logro el cumplimiento de la meta prevista para este periodo.
H94: fecha | J94: Actividad | M94: Responsable
H103: SOLICITUD | J103: Acción Correctiva
C105: Realizado por: | E105: LINA ALARCON
C107: Fecha: | E107: 45840 | I107: Oportunidad de Mejora
B109: PERIODO | C109: ANALISIS | H109: PLAN DE ACCION
B110: II SEMESTRE
H111: fecha | J111: Actividad | M111: Responsable
...

Sheet Hoja3
A3: OBJETIVOS DE CALIDAD
A4: Verificar que los requisitos del cliente se cumplan.
A5: Aumentar la satisfacción de nuestros clientes
A6: Dar solución rápida y eficaz a las quejas y reclamos de nuestros clientes
A7: Asesorar a nuestros clientes en forma eficaz
A8: Ofrecer materiales y equipos de calidad y de marcas reconocidas
A9: Cumplir con los tiempos de entrega especificados en las cotizaciones
A10: Contar con el respaldo de proveedores reconocidos en el mercado
A11: Verificar la conformidad y eficacia del SGC
A13: Generar acciones que permitan mejorar continuamente el SGC

Sheet Indicador 2
C2: SISTEMA DE GESTIÓN DE CALIDAD
C3: DIRECCIONAMIENTO ESTRATÉGICO
C4: FICHA TÉCNICA DEL INDICADOR
C5: VERSIÓN: 03 | G5: FECHA: 7-05-2025 | K5: Página 1 de 1
B7: PROCESO | E7: Gestión Documental y de Tecnologías de la Información
B8: OBJETIVO DEL PROCESO | E8: Administrar, planificar, gestionar y evaluar los recursos de infraestructura tecnológica de la información y comunicación, asegurando la disponibilidad y optimización de los servicios tecnológicos mediante planes, programas y proyectos orientados al cumplimiento de la misionalidad del Concejo Municipal de Chía.
B11: NOMBRE DEL INDICADOR | L11: TIPO INDICADOR
B12: Incidencias TIC gestionadas Oportunamente | L12: EFICACIA
B18: FÓRMULA
B20: (N° solicitudes de servicios tecnológicos gestionadas oportunamente en el periódio / N° de solicitudes de servicios tecnológicos reportadas en el periodo)*100
B24: DATOS REQUERIDOS PARA EL CALCULO | H24: ORIGEN DE LOS DATOS
B25: A. N° solicitudes de servicios tecnológicos gestionadas oportunamente del periódico. B. N° de solicitudes de servicios tecnológicos reportadas en el periodo | H25: Correo electronico
B27: RESPONSABLE DE LA RECOPILACIÓN DE DATOS | H27: RESPONSABLE DEL ANÁLISIS
B28: Contratista TIC | H28: Contratista TI
B30: META ESTABLECIDA | E30: CRITERIO DE ANALISIS
B31: 0.92 | E31: CONDICIÓN CRITICA | H31: CONDICIÓN NORMAL | L31: CONDICIÓN SATISFACTORIA
E32: <90% | H32: 91%-98% | L32: >98%
B33: UNIDAD DE MEDIDA | H33: FRECUENCIA DE MEDICIÓN
B34: Porcentaje | H34: Mensual - Indicador Trimestral
B36: HISTÓRICO
B37: PERIODO | C37: I CUATRIMESTRE | D37: IICUATRIMESTRE | E37: III CUATRIMESTRE
B38: Cond.Satisfactoria
B39: Cond. Crítica
B40: Resultado | C40: 1 | D40: 1
B41: TENDENCIA
B42: TECNICA ESTADISTICA APLICADA
B66: TRIMESTRE | C66: N° de Incidencias gestionadas oportunamente | D66: N° de Incidencias reportadas | E66: % de Cumplimiento
B67: Enero | C67: 0 | D67: 0 | E67: 1
B68: Feb | C68: 26 | D68: 26 | E68: 1
B69: Mar | C69: 10 | D69: 10 | E69: 1
B70: Abr | C70: 13 | D70: 13 | E70: 1
B71: May | C71: 11 | D71: 11 | E71: 1
B72: Jun | C72: 14 | D72: 14 | E72: 1
B73: Jul | C73: 12 | D73: 12 | E73: 1
B74: Ago | C74: 13 | D74: 13 | E74: 1
B75: Sep
B76: Oct
B77: Nov
B78: Dic
B79: TOTAL | C79: =SUM(C67:C78) -> 99 | D79: =SUM(D67:D78) -> 99 | E79: =+C79/D79 -> 1
...

Sheet Indicador 3
C2: SISTEMA DE GESTIÓN DE CALIDAD
C3: DIRECCIONAMIENTO ESTRATÉGICO
C4: FICHA TÉCNICA DEL INDICADOR
C5: VERSIÓN: 03 | G5: FECHA: 07-05-2025 | K5: Página 1 de 1
B7: PROCESO | E7: Gestión Documental y de Tecnologías de la Información
B8: OBJETIVO DEL PROCESO | E8: Administrar, planificar, gestionar y evaluar los recursos de infraestructura tecnológica de la información y comunicación, asegurando la disponibilidad y optimización de los servicios tecnológicos mediante planes, programas y proyectos orientados al cumplimiento de la misionalidad del Concejo Municipal de Chía.
B11: NOMBRE DEL INDICADOR | L11: TIPO INDICADOR
B12: Cumplimiento de la ejecución del PETI | L12: EFICACIA
B18: FÓRMULA
B20: (N° de Iniciativas ejecutadas de manera satisfactoria en el periodo / N° de iniciativas planeadas a ejecutar en el periodo)*100
B24: DATOS REQUERIDOS PARA EL CALCULO | H24: ORIGEN DE LOS DATOS
B25: * N° IniciativasEjecutadas = Número de iniciativas ejecutadas de manera satisfactoria en el periodo y que corresponden al periodo de medición según lo planeado. *N° IniciativasPlaneadas = Número total de iniciativas planeadas a ejecutar en el periodo. | H25: Plan Estratégico de Tecnologias de la Información - PETI.
B27: RESPONSABLE DE LA RECOPILACIÓN DE DATOS | H27: RESPONSABLE DEL ANÁLISIS
B28: Contratista TI | H28: Contratista TI
B30: META ESTABLECIDA | E30: CRITERIO DE ANALISIS
B31: 0.9 | E31: CONDICIÓN CRITICA | H31: CONDICIÓN NORMAL | L31: CONDICIÓN SATISFACTORIA
E32: <90% | H32: 90% - 95% | L32: >95%
B33: UNIDAD DE MEDIDA | H33: FRECUENCIA DE MEDICIÓN
B34: Porcentaje | H34: Semestral
B36: HISTÓRICO
B37: PERIODO | C37: I SEM | D37: II SEM
B38: Cond.Satisfactoria
B39: Cond. Crítica
B40: Resultado | C40: 1
B41: TENDENCIA
B42: TECNICA ESTADISTICA APLICADA
B66: TRIMESTRE | C66: N° de Iniciativas ejecutadas | D66: N° de iniciativas planeadas | E66: % de Cumplimiento
B67: I SEM | C67: 8 | D67: 8 | E67: =+C67/D67 -> 1
B68: II SEM
B69: TOTAL | C69: =SUM(C67:C68) -> 8 | D69: =SUM(D67:D68) -> 8 | E69: =+C69/D69 -> 1
B81: ANALISIS DE INDICADORES
B83: PERIODO | C83: ANALISIS | H83: PLAN DE ACCION
B84: I SEMESTRE
C85: En el primer semestre se establecieron 8 actividades en el plan PETI de las cuales se ejecutaron en su totalidad, logrando un cumplimiento del 100%, evidencia un resultado positivo en las metas planeadas | H85: fecha | J85: Actividad | M85: Responsable
H94: SOLICITUD | J94: Acción Correctiva
C96: Realizado por: | E96: LINA ALARCON
C98: Fecha: | E98: 45840 | I98: Oportunidad de Mejora
B100: PERIODO | C100: ANALISIS | H100: PLAN DE ACCION
B101: II SEMESTRE
H102: fecha | J102: Actividad | M102: Responsable
...

Sheet Hoja1
